File: Lab 2 - Monotonic Tensile and Fracture Toughness/test2.csv
Time,Extension,Load,Tensile strain (Extension),Strain 1
(s),(mm),(N),(%),(%)
"0.00000","0.00000","1.57819","0.00000","0.00133"
"0.20000","0.00819","1.96982","0.01432","0.00142"
"0.40000","0.01913","58.05145","0.03344","0.00233"
"0.60000","0.02976","143.17018","0.05203","0.00293"
"0.80000","0.03996","243.29074","0.06987","0.00435"
"1.00000","0.04999","359.52539","0.08740","0.00570"
"1.20000","0.06005","505.29059","0.10498","0.00742"
"1.40000","0.07010","656.45099","0.12256","0.00970"
"1.60000","0.08008","800.81488","0.14000","0.01146"
"1.80000","0.09011","943.82379","0.15753","0.01336"
"2.00000","0.10014","1084.08032","0.17507","0.01527"
"2.20000","0.11004","1218.19055","0.19238","0.01683"
"2.40000","0.12007","1349.40991","0.20991","0.01861"
"2.60000","0.13017","1477.87756","0.22758","0.02023"
"2.80000","0.14013","1597.63843","0.24498","0.02164"
"3.00000","0.15008","1710.08813","0.26238","0.02311"
"3.20000","0.16009","1819.79272","0.27987","0.02409"
"3.40000","0.17009","1917.28003","0.29736","0.02545"
"3.60000","0.18002","1992.03870","0.31472","0.02594"
"3.80000","0.19012","2064.92603","0.33238","0.02633"
"4.00000","0.20018","2142.55054","0.34996","0.02728"
"4.20000","0.21008","2216.99170","0.36727","0.02810"
"4.40000","0.21996","2286.60645","0.38454","0.02893"
"4.60000","0.23011","2351.54858","0.40229","0.02889"
"4.80000","0.24012","2410.63550","0.41978","0.03017"
"5.00000","0.25007","2465.68018","0.43718","0.03061"
"5.20000","0.26012","2519.09448","0.45476","0.03154"
"5.40000","0.27013","2571.06250","0.47225","0.03207"
"5.60000","0.28008","2622.36938","0.48965","0.03305"
"5.80000","0.29006","2674.72900","0.50710","0.03304"
"6.00000","0.30016","2728.63721","0.52476","0.03422"
"6.20000","0.31012","2780.24854","0.54216","0.03485"
"6.40000","0.32007","2829.05127","0.55956","0.03527"
"6.60000","0.33007","2881.46875","0.57705","0.03564"
"6.80000","0.34008","2932.71680","0.59454","0.03652"
"7.00000","0.35006","2982.17529","0.61199","0.03732"
"7.20000","0.36011","3033.73828","0.62956","0.03769"
"7.40000","0.37014","3085.57764","0.64710","0.03865"
"7.60000","0.38007","3136.69189","0.66445","0.03894"
"7.80000","0.39002","3187.69556","0.68185","0.04003"
"8.00000","0.40010","3241.79297","0.69948","0.04056"
"8.20000","0.41013","3296.40063","0.71701","0.04100"
"8.40000","0.42006","3348.54712","0.73437","0.04187"
"8.60000","0.43011","3404.51147","0.75194","0.04263"
"8.80000","0.44014","3462.38721","0.76948","0.04334"
"9.00000","0.45007","3517.78198","0.78683","0.04415"
"9.20000","0.46007","3574.33521","0.80432","0.04474"
"9.40000","0.47018","3634.97314","0.82199","0.04543"
"9.60000","0.48013","3692.01416","0.83939","0.04633"
"9.80000","0.49006","3748.87695","0.85675","0.04701"
"10.00000","0.50011","3809.96216","0.87432","0.04768"
"10.20000","0.51012","3869.58008","0.89181","0.04866"
"10.40000","0.52004","3929.44702","0.90917","0.04941"
"10.60000","0.53010","3991.76733","0.92675","0.05030"
"10.80000","0.54015","4054.76611","0.94432","0.05111"
"11.00000","0.55008","4116.36475","0.96168","0.05209"
"11.20000","0.56003","4178.51562","0.97908","0.05255"
"11.40000","0.57011","4244.05859","0.99670","0.05311"
"11.60000","0.58014","4309.09473","1.01424","0.05434"
"11.80000","0.59005","4372.71436","1.03155","0.05545"
"12.00000","0.60010","4439.17822","1.04913","0.05609"
"12.20000","0.61008","4504.67676","1.06657","0.05698"
"12.40000","0.62001","4570.33789","1.08393","0.05816"
"12.60000","0.63004","4637.68555","1.10146","0.05878"
"12.80000","0.64014","4708.09570","1.11913","0.05968"
"13.00000","0.65014","4774.60010","1.13662","0.06058"
"13.20000","0.66010","4840.48340","1.15402","0.06172"
"13.40000","0.67015","4911.64551","1.17159","0.06223"
"13.60000","0.68013","4981.94238","1.18904","0.06331"
"13.80000","0.69006","5050.71191","1.20640","0.06411"
"14.00000","0.70011","5121.09619","1.22397","0.06532"
"14.20000","0.71019","5192.58594","1.24159","0.06613"
"14.40000","0.72009","5261.98633","1.25891","0.06693"
"14.60000","0.73002","5330.88379","1.27626","0.06807"
"14.80000","0.74010","5403.33398","1.29389","0.06909"
"15.00000","0.75013","5472.08545","1.31142","0.06989"
"15.20000","0.76006","5541.28223","1.32878","0.07104"
"15.40000","0.77011","5614.96973","1.34635","0.07206"
"15.60000","0.78014","5687.80713","1.36389","0.07319"
"15.80000","0.79007","5758.75049","1.38124","0.07380"
"16.00000","0.80005","5833.46436","1.39869","0.07438"
"16.20000","0.81010","5910.21143","1.41627","0.07606"
"16.40000","0.82011","5984.58740","1.43375","0.07688"
"16.60000","0.83006","6058.57910","1.45116","0.07772"
"16.80000","0.84011","6135.87744","1.46873","0.07882"
"17.00000","0.85009","6210.79639","1.48618","0.08019"
"17.20000","0.86000","6284.35254","1.50349","0.08095"
"17.40000","0.87010","6361.80322","1.52116","0.08231"
"17.60000","0.88018","6434.08301","1.53878","0.08342"
"17.80000","0.89008","6511.81348","1.55609","0.08433"
"18.00000","0.90001","6589.43359","1.57345","0.08533"
"18.20000","0.91009","6667.70020","1.59107","0.08663"
"18.40000","0.92009","6747.32568","1.60856","0.08767"
"18.60000","0.93005","6823.52539","1.62596","0.08874"
"18.80000","0.94015","6902.95312","1.64362","0.08962"
"19.00000","0.95016","6981.34521","1.66111","0.09066"
"19.20000","0.96006","7059.07959","1.67843","0.09203"
"19.40000","0.97009","7138.30957","1.69596","0.09327"
"19.60000","0.98017","7219.16553","1.71358","0.09452"
"19.80000","0.99012","7297.91992","1.73098","0.09564"
"20.00000","1.00007","7378.05078","1.74838","0.09666"
"20.20000","1.01010","7458.53271","1.76592","0.09796"
"20.40000","1.02008","7537.05127","1.78336","0.09903"
"20.60000","1.03006","7617.19629","1.80081","0.10035"
"20.80000","1.04011","7699.94727","1.81838","0.10169"
"21.00000","1.05014","7782.78467","1.83592","0.10249"
"21.20000","1.06007","7861.26904","1.85327","0.10413"
"21.40000","1.07005","7944.28564","1.87072","0.10574"
"21.60000","1.08010","8029.75684","1.88829","0.10676"
"21.80000","1.09011","8112.27197","1.90578","0.10778"
"22.00000","1.10006","8193.68457","1.92318","0.10912"
"22.20000","1.11012","8278.61621","1.94076","0.11058"
"22.40000","1.12012","8363.91504","1.95825","0.11189"
"22.60000","1.13002","8446.79883","1.97556","0.11283"
"22.80000","1.14005","8532.26367","1.99310","0.11470"
"23.00000","1.15018","8617.85840","2.01081","0.11561"
"23.20000","1.16013","8702.11230","2.02821","0.11692"
"23.40000","1.17004","8785.40039","2.04552","0.11834"
"23.60000","1.18012","8872.00098","2.06314","0.12003"
"23.80000","1.19010","8956.84863","2.08059","0.12092"
"24.00000","1.20005","9039.73340","2.09799","0.12260"
"24.20000","1.21010","9127.47266","2.11556","0.12432"
"24.40000","1.22013","9214.08301","2.13310","0.12531"
"24.60000","1.23006","9297.01465","2.15046","0.12666"
"24.80000","1.24004","9380.94922","2.16790","0.12816"
"25.00000","1.25014","9468.83301","2.18557","0.12975"
"25.20000","1.26012","9554.38770","2.20301","0.13069"
"25.40000","1.27008","9637.68750","2.22041","0.13205"
"25.60000","1.28013","9722.78125","2.23799","0.13342"
"25.80000","1.29013","9808.17090","2.25548","0.13474"
"26.00000","1.30006","9893.11426","2.27283","0.13619"
"26.20000","1.31007","9981.25781","2.29032","0.13768"
"26.40000","1.32017","10069.95703","2.30799","0.13922"
"26.60000","1.33010","10154.91602","2.32535","0.14115"
"26.80000","1.34005","10243.75684","2.34275","0.14232"
"27.00000","1.35011","10333.03027","2.36032","0.14374"
"27.20000","1.36008","10420.48340","2.37777","0.14536"
"27.40000","1.37006","10506.58789","2.39521","0.14683"
"27.60000","1.38009","10598.47559","2.41275","0.14836"
"27.80000","1.39010","10687.36914","2.43024","0.14952"
"28.00000","1.40005","10775.57324","2.44764","0.15081"
"28.20000","1.41003","10864.43945","2.46508","0.15262"
"28.40000","1.42008","10955.51074","2.48266","0.15400"
"28.60000","1.43006","11045.95508","2.50011","0.15547"
"28.80000","1.44006","11137.93652","2.51759","0.15670"
"29.00000","1.45014","11228.91113","2.53522","0.15840"
"29.20000","1.46015","11319.03613","2.55270","0.15988"
"29.40000","1.47008","11409.88574","2.57006","0.16129"
"29.60000","1.48005","11502.09570","2.58751","0.16220"
"29.80000","1.49013","11595.87402","2.60513","0.16422"
"30.00000","1.50011","11686.50781","2.62257","0.16571"
"30.20000","1.51009","11778.43262","2.64002","0.16678"
"30.40000","1.52012","11873.80273","2.65755","0.16852"
"30.60000","1.53010","11967.11328","2.67500","0.17007"
"30.80000","1.54005","12059.67090","2.69240","0.17124"
"31.00000","1.55011","12154.13574","2.70997","0.17313"
"31.20000","1.56018","12249.68164","2.72760","0.17487"
"31.40000","1.57009","12342.79980","2.74491","0.17609"
"31.60000","1.58004","12435.85840","2.76231","0.17812"
"31.80000","1.59010","12531.94238","2.77989","0.18034"
"32.00000","1.60007","12625.70215","2.79733","0.18175"
"32.20000","1.61003","12721.62012","2.81473","0.18340"
"32.40000","1.62013","12820.13184","2.83240","0.18486"
"32.60000","1.63014","12912.48633","2.84989","0.18642"
"32.80000","1.64001","13006.79785","2.86716","0.18789"
"33.00000","1.65002","13105.63867","2.88465","0.18975"
"33.20000","1.66015","13204.35547","2.90235","0.19116"
"33.40000","1.67013","13299.19824","2.91980","0.19292"
"33.60000","1.68005","13395.35742","2.93716","0.19416"
"33.80000","1.69008","13494.37695","2.95469","0.19589"
"34.00000","1.70006","13593.26660","2.97213","0.19740"
"34.20000","1.71001","13691.27344","2.98954","0.19905"
"34.40000","1.72012","13790.87402","3.00720","0.20098"
"34.60000","1.73017","13889.04785","3.02478","0.20233"
"34.80000","1.74010","13986.78320","3.04214","0.20394"
"35.00000","1.75005","14086.19629","3.05954","0.20577"
"35.20000","1.76013","14185.57715","3.07716","0.20721"
"35.40000","1.77011","14283.24707","3.09460","0.20884"
"35.60000","1.78007","14384.02539","3.11200","0.21037"
"35.80000","1.79015","14487.05469","3.12962","0.21209"
"36.00000","1.80010","14584.88574","3.14703","0.21365"
"36.20000","1.81000","14681.57422","3.16434","0.21537"
"36.40000","1.82003","14784.17383","3.18187","0.21702"
"36.60000","1.83014","14887.84570","3.19954","0.21882"
"36.80000","1.84011","14988.12988","3.21698","0.22071"
"37.00000","1.85007","15087.02344","3.23438","0.22212"
"37.20000","1.86012","15188.25293","3.25196","0.22378"
"37.40000","1.87010","15291.21289","3.26941","0.22549"
"37.60000","1.88005","15392.53906","3.28681","0.22769"
"37.80000","1.89013","15495.98535","3.30443","0.22915"
"38.00000","1.90016","15598.09180","3.32196","0.23109"
"38.20000","1.91004","15697.81641","3.33923","0.23237"
"38.40000","1.92002","15802.33301","3.35667","0.23406"
"38.60000","1.93012","15905.47754","3.37434","0.23576"
"38.80000","1.94013","16007.60645","3.39183","0.23769"
"39.00000","1.95008","16109.26367","3.40923","0.23929"
"39.20000","1.96013","16215.03809","3.42681","0.24133"
"39.40000","1.97011","16319.02441","3.44425","0.24310"
"39.60000","1.98002","16421.57227","3.46157","0.24466"
"39.80000","1.99007","16526.83008","3.47914","0.24642"
"40.00000","2.00015","16633.69336","3.49676","0.24810"
"40.20000","2.01005","16737.41406","3.51408","0.24962"
"40.40000","2.02003","16841.70312","3.53152","0.25154"
"40.60000","2.03013","16947.81250","3.54919","0.25317"
"40.80000","2.04009","17052.56445","3.56659","0.25490"
"41.00000","2.05007","17158.72070","3.58403","0.25680"
"41.20000","2.06017","17266.30859","3.60170","0.25826"
"41.40000","2.07020","17370.24414","3.61923","0.26033"
"41.60000","2.08010","17473.79688","3.63654","0.26221"
"41.80000","2.09006","17581.60156","3.65395","0.26395"
"42.00000","2.10014","17690.24414","3.67157","0.26561"
"42.20000","2.11011","17796.62305","3.68901","0.26720"
"42.40000","2.12007","17902.40625","3.70641","0.26892"
"42.60000","2.13010","18011.21484","3.72395","0.27084"
"42.80000","2.14010","18119.66992","3.74143","0.27270"
"43.00000","2.15003","18225.66406","3.75879","0.27477"
"43.20000","2.16006","18335.40820","3.77632","0.27665"
"43.40000","2.17014","18444.50586","3.79395","0.27837"
"43.60000","2.18009","18553.82422","3.81135","0.28013"
"43.80000","2.19002","18662.89648","3.82870","0.28220"
"44.00000","2.20012","18773.25977","3.84637","0.28378"
"44.20000","2.21008","18879.03906","3.86377","0.28571"
"44.40000","2.22001","18987.86914","3.88113","0.28735"
"44.60000","2.23011","19100.44922","3.89879","0.28935"
"44.80000","2.24016","19211.74609","3.91637","0.29138"
"45.00000","2.25012","19318.23047","3.93377","0.29320"
"45.20000","2.26007","19428.63281","3.95117","0.29503"
"45.40000","2.27012","19540.32422","3.96875","0.29700"
"45.60000","2.28008","19649.23438","3.98615","0.29934"
"45.80000","2.29006","19759.42383","4.00360","0.30106"
"46.00000","2.30016","19871.49219","4.02126","0.30273"
"46.20000","2.31014","19984.08789","4.03871","0.30493"
"46.40000","2.32004","20093.07812","4.05602","0.30626"
"46.60000","2.33007","20205.61328","4.07355","0.30844"
"46.80000","2.34015","20317.14258","4.09117","0.31060"
"47.00000","2.35008","20427.19531","4.10853","0.31209"
"47.20000","2.36006","20539.49023","4.12598","0.31439"
"47.40000","2.37014","20650.81055","4.14360","0.31613"
"47.60000","2.38009","20759.94141","4.16100","0.31794"
"47.80000","2.39002","20869.69922","4.17835","0.32014"
"48.00000","2.40010","20987.84570","4.19598","0.32196"
"48.20000","2.41015","21100.47070","4.21355","0.32395"
"48.40000","2.42008","21212.14648","4.23091","0.32605"
"48.60000","2.43008","21325.69922","4.24840","0.32787"
"48.80000","2.44006","21440.45508","4.26584","0.33013"
"49.00000","2.45007","21554.33594","4.28333","0.33188"
"49.20000","2.46010","21667.00391","4.30087","0.33399"
"49.40000","2.47015","21780.25977","4.31844","0.33607"
"49.60000","2.48010","21890.71289","4.33584","0.33836"
"49.80000","2.48998","22002.59961","4.35311","0.34062"
"50.00000","2.50003","22118.94336","4.37069","0.34224"
"50.20000","2.51011","22232.51562","4.38831","0.34447"
"50.40000","2.52012","22343.47070","4.40580","0.34594"
"50.60000","2.53012","22456.75195","4.42329","0.34890"
"50.80000","2.54015","22569.57227","4.44082","0.35086"
"51.00000","2.55008","22680.32812","4.45818","0.35377"
"51.20000","2.56006","22791.34375","4.47562","0.35508"
"51.40000","2.57011","22905.06445","4.49320","0.35775"
"51.60000","2.58014","23016.76562","4.51074","0.36076"
"51.80000","2.59004","23125.94336","4.52805","0.36313"
"52.00000","2.60002","23238.52344","4.54549","0.36500"
"52.20000","2.61008","23349.91211","4.56307","0.36803"
"52.40000","2.62008","23461.06445","4.58056","0.37041"
"52.60000","2.63008","23569.20508","4.59805","0.37293"
"52.80000","2.64016","23677.24414","4.61567","0.37557"
"53.00000","2.65012","23779.83008","4.63307","0.37828"
"53.20000","2.66004","23882.99219","4.65043","0.38121"
"53.40000","2.67007","23987.95312","4.66796","0.38461"
"53.60000","2.68013","24089.40039","4.68554","0.38847"
"53.80000","2.69011","24186.63477","4.70298","0.39171"
"54.00000","2.70001","24284.71875","4.72030","0.39553"
"54.20000","2.71006","24383.99805","4.73787","0.39904"
"54.40000","2.72007","24477.57031","4.75536","0.40309"
"54.60000","2.73007","24567.92383","4.77285","0.40754"
"54.80000","2.74018","24658.72266","4.79052","0.41270"
"55.00000","2.75015","24747.20703","4.80796","0.41742"
"55.20000","2.76008","24830.02148","4.82532","0.42273"
"55.40000","2.77004","24913.16211","4.84272","0.42866"
"55.60000","2.78009","24994.91211","4.86030","0.43483"
"55.80000","2.79007","25071.38867","4.87774","0.44094"
"56.00000","2.80005","25145.75195","4.89519","0.44823"
"56.20000","2.81010","25219.94727","4.91276","0.45554"
"56.40000","2.82011","25286.88672","4.93025","0.46258"
"56.60000","2.83003","25351.70703","4.94761","0.47044"
"56.80000","2.84009","25420.09375","4.96519","0.47830"
"57.00000","2.85017","25482.47656","4.98281","0.48744"
"57.20000","2.86015","25539.99219","5.00025","0.49728"
"57.40000","2.87010","25597.08984","5.01766","0.50660"
"57.60000","2.88013","25655.13477","5.03519","0.51700"
"57.80000","2.89011","25706.60156","5.05263","0.52731"
"58.00000","2.90003","25755.19922","5.06999","0.53804"
"58.20000","2.91014","25804.87500","5.08766","0.54864"
"58.40000","2.92014","25849.58594","5.10514","0.55989"
"58.60000","2.93005","25893.05859","5.12246","0.57129"
"58.80000","2.94007","25935.87891","5.13999","0.58304"
"59.00000","2.95013","25976.88477","5.15757","0.59568"
"59.20000","2.96011","26011.63477","5.17501","0.60806"
"59.40000","2.97004","26047.14258","5.19237","0.62103"
"59.60000","2.98012","26083.69531","5.20999","0.63455"
"59.80000","2.99012","26114.60352","5.22748","0.64741"
"60.00000","3.00000","26143.38672","5.24475","0.66132"
"60.20000","3.01003","26175.73438","5.26228","0.67538"
"60.40000","3.02013","26205.31836","5.27995","0.68949"
"60.60000","3.03008","26229.41992","5.29735","0.70519"
"60.80000","3.04006","26254.65625","5.31479","0.72004"
"61.00000","3.05014","26278.37109","5.33242","0.73498"
"61.20000","3.06009","26301.51562","5.34982","0.75047"
"61.40000","3.07005","26323.72656","5.36722","0.76551"
"61.60000","3.08015","26345.42578","5.38488","0.78121"
"61.80000","3.09018","26363.80859","5.40242","0.79750"
"62.00000","3.10008","26380.71680","5.41973","0.81391"
"62.20000","3.11009","26399.07227","5.43722","0.83022"
"62.40000","3.12012","26416.52539","5.45475","0.84604"
"62.60000","3.13010","26431.81055","5.47220","0.86266"
"62.80000","3.14007","26447.31641","5.48964","0.87909"
"63.00000","3.15015","26465.31250","5.50726","0.89596"
"63.20000","3.16013","26478.56836","5.52471","0.91266"
"63.40000","3.17004","26491.20312","5.54202","0.92994"
"63.60000","3.18006","26506.60938","5.55955","0.94735"
"63.80000","3.19012","26520.84180","5.57713","0.96475"
"64.00000","3.20007","26531.78906","5.59453","0.98238"
"64.20000","3.21008","26543.57031","5.61202","1.00032"
"64.40000","3.22013","26553.86328","5.62960","1.01814"
"64.60000","3.23006","26565.06250","5.64695","1.03632"
"64.80000","3.24001","26575.75977","5.66436","1.05360"
"65.00000","3.25014","26589.23242","5.68206","1.07157"
"65.20000","3.26020","26597.40234","5.69964","1.08998"
"65.40000","3.27007","26603.68945","5.71691","1.10764"
"65.60000","3.28005","26614.75781","5.73436","1.12614"
"65.80000","3.29013","26625.98438","5.75198","1.14449"
"66.00000","3.30008","26633.92383","5.76938","1.16230"
"66.20000","3.31009","26641.31836","5.78687","1.18052"
"66.40000","3.32019","26652.63672","5.80453","1.19877"
"66.60000","3.33017","26660.14453","5.82198","1.21722"
"66.80000","3.34002","26666.07227","5.83920","1.23572"
"67.00000","3.35010","26676.82227","5.85682","1.25463"
"67.20000","3.36013","26685.80469","5.87436","1.27312"
"67.40000","3.37006","26690.93945","5.89171","1.29130"
"67.60000","3.38006","26699.15039","5.90920","1.31043"
"67.80000","3.39012","26707.45508","5.92678","1.32870"
"68.00000","3.40005","26711.55859","5.94414","1.34706"
"68.20000","3.41000","26720.55664","5.96154","1.36558"
"68.40000","3.42016","26731.30859","5.97929","1.38415"
"68.60000","3.43018","26736.33008","5.99682","1.40310"
"68.80000","3.44009","26739.32812","6.01414","1.42149"
"69.00000","3.45009","26748.83008","6.03163","1.43996"
"69.20000","3.46014","26757.50195","6.04920","1.45871"
"69.40000","3.47010","26762.14648","6.06660","1.47695"
"69.60000","3.48008","26768.55664","6.08405","1.49554"
"69.80000","3.49016","26776.80469","6.10167","1.51495"
"70.00000","3.50008","26783.99023","6.11903","1.53378"
"70.20000","3.51001","26789.76953","6.13639","1.55274"
"70.40000","3.52012","26797.32227","6.15405","1.57134"
"70.60000","3.53015","26802.39648","6.17158","1.58979"
"70.80000","3.54007","26807.37305","6.18894","1.60820"
"71.00000","3.55008","26814.43945","6.20643","1.62703"
"71.20000","3.56011","26820.94922","6.22396","1.64588"
"71.40000","3.57006","26825.42188","6.24136","1.66438"
"71.60000","3.58004","26831.86328","6.25881","1.68252"
"71.80000","3.59014","26839.30664","6.27647","1.70092"
"72.00000","3.60012","26845.68555","6.29392","1.71902"
"72.20000","3.61005","26849.26172","6.31128","1.73790"
"72.40000","3.62010","26856.57227","6.32885","1.75595"
"72.60000","3.63013","26865.28906","6.34639","1.77386"
"72.80000","3.64011","26870.48633","6.36383","1.79250"
"73.00000","3.65009","26876.78125","6.38128","1.81067"
"73.20000","3.66019","26882.41602","6.39894","1.82937"
"73.40000","3.67015","26885.88477","6.41634","1.84728"
"73.60000","3.68005","26891.04883","6.43366","1.86536"
"73.80000","3.69011","26899.63281","6.45123","1.88306"
"74.00000","3.70016","26905.29883","6.46881","1.90083"
"74.20000","3.71009","26907.61719","6.48617","1.91908"
"74.40000","3.72007","26915.66406","6.50361","1.93741"
"74.60000","3.73012","26922.44336","6.52119","1.95480"
"74.80000","3.74007","26925.33789","6.53859","1.97284"
"75.00000","3.75005","26931.46680","6.55604","1.99071"
"75.20000","3.76013","26939.77344","6.57366","2.00806"
"75.40000","3.77011","26946.72852","6.59110","2.02579"
"75.60000","3.78001","26951.12891","6.60841","2.04364"
"75.80000","3.79007","26957.06836","6.62599","2.06146"
"76.00000","3.80010","26964.03516","6.64353","2.07905"
"76.20000","3.81005","26968.74414","6.66093","2.09675"
"76.40000","3.82008","26974.85742","6.67846","2.11417"
"76.60000","3.83018","26980.50195","6.69612","2.13181"
"76.80000","3.84016","26984.23828","6.71357","2.14932"
"77.00000","3.85007","26988.62305","6.73088","2.16691"
"77.20000","3.86009","26996.33203","6.74842","2.18467"
"77.40000","3.87012","27002.71875","6.76595","2.20173"
"77.60000","3.88013","27005.68359","6.78344","2.21860"
"77.80000","3.89011","27011.61133","6.80088","2.23662"
"78.00000","3.90013","27017.47070","6.81842","2.25357"
"78.20000","3.91006","27023.08203","6.83577","2.27062"
"78.40000","3.92004","27028.47461","6.85322","2.28745"
"78.60000","3.93015","27035.96875","6.87088","2.30482"
"78.80000","3.94012","27040.70508","6.88833","2.32188"
"79.00000","3.95008","27045.57227","6.90573","2.33879"
"79.20000","3.96008","27051.35352","6.92322","2.35665"
"79.40000","3.97011","27058.50977","6.94075","2.37336"
"79.60000","3.98006","27063.30078","6.95815","2.39030"
"79.80000","3.99007","27069.88477","6.97564","2.40745"
"80.00000","4.00015","27074.75781","6.99326","2.42440"
"80.20000","4.01013","27077.42188","7.01071","2.44173"
"80.40000","4.02005","27080.88086","7.02807","2.45876"
"80.60000","4.03006","27088.54102","7.04555","2.47523"
"80.80000","4.04016","27096.83984","7.06322","2.49197"
"81.00000","4.05012","27100.05078","7.08062","2.50920"
"81.20000","4.06009","27104.96094","7.09807","2.52596"
"81.40000","4.07010","27112.36523","7.11555","2.54254"
"81.60000","4.08003","27116.85547","7.13291","2.55938"
"81.80000","4.09000","27122.40234","7.15036","2.57612"
"82.00000","4.10013","27129.17969","7.16807","2.59272"
"82.20000","4.11016","27134.63281","7.18560","2.60927"
"82.40000","4.12012","27139.26367","7.20300","2.62593"
"82.60000","4.13010","27144.35742","7.22045","2.64276"
"82.80000","4.14015","27149.13477","7.23802","2.65928"
"83.00000","4.15010","27153.92383","7.25542","2.67605"
"83.20000","4.16008","27162.19141","7.27287","2.69263"
"83.40000","4.17016","27169.00391","7.29049","2.70928"
"83.60000","4.18009","27170.41602","7.30785","2.72510"
"83.80000","4.18999","27174.42773","7.32516","2.74178"
"84.00000","4.20007","27181.36523","7.34278","2.75811"
"84.20000","4.21012","27188.61328","7.36036","2.77469"
"84.40000","4.22010","27191.91602","7.37780","2.79187"
"84.60000","4.23011","27198.07031","7.39529","2.80816"
"84.80000","4.24014","27203.78906","7.41283","2.82411"
"85.00000","4.25006","27209.43359","7.43018","2.84020"
"85.20000","4.26004","27215.60547","7.44763","2.85691"
"85.40000","4.27015","27221.70898","7.46529","2.87304"
"85.60000","4.28015","27225.17188","7.48278","2.89008"
"85.80000","4.29000","27227.69336","7.50001","2.90652"
"86.00000","4.30006","27235.73828","7.51758","2.92276"
"86.20000","4.31014","27242.06445","7.53521","2.93934"
"86.40000","4.32012","27245.68164","7.55265","2.95530"
"86.60000","4.33009","27250.87109","7.57009","2.97207"
"86.80000","4.34017","27258.46094","7.58772","2.98835"
"87.00000","4.35013","27260.44336","7.60512","3.00396"
"87.20000","4.36000","27263.32617","7.62239","3.02011"
"87.40000","4.37011","27272.38867","7.64005","3.03592"
"87.60000","4.38014","27280.48633","7.65758","3.05247"
"87.80000","4.39004","27283.43359","7.67490","3.06920"
"88.00000","4.40004","27291.19141","7.69239","3.08573"
"88.20000","4.41012","27296.28125","7.71001","3.10190"
"88.40000","4.42005","27299.42578","7.72736","3.11791"
"88.60000","4.43003","27304.44727","7.74481","3.13413"
"88.80000","4.44019","27312.31836","7.76256","3.15037"
"89.00000","4.45019","27314.97070","7.78005","3.16664"
"89.20000","4.46007","27317.02539","7.79732","3.18315"
"89.40000","4.47010","27325.41602","7.81486","3.19898"
"89.60000","4.48015","27331.14062","7.83243","3.21540"
"89.80000","4.49008","27335.12891","7.84979","3.23084"
"90.00000","4.50008","27340.08398","7.86728","3.24694"
"90.20000","4.51016","27347.14062","7.88490","3.26328"
"90.40000","4.52009","27350.12695","7.90226","3.27908"
"90.60000","4.53002","27353.91016","7.91961","3.29515"
"90.80000","4.54012","27362.58594","7.93728","3.31133"
"91.00000","4.55013","27367.73438","7.95477","3.32691"
"91.20000","4.56006","27372.92969","7.97212","3.34314"
"91.40000","4.57006","27379.86133","7.98961","3.35936"
"91.60000","4.58011","27384.95508","8.00719","3.37547"
"91.80000","4.59004","27387.11523","8.02455","3.39187"
"92.00000","4.59999","27394.70508","8.04195","3.40789"
"92.20000","4.61012","27402.14844","8.05966","3.42411"
"92.40000","4.62013","27404.87500","8.07715","3.43975"
"92.60000","4.63008","27407.11914","8.09455","3.45597"
"92.80000","4.64011","27412.24414","8.11208","3.47197"
"93.00000","4.65014","27418.79883","8.12961","3.48850"
"93.20000","4.66007","27421.22461","8.14697","3.50435"
"93.40000","4.67010","27427.46094","8.16450","3.52032"
"93.60000","4.68020","27432.48438","8.18217","3.53636"
"93.80000","4.69013","27438.18750","8.19953","3.55200"
"94.00000","4.70003","27443.75977","8.21684","3.56760"
"94.20000","4.71011","27450.18359","8.23446","3.58385"
"94.40000","4.72014","27455.91016","8.25199","3.59978"
"94.60000","4.73007","27459.72070","8.26935","3.61588"
"94.80000","4.74012","27466.04688","8.28693","3.63178"
"95.00000","4.75013","27470.34180","8.30442","3.64791"
"95.20000","4.76006","27473.53320","8.32177","3.66390"
"95.40000","4.77001","27478.76562","8.33918","3.67988"
"95.60000","4.78014","27487.53711","8.35688","3.69627"
"95.80000","4.79014","27490.98828","8.37437","3.71218"
"96.00000","4.80007","27492.49609","8.39173","3.72773"
"96.20000","4.81010","27498.66797","8.40926","3.74343"
"96.40000","4.82008","27504.48828","8.42671","3.75933"
"96.60000","4.83003","27509.73633","8.44411","3.77517"
"96.80000","4.84009","27515.29297","8.46169","3.79160"
"97.00000","4.85016","27521.35742","8.47931","3.80823"
"97.20000","4.86009","27523.43164","8.49667","3.82441"
"97.40000","4.87000","27527.55664","8.51398","3.84068"
"97.60000","4.88010","27536.50000","8.53164","3.85644"
"97.80000","4.89013","27540.91406","8.54918","3.87317"
"98.00000","4.90011","27544.15820","8.56662","3.88877"
"98.20000","4.91016","27549.71094","8.58420","3.90497"
"98.40000","4.92017","27554.83008","8.60169","3.92101"
"98.60000","4.93007","27557.52539","8.61900","3.93666"
"98.80000","4.94007","27561.31055","8.63649","3.95248"
"99.00000","4.95015","27569.07422","8.65411","3.96843"
"99.20000","4.96013","27573.82617","8.67156","3.98423"
"99.40000","4.97003","27578.19922","8.68887","4.00050"
"99.60000","4.98006","27583.27930","8.70640","4.01671"
"99.80000","4.99007","27588.33203","8.72389","4.03257"
"100.00000","5.00004","27596.21484","8.74134","4.04869"
"100.20000","5.01012","27601.44141","8.75896","4.06459"
"100.40000","5.02020","27605.02344","8.77658","4.08068"
"100.60000","5.03011","27606.23047","8.79389","4.09717"
"100.80000","5.04006","27608.77344","8.81129","4.11259"
"101.00000","5.05011","27615.96484","8.82887","4.12858"
"101.20000","5.06012","27620.78320","8.84636","4.14547"
"101.40000","5.07010","27623.63281","8.86381","4.16156"
"101.60000","5.08007","27628.87109","8.88125","4.17761"
"101.80000","5.09010","27635.35742","8.89878","4.19328"
"102.00000","5.10006","27638.65234","8.91618","4.20945"
"102.20000","5.11009","27644.65820","8.93372","4.22537"
"102.40000","5.12019","27649.68555","8.95138","4.24132"
"102.60000","5.13014","27654.55273","8.96878","4.25708"
"102.80000","5.14005","27656.94531","8.98610","4.27255"
"103.00000","5.15005","27662.46289","9.00358","4.28909"
"103.20000","5.16010","27668.02344","9.02116","4.30474"
"103.40000","5.17006","27672.44336","9.03856","4.32073"
"103.60000","5.18006","27679.37500","9.05605","4.33725"
"103.80000","5.19012","27685.00781","9.07363","4.35365"
"104.00000","5.20010","27686.20898","9.09108","4.36937"
"104.20000","5.21005","27688.80078","9.10848","4.38514"
"104.40000","5.22013","27696.51172","9.12610","4.40121"
"104.60000","5.23016","27700.37891","9.14363","4.41728"
"104.80000","5.24011","27702.78125","9.16103","4.43336"
"105.00000","5.25014","27707.45117","9.17856","4.44964"
"105.20000","5.26014","27712.48242","9.19605","4.46570"
"105.40000","5.27007","27716.66016","9.21341","4.48121"
"105.60000","5.28005","27721.87891","9.23086","4.49749"
"105.80000","5.29015","27727.54688","9.24852","4.51367"
"106.00000","5.30013","27730.10938","9.26597","4.52931"
"106.20000","5.31004","27735.01367","9.28328","4.54571"
"106.40000","5.32009","27740.94727","9.30086","4.56190"
"106.60000","5.33012","27745.87500","9.31839","4.57801"
"106.80000","5.34010","27749.74023","9.33583","4.59393"
"107.00000","5.35005","27755.34766","9.35323","4.61054"
"107.20000","5.36010","27760.00586","9.37081","4.62690"
"107.40000","5.37008","27763.79492","9.38826","4.64316"
"107.60000","5.38001","27763.87109","9.40561","4.65907"
"107.80000","5.39007","27770.52734","9.42319","4.67434"
"108.00000","5.40012","27776.36719","9.44077","4.69059"
"108.20000","5.41010","27778.92578","9.45821","4.70701"
"108.40000","5.42015","27782.59180","9.47579","4.72320"
"108.60000","5.43018","27787.55664","9.49332","4.73957"
"108.80000","5.44011","27790.50391","9.51068","4.75487"
"109.00000","5.45004","27796.55469","9.52804","4.77132"
"109.20000","5.46014","27804.36328","9.54570","4.78700"
"109.40000","5.47017","27806.88086","9.56324","4.80356"
"109.60000","5.48005","27809.44336","9.58051","4.81923"
"109.80000","5.49008","27814.11914","9.59804","4.83605"
"110.00000","5.50011","27817.23438","9.61557","4.85194"
"110.20000","5.51006","27820.70117","9.63297","4.86807"
"110.40000","5.52006","27826.35352","9.65046","4.88411"
"110.60000","5.53017","27833.63086","9.66813","4.90088"
"110.80000","5.54015","27834.34766","9.68557","4.91694"
"111.00000","5.55005","27837.38672","9.70289","4.93323"
"111.20000","5.56010","27842.13086","9.72046","4.94862"
"111.40000","5.57008","27847.30859","9.73791","4.96506"
"111.60000","5.58006","27852.00977","9.75535","4.98046"
"111.80000","5.59012","27857.61914","9.77293","4.99776"
"112.00000","5.60014","27861.61523","9.79046","5.01405"
"112.20000","5.61005","27862.85938","9.80778","5.02987"
"112.40000","5.62000","27868.56836","9.82518","5.04633"
"112.60000","5.63016","27876.20117","9.84293","5.06295"
"112.80000","5.64016","27876.28516","9.86042","5.07936"
"113.00000","5.65006","27877.32227","9.87773","5.09540"
"113.20000","5.66007","27883.26367","9.89522","5.11145"
"113.40000","5.67007","27887.74609","9.91271","5.12794"
"113.60000","5.68005","27890.63086","9.93016","5.14401"
"113.80000","5.69010","27897.10547","9.94773","5.16005"
"114.00000","5.70021","27901.65039","9.96540","5.17627"
"114.20000","5.71014","27903.95898","9.98275","5.19270"
"114.40000","5.72004","27906.08398","10.00007","5.20877"
"114.60000","5.73014","27911.29297","10.01773","5.22532"
"114.80000","5.74015","27915.51953","10.03522","5.24167"
"115.00000","5.75008","27918.98242","10.05258","5.25756"
"115.20000","5.76013","27924.19531","10.07016","5.27416"
"115.40000","5.77011","27927.04492","10.08760","5.29024"
"115.60000","5.77999","27929.04102","10.10487","5.30663"
"115.80000","5.79001","27935.72266","10.12240","5.32368"
"116.00000","5.80017","27941.77539","10.14016","5.33994"
"116.20000","5.81017","27943.54297","10.15765","5.35610"
"116.40000","5.82008","27944.80273","10.17496","5.37245"
"116.60000","5.83011","27949.23242","10.19249","5.38864"
"116.80000","5.84011","27952.23242","10.20998","5.40515"
"117.00000","5.85006","27955.05469","10.22738","5.42146"
"117.20000","5.86009","27959.26953","10.24492","5.43788"
"117.40000","5.87017","27964.54688","10.26254","5.45382"
"117.60000","5.88005","27966.37500","10.27981","5.47069"
"117.80000","5.89000","27970.25781","10.29721","5.48684"
"118.00000","5.90011","27976.24414","10.31487","5.50306"
"118.20000","5.91014","27979.87695","10.33240","5.51985"
"118.40000","5.92009","27982.83398","10.34981","5.53590"
"118.60000","5.93012","27987.64062","10.36734","5.55253"
"118.80000","5.94010","27990.37109","10.38478","5.56910"
"119.00000","5.95002","27993.84570","10.40214","5.58545"
"119.20000","5.96005","27998.71875","10.41967","5.60180"
"119.40000","5.97016","28003.99414","10.43734","5.61828"
"119.60000","5.98009","28006.70898","10.45470","5.63487"
"119.80000","5.99004","28008.03125","10.47210","5.65120"
"120.00000","6.00012","28011.06641","10.48972","5.66749"
"120.20000","6.01012","28014.91992","10.50721","5.68423"
"120.40000","6.02008","28018.13281","10.52461","5.70101"
"120.60000","6.03013","28023.02148","10.54219","5.71789"
"120.80000","6.04018","28027.78516","10.55976","5.73396"
"121.00000","6.05009","28029.53516","10.57708","5.75068"
"121.20000","6.06004","28034.69922","10.59448","5.76664"
"121.40000","6.07012","28038.35547","10.61210","5.78369"
"121.60000","6.08015","28040.88867","10.62963","5.80002"
"121.80000","6.09008","28042.34570","10.64699","5.81672"
"122.00000","6.10011","28048.32422","10.66452","5.83347"
"122.20000","6.11011","28051.81445","10.68201","5.85012"
"122.40000","6.12006","28052.60742","10.69941","5.86640"
"122.60000","6.13007","28056.97070","10.71690","5.88310"
"122.80000","6.14015","28063.43945","10.73452","5.89988"
"123.00000","6.15010","28065.40820","10.75192","5.91638"
"123.20000","6.16003","28066.18555","10.76928","5.93336"
"123.40000","6.17008","28071.03906","10.78686","5.95011"
"123.60000","6.18009","28073.79102","10.80435","5.96631"
"123.80000","6.19001","28077.46484","10.82170","5.98310"
"124.00000","6.20009","28083.79883","10.83932","5.99999"
"124.20000","6.21017","28088.19922","10.85695","6.01651"
"124.40000","6.22010","28086.69141","10.87430","6.03309"
"124.60000","6.23005","28090.10156","10.89170","6.04961"
"124.80000","6.24013","28095.98438","10.90933","6.06666"
"125.00000","6.25011","28097.15039","10.92677","6.08330"
"125.20000","6.26009","28098.86133","10.94422","6.09963"
"125.40000","6.27015","28103.17969","10.96179","6.11624"
"125.60000","6.28015","28106.69531","10.97928","6.13294"
"125.80000","6.29008","28108.39453","10.99664","6.14942"
"126.00000","6.30006","28112.10156","11.01408","6.16639"
"126.20000","6.31013","28116.52344","11.03170","6.18299"
"126.40000","6.32011","28120.05859","11.04915","6.19955"
"126.60000","6.33009","28122.86523","11.06659","6.21638"
"126.80000","6.34012","28127.83789","11.08413","6.23279"
"127.00000","6.35010","28129.20898","11.10157","6.24945"
"127.20000","6.36003","28131.30664","11.11893","6.26677"
"127.40000","6.37006","28137.00781","11.13646","6.28354"
"127.60000","6.38014","28141.46484","11.15408","6.30101"
"127.80000","6.39009","28142.16992","11.17148","6.31792"
"128.00000","6.40004","28142.61523","11.18889","6.33446"
"128.20000","6.41007","28147.48633","11.20642","6.35165"
"128.40000","6.42013","28151.73047","11.22400","6.36822"
"128.60000","6.43010","28152.69531","11.24144","6.38560"
"128.80000","6.44013","28155.26172","11.25897","6.40190"
"129.00000","6.45011","28157.66602","11.27642","6.41844"
"129.20000","6.46004","28159.99609","11.29378","6.43524"
"129.40000","6.47004","28164.39062","11.31127","6.45215"
"129.60000","6.48015","28167.86523","11.32893","6.46914"
"129.80000","6.49015","28170.46875","11.34642","6.48590"
"130.00000","6.50013","28174.41797","11.36387","6.50261"
"130.20000","6.51013","28178.15820","11.38135","6.51966"
"130.40000","6.52011","28180.00000","11.39880","6.53610"
"130.60000","6.53007","28180.62695","11.41620","6.55330"
"130.80000","6.54010","28186.40234","11.43373","6.57039"
"131.00000","6.55015","28190.85352","11.45131","6.58756"
"131.20000","6.56008","28191.38086","11.46867","6.60438"
"131.40000","6.57001","28192.62500","11.48603","6.62158"
"131.60000","6.58006","28197.47266","11.50360","6.63856"
"131.80000","6.59012","28200.11914","11.52118","6.65568"
"132.00000","6.60009","28201.71484","11.53862","6.67307"
"132.20000","6.61017","28205.80859","11.55625","6.68998"
"132.40000","6.62018","28206.07812","11.57374","6.70682"
"132.60000","6.63008","28206.87500","11.59105","6.72378"
"132.80000","6.64008","28210.93555","11.60854","6.74127"
"133.00000","6.65014","28216.90820","11.62611","6.75778"
"133.20000","6.66012","28217.79883","11.64356","6.77495"
"133.40000","6.67002","28219.82812","11.66087","6.79192"
"133.60000","6.68010","28225.31445","11.67849","6.80890"
"133.80000","6.69010","28227.80273","11.69598","6.82615"
"134.00000","6.70008","28228.17773","11.71343","6.84314"
"134.20000","6.71013","28231.91602","11.73100","6.85988"
"134.40000","6.72016","28235.33789","11.74854","6.87758"
"134.60000","6.73009","28234.87305","11.76589","6.89446"
"134.80000","6.73999","28236.80273","11.78321","6.91177"
"135.00000","6.75010","28241.04688","11.80087","6.92873"
"135.20000","6.76010","28243.53906","11.81836","6.94577"
"135.40000","6.77003","28245.95898","11.83572","6.96345"
"135.60000","6.78009","28250.76367","11.85330","6.98017"
"135.80000","6.79011","28251.63672","11.87083","6.99809"
"136.00000","6.80004","28253.95117","11.88819","7.01507"
"136.20000","6.81007","28258.85938","11.90572","7.03269"
"136.40000","6.82018","28263.75000","11.92338","7.04930"
"136.60000","6.83018","28262.35547","11.94087","7.06690"
"136.80000","6.84008","28261.83984","11.95819","7.08449"
"137.00000","6.85011","28267.15430","11.97572","7.10167"
"137.20000","6.86012","28269.91016","11.99321","7.11918"
"137.40000","6.87004","28271.55273","12.01057","7.13620"
"137.60000","6.88010","28274.20898","12.02814","7.15371"
"137.80000","6.89015","28278.11914","12.04572","7.17123"
"138.00000","6.90006","28277.24219","12.06303","7.18891"
"138.20000","6.91001","28279.96289","12.08043","7.20607"
"138.40000","6.92011","28284.31641","12.09810","7.22360"
"138.60000","6.93012","28284.53125","12.11559","7.24107"
"138.80000","6.94002","28285.98828","12.13290","7.25815"
"139.00000","6.95007","28290.88281","12.15048","7.27621"
"139.20000","6.96013","28294.27930","12.16806","7.29357"
"139.40000","6.97003","28293.26953","12.18537","7.31127"
"139.60000","6.98001","28296.97070","12.20281","7.32881"
"139.80000","6.99014","28302.26172","12.22052","7.34610"
"140.00000","7.00012","28302.07617","12.23797","7.36346"
"140.20000","7.01007","28301.21484","12.25537","7.38134"
"140.40000","7.02015","28305.36914","12.27299","7.39903"
"140.60000","7.03010","28307.21484","12.29039","7.41633"
"140.80000","7.04003","28308.70117","12.30775","7.43421"
"141.00000","7.05014","28313.19922","12.32541","7.45192"
"141.20000","7.06019","28314.38281","12.34299","7.46951"
"141.40000","7.07009","28315.76562","12.36030","7.48682"
"141.60000","7.08005","28318.46680","12.37770","7.50471"
"141.80000","7.09010","28321.22070","12.39528","7.52250"
"142.00000","7.10011","28321.79102","12.41277","7.53995"
"142.20000","7.11006","28323.36719","12.43017","7.55747"
"142.40000","7.12014","28328.88086","12.44779","7.57579"
"142.60000","7.13014","28330.73047","12.46528","7.59375"
"142.80000","7.14007","28330.39258","12.48264","7.61154"
"143.00000","7.15007","28333.43750","12.50013","7.62900"
"143.20000","7.16015","28337.74414","12.51775","7.64674"
"143.40000","7.17013","28338.02734","12.53519","7.66464"
"143.60000","7.18008","28338.18750","12.55260","7.68228"
"143.80000","7.19014","28340.81445","12.57017","7.70036"
"144.00000","7.20007","28339.94531","12.58753","7.71807"
"144.20000","7.21002","28342.85156","12.60493","7.73611"
"144.40000","7.22013","28347.68945","12.62260","7.75421"
"144.60000","7.23018","28349.93945","12.64017","7.77215"
"144.80000","7.24008","28348.75586","12.65749","7.79017"
"145.00000","7.25001","28353.74805","12.67484","7.80831"
"145.20000","7.26009","28357.83984","12.69246","7.82645"
"145.40000","7.27012","28358.42969","12.71000","7.84452"
"145.60000","7.28007","28358.80859","12.72740","7.86293"
"145.80000","7.29018","28361.75000","12.74506","7.88112"
"146.00000","7.30016","28362.94531","12.76251","7.89956"
"146.20000","7.31006","28361.32617","12.77982","7.91753"
"146.40000","7.32009","28363.72461","12.79736","7.93540"
"146.60000","7.33014","28367.96680","12.81493","7.95365"
"146.80000","7.34010","28369.82031","12.83233","7.97215"
"147.00000","7.35005","28370.77148","12.84973","7.99020"
"147.20000","7.36013","28371.81641","12.86736","8.00817"
"147.40000","7.37003","28370.13672","12.88467","8.02628"
"147.60000","7.38003","28375.13086","12.90216","8.04454"
"147.80000","7.39014","28378.93750","12.91982","8.06339"
"148.00000","7.40019","28380.03711","12.93740","8.08173"
"148.20000","7.41010","28377.52930","12.95471","8.09951"
"148.40000","7.42005","28381.33789","12.97211","8.11816"
"148.60000","7.43013","28385.66602","12.98974","8.13629"
"148.80000","7.44008","28386.19727","13.00714","8.15508"
"149.00000","7.45006","28385.47461","13.02458","8.17410"
"149.20000","7.46011","28387.51367","13.04216","8.19224"
"149.40000","7.47009","28389.39453","13.05960","8.21047"
"149.60000","7.48005","28390.03125","13.07700","8.22849"
"149.80000","7.49010","28392.31445","13.09458","8.24681"
"150.00000","7.50021","28395.00000","13.11225","8.26499"
"150.20000","7.51013","28396.00391","13.12960","8.28346"
"150.40000","7.52006","28396.50000","13.14696","8.30224"
"150.60000","7.53007","28399.48828","13.16445","8.32048"
"150.80000","7.54007","28400.31641","13.18194","8.33881"
"151.00000","7.55005","28401.60352","13.19938","8.35743"
"151.20000","7.56010","28406.67578","13.21696","8.37657"
"151.40000","7.57013","28409.01562","13.23449","8.39556"
"151.60000","7.58006","28408.36914","13.25185","8.41395"
"151.80000","7.59006","28409.98438","13.26934","8.43272"
"152.00000","7.60012","28412.76758","13.28692","8.45161"
"152.20000","7.61015","28413.50195","13.30445","8.47012"
"152.40000","7.62007","28410.79297","13.32181","8.48947"
"152.60000","7.63013","28413.41211","13.33939","8.50765"
"152.80000","7.64016","28413.93945","13.35692","8.52603"
"153.00000","7.65006","28414.49414","13.37423","8.54479"
"153.20000","7.66006","28416.99805","13.39172","8.56351"
"153.40000","7.67017","28420.13477","13.40939","8.58252"
"153.60000","7.68012","28420.80859","13.42679","8.60165"
"153.80000","7.69008","28420.97656","13.44419","8.62030"
"154.00000","7.70013","28424.63477","13.46177","8.63920"
"154.20000","7.71011","28425.27930","13.47921","8.65811"
"154.40000","7.72006","28426.06055","13.49661","8.67682"
"154.60000","7.73009","28430.32227","13.51414","8.69601"
"154.80000","7.74009","28430.74805","13.53163","8.71596"
"155.00000","7.75005","28428.84375","13.54904","8.73554"
"155.20000","7.76003","28430.70703","13.56648","8.75411"
"155.40000","7.77008","28433.17383","13.58406","8.77351"
"155.60000","7.78008","28434.41602","13.60155","8.79226"
"155.80000","7.79006","28435.29883","13.61899","8.81178"
"156.00000","7.80014","28436.55664","13.63661","8.83115"
"156.20000","7.81017","28435.38477","13.65415","8.85021"
"156.40000","7.82010","28434.27734","13.67150","8.86883"
"156.60000","7.83008","28436.43945","13.68895","8.88822"
"156.80000","7.84013","28438.76562","13.70652","8.90723"
"157.00000","7.85014","28439.11914","13.72401","8.92602"
"157.20000","7.86009","28441.92969","13.74141","8.94609"
"157.40000","7.87012","28445.93164","13.75895","8.96554"
"157.60000","7.88010","28446.32031","13.77639","8.98487"
"157.80000","7.89005","28446.31641","13.79379","9.00404"
"158.00000","7.90010","28448.96680","13.81137","9.02384"
"158.20000","7.91016","28450.17969","13.82895","9.04339"
"158.40000","7.92011","28448.53906","13.84635","9.06268"
"158.60000","7.93006","28448.30664","13.86375","9.08227"
"158.80000","7.94012","28450.83789","13.88133","9.10166"
"159.00000","7.95007","28449.89648","13.89873","9.12162"
"159.20000","7.96005","28450.72461","13.91617","9.14161"
"159.40000","7.97013","28452.83789","13.93379","9.16125"
"159.60000","7.98013","28452.01562","13.95128","9.18049"
"159.80000","7.99004","28451.49023","13.96860","9.20020"
"160.00000","8.00004","28454.90039","13.98609","9.21947"