File: Lab 2 - Monotonic Tensile and Fracture Toughness/test3.csv
Time,Extension,Load,Tensile strain (Extension)
(s),(mm),(N),(%)
"0.00000","0.00000","2.87997","0.00000"
"0.20000","0.01645","19.11779","0.02877"
"0.40000","0.03870","239.90628","0.06767"
"0.60000","0.05977","526.55701","0.10449"
"0.80000","0.08003","777.06714","0.13991"
"1.00000","0.10016","1011.19690","0.17511"
"1.20000","0.12012","1239.93787","0.21000"
"1.40000","0.14015","1450.67554","0.24502"
"1.60000","0.16026","1643.56421","0.28018"
"1.80000","0.18017","1752.11182","0.31498"
"2.00000","0.20023","1841.31226","0.35005"
"2.20000","0.22021","1914.08899","0.38498"
"2.40000","0.24022","1968.32532","0.41996"
"2.60000","0.26025","2013.38098","0.45498"
"2.80000","0.28021","2060.64062","0.48987"
"3.00000","0.30021","2112.33228","0.52485"
"3.20000","0.32022","2168.25464","0.55983"
"3.40000","0.34020","2231.20386","0.59476"
"3.60000","0.36016","2296.23120","0.62965"
"3.80000","0.38019","2367.78638","0.66467"
"4.00000","0.40025","2443.15967","0.69974"
"4.20000","0.42018","2522.53247","0.73459"
"4.40000","0.44024","2606.33838","0.76965"
"4.60000","0.46015","2690.57910","0.80445"
"4.80000","0.48018","2778.71021","0.83948"
"5.00000","0.50024","2869.51074","0.87454"
"5.20000","0.52015","2961.89819","0.90935"
"5.40000","0.54020","3054.21436","0.94441"
"5.60000","0.56019","3149.78320","0.97935"
"5.80000","0.58017","3247.71704","1.01428"
"6.00000","0.60028","3348.46484","1.04943"
"6.20000","0.62021","3449.32642","1.08428"
"6.40000","0.64022","3552.51904","1.11926"
"6.60000","0.66017","3654.22119","1.15415"
"6.80000","0.68026","3757.56958","1.18926"
"7.00000","0.70019","3860.04932","1.22411"
"7.20000","0.72015","3960.08911","1.25900"
"7.40000","0.74023","4067.94214","1.29411"
"7.60000","0.76014","4179.89062","1.32891"
"7.80000","0.78024","4296.84424","1.36406"
"8.00000","0.80023","4412.52344","1.39900"
"8.20000","0.82018","4531.48389","1.43389"
"8.40000","0.84029","4652.16650","1.46904"
"8.60000","0.86017","4773.24072","1.50380"
"8.80000","0.88021","4896.57275","1.53882"
"9.00000","0.90016","5020.78027","1.57371"
"9.20000","0.92017","5144.41113","1.60869"
"9.40000","0.94023","5271.20850","1.64376"
"9.60000","0.96024","5396.01807","1.67873"
"9.80000","0.98017","5521.68506","1.71358"
"10.00000","1.00018","5650.82324","1.74856"
"10.20000","1.02023","5777.66797","1.78362"
"10.40000","1.04022","5910.89453","1.81856"
"10.60000","1.06020","6042.04297","1.85349"
"10.80000","1.08023","6178.12988","1.88852"
"11.00000","1.10019","6312.28516","1.92341"
"11.20000","1.12025","6448.99756","1.95847"
"11.40000","1.14018","6585.73193","1.99332"
"11.60000","1.16016","6722.70264","2.02825"
"11.80000","1.18024","6865.34277","2.06336"
"12.00000","1.20020","7006.94824","2.09825"
"12.20000","1.22023","7151.40088","2.13327"
"12.40000","1.24022","7295.87207","2.16821"
"12.60000","1.26015","7444.33838","2.20305"
"12.80000","1.28023","7595.42676","2.23817"
"13.00000","1.30016","7748.03760","2.27301"
"13.20000","1.32017","7901.15723","2.30799"
"13.40000","1.34018","8056.99902","2.34297"
"13.60000","1.36018","8211.85449","2.37795"
"13.80000","1.38019","8372.81348","2.41292"
"14.00000","1.40020","8532.33301","2.44790"
"14.20000","1.42021","8693.28418","2.48288"
"14.40000","1.44014","8854.91309","2.51773"
"14.60000","1.46025","9017.49219","2.55288"
"14.80000","1.48020","9184.33105","2.58777"
"15.00000","1.50016","9348.67969","2.62266"
"15.20000","1.52022","9520.10645","2.65773"
"15.40000","1.54015","9689.24023","2.69257"
"15.60000","1.56018","9860.99414","2.72760"
"15.80000","1.58024","10035.63867","2.76266"
"16.00000","1.60022","10206.89062","2.79760"
"16.20000","1.62021","10382.55957","2.83253"
"16.40000","1.64024","10557.10742","2.86755"
"16.60000","1.66022","10736.25195","2.90249"
"16.80000","1.68015","10916.13281","2.93733"
"17.00000","1.70019","11097.93555","2.97235"
"17.20000","1.72019","11278.99609","3.00733"
"17.40000","1.74018","11464.54590","3.04227"
"17.60000","1.76026","11647.99512","3.07738"
"17.80000","1.78009","11831.72559","3.11205"
"18.00000","1.80022","12018.69043","3.14725"
"18.20000","1.82021","12208.89355","3.18218"
"18.40000","1.84016","12397.49316","3.21707"
"18.60000","1.86025","12585.95020","3.25218"
"18.80000","1.88015","12778.28516","3.28698"
"19.00000","1.90024","12969.53418","3.32209"
"19.20000","1.92024","13163.39941","3.35707"
"19.40000","1.94013","13350.86816","3.39183"
"19.60000","1.96021","13551.62402","3.42694"
"19.80000","1.98017","13745.88770","3.46183"
"20.00000","2.00025","13942.38281","3.49694"
"20.20000","2.02021","14140.96973","3.53183"
"20.40000","2.04019","14335.33301","3.56676"
"20.60000","2.06020","14535.04102","3.60174"
"20.80000","2.08020","14733.78809","3.63672"
"21.00000","2.10021","14936.79590","3.67170"
"21.20000","2.12012","15139.60645","3.70650"
"21.40000","2.14018","15343.76562","3.74157"
"21.60000","2.16021","15549.94922","3.77659"
"21.80000","2.18019","15754.64453","3.81152"
"22.00000","2.20027","15961.59668","3.84663"
"22.20000","2.22018","16167.00488","3.88144"
"22.40000","2.24024","16375.58301","3.91650"
"22.60000","2.26022","16586.42188","3.95144"
"22.80000","2.28015","16795.48438","3.98628"
"23.00000","2.30021","17008.34766","4.02135"
"23.20000","2.32012","17218.80664","4.05615"
"23.40000","2.34018","17430.82031","4.09122"
"23.60000","2.36018","17646.32422","4.12620"
"23.80000","2.38027","17855.77148","4.16131"
"24.00000","2.40020","18070.88672","4.19615"
"24.20000","2.42018","18283.80664","4.23109"
"24.40000","2.44021","18501.13672","4.26611"
"24.60000","2.46017","18717.72070","4.30100"
"24.80000","2.48020","18935.10742","4.33602"
"25.00000","2.50019","19155.02930","4.37096"
"25.20000","2.52017","19370.15430","4.40589"
"25.40000","2.54023","19593.93359","4.44095"
"25.60000","2.56018","19812.50000","4.47585"
"25.80000","2.58017","20034.69336","4.51078"
"26.00000","2.60025","20259.01953","4.54589"
"26.20000","2.62016","20478.17383","4.58069"
"26.40000","2.64024","20705.47852","4.61580"
"26.60000","2.66022","20929.21680","4.65074"
"26.80000","2.68023","21153.06445","4.68571"
"27.00000","2.70021","21382.83594","4.72065"
"27.20000","2.72019","21610.28711","4.75558"
"27.40000","2.74010","21838.57227","4.79038"
"27.60000","2.76018","22070.41211","4.82550"
"27.80000","2.78029","22294.41992","4.86065"
"28.00000","2.80022","22522.58594","4.89550"
"28.20000","2.82026","22745.17773","4.93052"
"28.40000","2.84016","22972.47461","4.96532"
"28.60000","2.86017","23198.48633","5.00030"
"28.80000","2.88025","23426.68750","5.03541"
"29.00000","2.90014","23646.48438","5.07017"
"29.20000","2.92019","23867.17383","5.10523"
"29.40000","2.94015","24083.64062","5.14012"
"29.60000","2.96013","24291.88086","5.17506"
"29.80000","2.98027","24497.84375","5.21026"
"30.00000","3.00022","24689.89062","5.24515"
"30.20000","3.02021","24878.58203","5.28008"
"30.40000","3.04019","25057.53906","5.31501"
"30.60000","3.06022","25222.79883","5.35004"
"30.80000","3.08023","25377.90234","5.38501"
"31.00000","3.10013","25519.65430","5.41982"
"31.20000","3.12019","25650.66211","5.45488"
"31.40000","3.14013","25773.93945","5.48973"
"31.60000","3.16023","25883.83008","5.52488"
"31.80000","3.18027","25985.70898","5.55991"
"32.00000","3.20015","26074.15625","5.59466"
"32.20000","3.22031","26156.86914","5.62991"
"32.40000","3.24019","26228.82422","5.66466"
"32.60000","3.26022","26292.01172","5.69969"
"32.80000","3.28020","26353.44531","5.73462"
"33.00000","3.30016","26403.50391","5.76951"
"33.20000","3.32024","26454.56445","5.80462"
"33.40000","3.34023","26493.83203","5.83955"
"33.60000","3.36016","26531.91992","5.87440"
"33.80000","3.38022","26569.42578","5.90947"
"34.00000","3.40022","26596.50195","5.94445"
"34.20000","3.42021","26627.20312","5.97938"
"34.40000","3.44019","26653.02539","6.01431"
"34.60000","3.46025","26679.46289","6.04938"
"34.80000","3.48020","26699.50977","6.08427"
"35.00000","3.50024","26721.37891","6.11929"
"35.20000","3.52022","26741.21484","6.15423"
"35.40000","3.54015","26757.98242","6.18907"
"35.60000","3.56026","26775.94922","6.22423"
"35.80000","3.58021","26790.92969","6.25912"
"36.00000","3.60025","26806.47656","6.29414"
"36.20000","3.62023","26823.08594","6.32907"
"36.40000","3.64011","26836.29688","6.36383"
"36.60000","3.66025","26851.49609","6.39903"
"36.80000","3.68018","26863.49219","6.43388"
"37.00000","3.70021","26874.86914","6.46890"
"37.20000","3.72019","26890.00000","6.50383"
"37.40000","3.74020","26900.92578","6.53881"
"37.60000","3.76018","26913.68750","6.57375"
"37.80000","3.78022","26925.19336","6.60877"
"38.00000","3.80020","26936.62695","6.64370"
"38.20000","3.82015","26949.49805","6.67859"
"38.40000","3.84026","26958.92969","6.71375"
"38.60000","3.86027","26971.72070","6.74872"
"38.80000","3.88018","26978.18555","6.78353"
"39.00000","3.90021","26992.76758","6.81855"
"39.20000","3.92014","27002.64844","6.85339"
"39.40000","3.94017","27014.97070","6.88842"
"39.60000","3.96028","27026.05469","6.92357"
"39.80000","3.98021","27034.10156","6.95842"
"40.00000","4.00022","27044.46289","6.99339"
"40.20000","4.02025","27055.33789","7.02842"
"40.40000","4.04021","27064.89258","7.06331"
"40.60000","4.06019","27077.34766","7.09824"
"40.80000","4.08018","27087.71289","7.13318"
"41.00000","4.10021","27099.42773","7.16820"
"41.20000","4.12019","27109.35742","7.20313"
"41.40000","4.14030","27117.31250","7.23829"
"41.60000","4.16013","27127.45117","7.27296"
"41.80000","4.18024","27137.50586","7.30811"
"42.00000","4.20022","27151.10156","7.34305"
"42.20000","4.22013","27159.86133","7.37785"
"42.40000","4.24029","27171.80469","7.41309"
"42.60000","4.26017","27181.59180","7.44785"
"42.80000","4.28025","27191.51172","7.48296"
"43.00000","4.30026","27202.72266","7.51794"
"43.20000","4.32012","27208.31055","7.55265"
"43.40000","4.34022","27223.39062","7.58780"
"43.60000","4.36021","27232.52539","7.62274"
"43.80000","4.38021","27243.61328","7.65772"
"44.00000","4.40022","27254.74609","7.69270"
"44.20000","4.42018","27262.02344","7.72759"
"44.40000","4.44021","27272.58594","7.76261"
"44.60000","4.46019","27281.50781","7.79754"
"44.80000","4.48020","27293.52734","7.83252"
"45.00000","4.50016","27304.35938","7.86741"
"45.20000","4.52019","27315.17773","7.90243"
"45.40000","4.54022","27324.35547","7.93745"
"45.60000","4.56018","27336.13477","7.97234"
"45.80000","4.58029","27345.63086","8.00750"
"46.00000","4.60017","27353.65234","8.04226"
"46.20000","4.62020","27362.67969","8.07728"
"46.40000","4.64026","27376.73242","8.11235"
"46.60000","4.66017","27385.14453","8.14715"
"46.80000","4.68023","27397.52734","8.18221"
"47.00000","4.70013","27406.52539","8.21702"
"47.20000","4.72017","27414.54492","8.25204"
"47.40000","4.74022","27427.84961","8.28710"
"47.60000","4.76026","27433.17188","8.32213"
"47.80000","4.78024","27444.24414","8.35706"
"48.00000","4.80022","27453.96875","8.39200"
"48.20000","4.82025","27466.72852","8.42702"
"48.40000","4.84016","27475.68555","8.46182"
"48.60000","4.86017","27484.27734","8.49680"
"48.80000","4.88023","27495.50977","8.53186"
"49.00000","4.90016","27504.10156","8.56671"
"49.20000","4.92029","27516.06641","8.60191"
"49.40000","4.94022","27524.11328","8.63675"
"49.60000","4.96018","27532.52148","8.67164"
"49.80000","4.98026","27544.42383","8.70675"
"50.00000","5.00015","27554.10742","8.74151"
"50.20000","5.02023","27564.90039","8.77662"
"50.40000","5.04024","27574.84570","8.81160"
"50.60000","5.06022","27582.34961","8.84654"
"50.80000","5.08025","27594.14062","8.88156"
"51.00000","5.10021","27601.68555","8.91645"
"51.20000","5.12017","27612.21289","8.95134"
"51.40000","5.14020","27625.75195","8.98636"
"51.60000","5.16026","27630.35938","9.02143"
"51.80000","5.18021","27643.00977","9.05632"
"52.00000","5.20025","27648.04883","9.09134"
"52.20000","5.22020","27657.06445","9.12623"
"52.40000","5.24016","27666.79297","9.16112"
"52.60000","5.26024","27677.74219","9.19623"
"52.80000","5.28013","27686.77148","9.23099"
"53.00000","5.30016","27697.27734","9.26601"
"53.20000","5.32019","27707.29297","9.30103"
"53.40000","5.34015","27713.44531","9.33592"
"53.60000","5.36028","27724.61133","9.37112"
"53.80000","5.38024","27732.43750","9.40601"
"54.00000","5.40022","27742.10547","9.44095"
"54.20000","5.42023","27750.48242","9.47592"
"54.40000","5.44021","27759.32617","9.51086"
"54.60000","5.46022","27769.27148","9.54584"
"54.80000","5.48015","27778.76562","9.58068"
"55.00000","5.50018","27786.59375","9.61570"
"55.20000","5.52009","27794.92969","9.65051"
"55.40000","5.54022","27804.48438","9.68570"
"55.60000","5.56031","27812.08398","9.72082"
"55.80000","5.58016","27820.90625","9.75553"
"56.00000","5.60032","27831.12500","9.79077"
"56.20000","5.62020","27840.40820","9.82553"
"56.40000","5.64018","27847.60547","9.86046"
"56.60000","5.66024","27856.73828","9.89553"
"56.80000","5.68017","27860.88867","9.93038"
"57.00000","5.70023","27872.66602","9.96544"
"57.20000","5.72024","27881.28906","10.00042"
"57.40000","5.74017","27889.01367","10.03527"
"57.60000","5.76023","27900.86523","10.07033"
"57.80000","5.78024","27904.42969","10.10531"
"58.00000","5.80017","27914.04102","10.14016"
"58.20000","5.82018","27920.94922","10.17514"
"58.40000","5.84029","27928.54297","10.21029"
"58.60000","5.86022","27937.02148","10.24514"
"58.80000","5.88023","27946.24609","10.28011"
"59.00000","5.90021","27953.44531","10.31505"
"59.20000","5.92009","27962.30859","10.34981"
"59.40000","5.94027","27971.67578","10.38509"
"59.60000","5.96023","27976.64648","10.41998"
"59.80000","5.98024","27983.18555","10.45496"
"60.00000","6.00027","27991.09570","10.48998"
"60.20000","6.02013","27999.13086","10.52470"
"60.40000","6.04026","28007.75195","10.55990"
"60.60000","6.06022","28015.46094","10.59479"
"60.80000","6.08015","28019.45508","10.62963"
"61.00000","6.10021","28032.46680","10.66470"
"61.20000","6.12014","28037.26562","10.69954"
"61.40000","6.14020","28045.81250","10.73461"
"61.60000","6.16025","28052.32031","10.76968"
"61.80000","6.18024","28057.30078","10.80461"
"62.00000","6.20019","28067.77344","10.83950"
"62.20000","6.22020","28073.89453","10.87448"
"62.40000","6.24023","28081.63672","10.90950"
"62.60000","6.26019","28086.72266","10.94439"
"62.80000","6.28020","28094.08984","10.97937"
"63.00000","6.30016","28100.30664","11.01426"
"63.20000","6.32014","28107.83594","11.04919"
"63.40000","6.34025","28117.24805","11.08435"
"63.60000","6.36018","28121.73438","11.11919"
"63.80000","6.38021","28129.30859","11.15422"
"64.00000","6.40024","28137.88086","11.18924"
"64.20000","6.42020","28141.01367","11.22413"
"64.40000","6.44021","28147.34375","11.25911"
"64.60000","6.46022","28154.93555","11.29408"
"64.80000","6.48022","28161.22461","11.32906"
"65.00000","6.50018","28170.71094","11.36395"
"65.20000","6.52026","28173.99805","11.39906"
"65.40000","6.54012","28180.34570","11.43378"
"65.60000","6.56025","28187.34375","11.46898"
"65.80000","6.58021","28192.04297","11.50387"
"66.00000","6.60012","28197.67578","11.53867"
"66.20000","6.62025","28205.30469","11.57387"
"66.40000","6.64023","28214.01562","11.60880"
"66.60000","6.66022","28216.90234","11.64374"
"66.80000","6.68025","28226.36328","11.67876"
"67.00000","6.70011","28227.85742","11.71347"
"67.20000","6.72019","28236.08203","11.74858"
"67.40000","6.74025","28241.82422","11.78365"
"67.60000","6.76023","28245.05664","11.81858"
"67.80000","6.78029","28253.71094","11.85365"
"68.00000","6.80017","28258.26953","11.88841"
"68.20000","6.82018","28265.86914","11.92338"
"68.40000","6.84023","28272.21484","11.95845"
"68.60000","6.86022","28274.18164","11.99338"
"68.80000","6.88017","28278.73242","12.02828"
"69.00000","6.90016","28285.53320","12.06321"
"69.20000","6.92019","28290.53320","12.09823"
"69.40000","6.94015","28298.51172","12.13312"
"69.60000","6.96030","28303.68945","12.16836"
"69.80000","6.98021","28308.32812","12.20317"
"70.00000","7.00022","28312.33398","12.23814"
"70.20000","7.02028","28314.97461","12.27321"
"70.40000","7.04016","28318.84375","12.30797"
"70.60000","7.06027","28325.25000","12.34312"
"70.80000","7.08015","28332.12305","12.37788"
"71.00000","7.10016","28336.86133","12.41286"
"71.20000","7.12019","28344.35156","12.44788"
"71.40000","7.14020","28346.62109","12.48286"
"71.60000","7.16023","28351.73047","12.51788"
"71.80000","7.18021","28356.40039","12.55282"
"72.00000","7.20029","28360.19336","12.58793"
"72.20000","7.22020","28363.05469","12.62273"
"72.40000","7.24018","28366.89648","12.65766"
"72.60000","7.26024","28375.26758","12.69273"
"72.80000","7.28015","28378.65625","12.72753"
"73.00000","7.30028","28385.66211","12.76273"
"73.20000","7.32024","28386.62500","12.79762"
"73.40000","7.34012","28389.46875","12.83238"
"73.60000","7.36030","28395.95117","12.86767"
"73.80000","7.38014","28397.53906","12.90233"
"74.00000","7.40019","28405.80664","12.93740"
"74.20000","7.42025","28410.16602","12.97247"
"74.40000","7.44021","28410.79883","13.00736"
"74.60000","7.46024","28416.26367","13.04238"
"74.80000","7.48020","28419.55469","13.07727"
"75.00000","7.50005","28421.38672","13.11198"
"75.20000","7.52024","28430.87695","13.14727"
"75.40000","7.54030","28430.35742","13.18234"
"75.60000","7.56023","28435.29492","13.21718"
"75.80000","7.58024","28436.71094","13.25216"
"76.00000","7.60019","28440.12109","13.28705"
"76.20000","7.62018","28442.96484","13.32199"
"76.40000","7.64028","28449.28125","13.35714"
"76.60000","7.66014","28451.20703","13.39185"
"76.80000","7.68015","28455.45508","13.42683"
"77.00000","7.70018","28460.84570","13.46185"
"77.20000","7.72014","28463.24805","13.49674"
"77.40000","7.74025","28467.91406","13.53190"
"77.60000","7.76025","28468.44531","13.56688"
"77.80000","7.78024","28470.62891","13.60181"
"78.00000","7.80027","28472.96875","13.63683"
"78.20000","7.82020","28476.57227","13.67168"
"78.40000","7.84023","28480.89844","13.70670"
"78.60000","7.86016","28485.25977","13.74155"
"78.80000","7.88017","28485.89648","13.77652"
"79.00000","7.90013","28491.44922","13.81141"
"79.20000","7.92021","28493.40234","13.84652"
"79.40000","7.94024","28493.40234","13.88155"
"79.60000","7.96018","28496.60742","13.91639"
"79.80000","7.98029","28498.28906","13.95155"
"80.00000","8.00022","28504.21875","13.98639"
"80.20000","8.02017","28504.12695","14.02128"
"80.40000","8.04023","28508.63672","14.05635"
"80.60000","8.06016","28509.39844","14.09120"
"80.80000","8.08020","28511.32227","14.12622"
"81.00000","8.10026","28515.32422","14.16128"
"81.20000","8.12019","28513.08008","14.19613"
"81.40000","8.14022","28518.70703","14.23115"
"81.60000","8.16023","28520.48047","14.26613"
"81.80000","8.18016","28522.91211","14.30098"
"82.00000","8.20017","28526.21094","14.33596"
"82.20000","8.22027","28527.49219","14.37111"
"82.40000","8.24026","28527.23828","14.40604"
"82.60000","8.26019","28529.26562","14.44089"
"82.80000","8.28022","28533.79492","14.47591"
"83.00000","8.30003","28537.10938","14.51054"
"83.20000","8.32026","28540.33789","14.54591"
"83.40000","8.34027","28539.56250","14.58089"
"83.60000","8.36023","28539.34375","14.61578"
"83.80000","8.38028","28540.47656","14.65085"
"84.00000","8.40012","28540.97461","14.68552"
"84.20000","8.42025","28544.78320","14.72071"
"84.40000","8.44023","28548.09375","14.75565"
"84.60000","8.46014","28547.52930","14.79045"
"84.80000","8.48022","28554.33594","14.82556"
"85.00000","8.50013","28552.24023","14.86036"
"85.20000","8.52019","28551.56055","14.89543"
"85.40000","8.54027","28555.92969","14.93054"
"85.60000","8.56025","28552.49609","14.96548"
"85.80000","8.58023","28553.93555","15.00041"
"86.00000","8.60022","28555.86914","15.03534"
"86.20000","8.62022","28559.04492","15.07032"
"86.40000","8.64018","28559.45898","15.10521"
"86.60000","8.66019","28559.77344","15.14019"
"86.80000","8.68017","28560.57617","15.17512"
"87.00000","8.70013","28561.45508","15.21001"
"87.20000","8.72026","28565.72852","15.24521"
"87.40000","8.74019","28563.80859","15.28006"
"87.60000","8.76020","28565.10938","15.31504"
"87.80000","8.78028","28566.00977","15.35015"
"88.00000","8.80019","28565.05859","15.38495"
"88.20000","8.82022","28567.74609","15.41997"
"88.40000","8.84021","28567.84180","15.45491"
"88.60000","8.86021","28565.63867","15.48988"
"88.80000","8.88020","28569.51953","15.52482"
"89.00000","8.90025","28568.35156","15.55988"
"89.20000","8.92016","28570.87305","15.59469"
"89.40000","8.94024","28572.32617","15.62980"
"89.60000","8.96023","28569.27734","15.66473"
"89.80000","8.98011","28569.07031","15.69949"
"90.00000","9.00024","28569.44531","15.73469"
"90.20000","9.02025","28571.94531","15.76967"
"90.40000","9.04021","28568.84570","15.80456"
"90.60000","9.06026","28572.29102","15.83962"
"90.80000","9.08010","28570.29492","15.87429"
"91.00000","9.10018","28572.79102","15.90940"
"91.20000","9.12026","28574.09180","15.94451"
"91.40000","9.14024","28568.33008","15.97945"
"91.60000","9.16028","28567.94922","16.01447"
"91.80000","9.18018","28566.22852","16.04927"
"92.00000","9.20017","28569.39648","16.08421"
"92.20000","9.22022","28572.09180","16.11927"
"92.40000","9.24021","28570.72266","16.15421"
"92.60000","9.26019","28570.07031","16.18914"
"92.80000","9.28015","28570.11523","16.22403"
"93.00000","9.30018","28567.65625","16.25905"
"93.20000","9.32019","28568.54297","16.29403"
"93.40000","9.34032","28566.86328","16.32923"
"93.60000","9.36025","28564.81055","16.36408"
"93.80000","9.38021","28563.97656","16.39896"
"94.00000","9.40027","28565.44922","16.43403"
"94.20000","9.42017","28562.80273","16.46883"
"94.40000","9.44023","28560.84180","16.50390"
"94.60000","9.46019","28562.62695","16.53879"
"94.80000","9.48012","28559.36328","16.57364"
"95.00000","9.50023","28563.10547","16.60879"
"95.20000","9.52021","28559.38086","16.64372"
"95.40000","9.54024","28555.83984","16.67875"
"95.60000","9.56023","28554.93750","16.71368"
"95.80000","9.58023","28551.35742","16.74866"
"96.00000","9.60022","28549.92188","16.78359"
"96.20000","9.62017","28549.51953","16.81848"
"96.40000","9.64026","28548.49609","16.85359"
"96.60000","9.66016","28545.82031","16.88840"
"96.80000","9.68025","28547.21289","16.92351"
"97.00000","9.70025","28544.05273","16.95849"
"97.20000","9.72013","28540.05664","16.99324"
"97.40000","9.74029","28538.30078","17.02849"
"97.60000","9.76012","28533.94727","17.06315"
"97.80000","9.78016","28531.28906","17.09818"
"98.00000","9.80024","28533.11914","17.13329"
"98.20000","9.82020","28529.38086","17.16818"
"98.40000","9.84026","28526.70898","17.20324"
"98.60000","9.86019","28522.95703","17.23809"
"98.80000","9.88007","28515.53320","17.27285"
"99.00000","9.90023","28519.12891","17.30809"
"99.20000","9.92029","28510.32617","17.34316"
"99.40000","9.94027","28508.74414","17.37809"
"99.60000","9.96023","28504.61914","17.41298"
"99.80000","9.98018","28501.33203","17.44787"
"100.00000","10.00019","28499.48047","17.48285"
"100.20000","10.02025","28495.48828","17.51792"
"100.40000","10.04018","28489.30859","17.55276"
"100.60000","10.06014","28482.16016","17.58765"
"100.80000","10.08020","28478.66406","17.62272"
"101.00000","10.10015","28471.18945","17.65761"
"101.20000","10.12024","28469.82422","17.69272"
"101.40000","10.14027","28462.61328","17.72774"
"101.60000","10.16018","28453.68164","17.76254"
"101.80000","10.18026","28450.54297","17.79765"
"102.00000","10.20019","28443.20898","17.83250"
"102.20000","10.22020","28435.53125","17.86748"
"102.40000","10.24020","28431.73242","17.90246"
"102.60000","10.26014","28421.52930","17.93730"
"102.80000","10.28017","28415.86133","17.97232"
"103.00000","10.30020","28407.23438","18.00735"
"103.20000","10.32024","28394.91406","18.04237"
"103.40000","10.34017","28389.40234","18.07722"
"103.60000","10.36025","28379.49414","18.11233"
"103.80000","10.38026","28370.83008","18.14730"
"104.00000","10.40016","28358.48047","18.18211"
"104.20000","10.42025","28352.07227","18.21722"
"104.40000","10.44018","28342.91406","18.25206"
"104.60000","10.46019","28328.89648","18.28704"
"104.80000","10.48027","28320.27344","18.32215"
"105.00000","10.50020","28304.33594","18.35700"
"105.20000","10.52026","28294.72461","18.39206"
"105.40000","10.54022","28280.83398","18.42695"
"105.60000","10.56015","28269.35742","18.46180"
"105.80000","10.58016","28259.23047","18.49678"
"106.00000","10.60027","28243.41602","18.53193"
"106.20000","10.62027","28228.58008","18.56691"
"106.40000","10.64020","28213.71289","18.60176"
"106.60000","10.66021","28198.81641","18.63673"
"106.80000","10.68004","28182.40430","18.67140"
"107.00000","10.70025","28169.20898","18.70673"
"107.20000","10.72028","28152.37305","18.74176"
"107.40000","10.74022","28136.69141","18.77660"
"107.60000","10.76027","28118.86914","18.81167"
"107.80000","10.78013","28101.62891","18.84638"
"108.00000","10.80021","28083.79492","18.88149"
"108.20000","10.82025","28067.55273","18.91652"
"108.40000","10.84013","28046.19727","18.95127"
"108.60000","10.86024","28029.20703","18.98643"
"108.80000","10.88012","28008.69727","19.02119"
"109.00000","10.90018","27989.55469","19.05625"
"109.20000","10.92029","27970.50195","19.09141"
"109.40000","10.94024","27944.17188","19.12630"
"109.60000","10.96025","27926.37695","19.16127"
"109.80000","10.98021","27902.62109","19.19616"
"110.00000","11.00021","27882.86719","19.23114"
"110.20000","11.02020","27861.04883","19.26608"
"110.40000","11.04015","27838.52148","19.30097"
"110.60000","11.06019","27813.29102","19.33599"
"110.80000","11.08012","27789.53906","19.37084"
"111.00000","11.10028","27764.03125","19.40608"
"111.20000","11.12021","27736.41406","19.44093"
"111.40000","11.14019","27712.64844","19.47586"
"111.60000","11.16030","27689.76172","19.51101"
"111.80000","11.18018","27661.58203","19.54577"
"112.00000","11.20021","27634.77539","19.58079"
"112.20000","11.22022","27609.31250","19.61577"
"112.40000","11.24020","27578.91797","19.65071"
"112.60000","11.26024","27555.73438","19.68573"
"112.80000","11.28024","27519.76562","19.72071"
"113.00000","11.30020","27492.79688","19.75560"
"113.20000","11.32021","27465.99609","19.79058"
"113.40000","11.34022","27434.90625","19.82555"
"113.60000","11.36012","27405.01758","19.86035"
"113.80000","11.38021","27372.70898","19.89547"
"114.00000","11.40029","27342.00391","19.93058"
"114.20000","11.42020","27308.22852","19.96538"
"114.40000","11.44025","27278.89648","20.00044"
"114.60000","11.46011","27244.96094","20.03516"
"114.80000","11.48014","27214.34766","20.07018"
"115.00000","11.50028","27179.44336","20.10538"
"115.20000","11.52021","27141.24414","20.14022"
"115.40000","11.54027","27109.29883","20.17529"
"115.60000","11.56020","27073.52734","20.21014"
"115.80000","11.58018","27037.05664","20.24507"
"116.00000","11.60026","27003.34766","20.28018"
"116.20000","11.62020","26964.31055","20.31503"
"116.40000","11.64018","26928.40430","20.34996"
"116.60000","11.66016","26889.52734","20.38489"
"116.80000","11.68017","26848.75391","20.41987"
"117.00000","11.70018","26811.63477","20.45485"
"117.20000","11.72028","26770.69531","20.49001"
"117.40000","11.74027","26732.07617","20.52494"
"117.60000","11.76017","26691.49414","20.55974"
"117.80000","11.78028","26650.35938","20.59490"
"118.00000","11.80019","26608.05664","20.62970"
"118.20000","11.82022","26563.11719","20.66472"
"118.40000","11.84018","26520.51172","20.69961"
"118.60000","11.86013","26474.79492","20.73450"
"118.80000","11.88022","26432.76953","20.76961"
"119.00000","11.90023","26385.76367","20.80459"
"119.20000","11.92023","26340.52930","20.83957"
"119.40000","11.94024","26294.52930","20.87455"
"119.60000","11.96022","26246.61328","20.90948"
"119.80000","11.98021","26198.12109","20.94442"
"120.00000","12.00016","26149.39453","20.97930"
"120.20000","12.02025","26099.18945","21.01441"
"120.40000","12.04020","26049.28906","21.04931"
"120.60000","12.06024","26000.49414","21.08433"
"120.80000","12.08027","25948.17578","21.11935"
"121.00000","12.10010","25896.62695","21.15402"
"121.20000","12.12028","25841.83203","21.18931"
"121.40000","12.14016","25787.56836","21.22406"
"121.60000","12.16015","25732.89258","21.25900"
"121.80000","12.18028","25678.27344","21.29419"
"122.00000","12.20019","25620.48047","21.32900"
"122.20000","12.22024","25562.55078","21.36406"
"122.40000","12.24020","25504.27930","21.39895"
"122.60000","12.26006","25442.97070","21.43367"
"122.80000","12.28022","25388.78320","21.46891"
"123.00000","12.30025","25320.44922","21.50393"
"123.20000","12.32026","25259.87305","21.53891"
"123.40000","12.34021","25195.99805","21.57380"
"123.60000","12.36020","25132.25977","21.60874"
"123.80000","12.38018","25067.23633","21.64367"
"124.00000","12.40024","24997.14844","21.67874"
"124.20000","12.42020","24927.81055","21.71363"
"124.40000","12.44013","24857.32227","21.74847"
"124.60000","12.46019","24785.46289","21.78354"
"124.80000","12.48017","24711.04492","21.81847"
"125.00000","12.50020","24637.86328","21.85350"
"125.20000","12.52028","24560.55273","21.88861"
"125.40000","12.54019","24482.14062","21.92341"
"125.60000","12.56025","24401.66016","21.95848"
"125.80000","12.58023","24317.73828","21.99341"
"126.00000","12.60021","24227.25781","22.02834"
"126.20000","12.62024","24133.30469","22.06336"
"126.40000","12.64015","24000.00195","22.09817"