File: Lab 2 - Monotonic Tensile and Fracture Toughness/test1.csv
Time,Extension,Load,Tensile strain (Extension)
(s),(mm),(N),(%)
"0.00000","0.00000","2.65744","0.00000"
"0.30000","0.01351","8.08780","0.02361"
"0.60000","0.02966","112.81239","0.05185"
"0.90000","0.04503","259.05777","0.07872"
"1.20000","0.06002","469.51575","0.10493"
"1.50000","0.07504","707.82581","0.13119"
"1.80000","0.09008","959.39886","0.15749"
"2.10000","0.10505","1218.35193","0.18366"
"2.40000","0.11999","1464.99744","0.20978"
"2.70000","0.13501","1705.94543","0.23604"
"3.00000","0.15006","1942.95923","0.26234"
"3.30000","0.16510","2178.81787","0.28864"
"3.60000","0.18012","2415.24951","0.31489"
"3.90000","0.19511","2653.91675","0.34110"
"4.20000","0.21013","2889.86304","0.36736"
"4.50000","0.22507","3122.16699","0.39348"
"4.80000","0.24012","3352.47144","0.41978"
"5.10000","0.25516","3575.98169","0.44608"
"5.40000","0.27013","3794.69995","0.47225"
"5.70000","0.28509","4003.34790","0.49842"
"6.00000","0.30009","4203.44336","0.52463"
"6.30000","0.31508","4399.12354","0.55084"
"6.60000","0.33005","4589.37891","0.57701"
"6.90000","0.34504","4770.64014","0.60322"
"7.20000","0.36003","4946.80908","0.62943"
"7.50000","0.37505","5120.01514","0.65569"
"7.80000","0.39005","5285.99170","0.68190"
"8.10000","0.40506","5449.31299","0.70815"
"8.40000","0.42006","5610.46777","0.73437"
"8.70000","0.43513","5767.03125","0.76071"
"9.00000","0.45012","5924.42285","0.78692"
"9.30000","0.46511","6078.31836","0.81313"
"9.60000","0.48011","6227.94385","0.83934"
"9.90000","0.49512","6381.07715","0.86560"
"10.20000","0.51012","6529.42285","0.89181"
"10.50000","0.52513","6676.83496","0.91807"
"10.80000","0.54013","6825.99609","0.94428"
"11.10000","0.55512","6970.40625","0.97049"
"11.40000","0.57009","7112.23193","0.99666"
"11.70000","0.58506","7254.83887","1.02283"
"12.00000","0.60005","7395.06641","1.04904"
"12.30000","0.61507","7535.91455","1.07529"
"12.60000","0.63004","7676.47559","1.10146"
"12.90000","0.64503","7816.43555","1.12767"
"13.20000","0.66007","7956.54346","1.15397"
"13.50000","0.67507","8099.84424","1.18018"
"13.80000","0.69006","8241.22754","1.20640"
"14.10000","0.70508","8385.35059","1.23265"
"14.40000","0.72015","8531.87207","1.25900"
"14.70000","0.73514","8674.57715","1.28521"
"15.00000","0.75008","8818.90625","1.31133"
"15.30000","0.76515","8965.39844","1.33767"
"15.60000","0.78017","9114.48145","1.36393"
"15.90000","0.79509","9261.40430","1.39001"
"16.20000","0.81010","9408.71191","1.41627"
"16.50000","0.82510","9555.64062","1.44248"
"16.80000","0.84009","9702.99219","1.46869"
"17.10000","0.85503","9848.83594","1.49481"
"17.40000","0.87003","9994.52930","1.52102"
"17.70000","0.88504","10139.39355","1.54728"
"18.00000","0.90004","10284.57324","1.57349"
"18.30000","0.91498","10426.23926","1.59961"
"18.60000","0.93005","10572.17188","1.62596"
"18.90000","0.94512","10715.88965","1.65230"
"19.20000","0.96011","10860.00684","1.67851"
"19.50000","0.97510","11007.41895","1.70473"
"19.80000","0.99012","11154.75293","1.73098"
"20.10000","1.00514","11299.00098","1.75724"
"20.40000","1.02008","11444.69336","1.78336"
"20.70000","1.03510","11589.95117","1.80962"
"21.00000","1.05017","11735.29590","1.83596"
"21.30000","1.06511","11878.90430","1.86208"
"21.60000","1.08003","12021.58984","1.88816"
"21.90000","1.09505","12165.10645","1.91442"
"22.20000","1.11004","12310.29102","1.94063"
"22.50000","1.12503","12456.52832","1.96684"
"22.80000","1.14003","12601.06250","1.99305"
"23.10000","1.15507","12750.71484","2.01935"
"23.40000","1.17009","12898.15039","2.04561"
"23.70000","1.18508","13043.30859","2.07182"
"24.00000","1.20005","13193.27344","2.09799"
"24.30000","1.21512","13342.75195","2.12433"
"24.60000","1.23014","13489.95996","2.15059"
"24.90000","1.24510","13641.56641","2.17675"
"25.20000","1.26012","13790.99805","2.20301"
"25.50000","1.27512","13940.49707","2.22922"
"25.80000","1.29011","14091.74512","2.25543"
"26.10000","1.30510","14243.88184","2.28165"
"26.40000","1.32009","14396.47363","2.30786"
"26.70000","1.33511","14553.78711","2.33411"
"27.00000","1.35011","14706.32227","2.36032"
"27.30000","1.36505","14858.92969","2.38645"
"27.60000","1.37999","15013.81738","2.41257"
"27.90000","1.39506","15169.08105","2.43892"
"28.20000","1.41005","15326.07715","2.46513"
"28.50000","1.42505","15483.64746","2.49134"
"28.80000","1.44006","15642.03320","2.51759"
"29.10000","1.45508","15802.80371","2.54385"
"29.40000","1.47010","15963.05078","2.57011"
"29.70000","1.48509","16121.77539","2.59632"
"30.00000","1.50011","16280.54980","2.62257"
"30.30000","1.51516","16441.93164","2.64887"
"30.60000","1.53017","16603.11328","2.67513"
"30.90000","1.54509","16762.30664","2.70121"
"31.20000","1.56011","16927.69922","2.72746"
"31.50000","1.57513","17089.72656","2.75372"
"31.80000","1.59007","17252.17578","2.77984"
"32.10000","1.60504","17415.31445","2.80601"
"32.40000","1.62006","17580.36914","2.83227"
"32.70000","1.63507","17745.64648","2.85852"
"33.00000","1.65004","17909.70508","2.88469"
"33.30000","1.66506","18074.75781","2.91095"
"33.60000","1.68008","18241.36523","2.93720"
"33.90000","1.69505","18405.15039","2.96337"
"34.20000","1.71001","18571.33594","2.98954"
"34.50000","1.72506","18741.23242","3.01584"
"34.80000","1.74015","18910.38867","3.04222"
"35.10000","1.75512","19076.25586","3.06839"
"35.40000","1.77016","19246.04688","3.09469"
"35.70000","1.78513","19414.67188","3.12086"
"36.00000","1.80017","19583.28906","3.14716"
"36.30000","1.81507","19751.22461","3.17319"
"36.60000","1.83011","19921.03906","3.19949"
"36.90000","1.84513","20089.34961","3.22575"
"37.20000","1.86010","20259.49609","3.25192"
"37.50000","1.87501","20429.61328","3.27800"
"37.80000","1.89003","20599.61328","3.30425"
"38.10000","1.90503","20772.94336","3.33046"
"38.40000","1.92004","20944.00195","3.35672"
"38.70000","1.93504","21113.05859","3.38293"
"39.00000","1.95008","21286.47656","3.40923"
"39.30000","1.96510","21457.77539","3.43549"
"39.60000","1.98012","21629.57617","3.46174"
"39.90000","1.99511","21802.00977","3.48795"
"40.20000","2.01013","21973.40039","3.51421"
"40.50000","2.02515","22143.87305","3.54046"
"40.80000","2.04011","22318.29297","3.56663"
"41.10000","2.05511","22489.96289","3.59284"
"41.40000","2.07012","22663.66797","3.61910"
"41.70000","2.08512","22836.39258","3.64531"
"42.00000","2.10009","23004.83594","3.67148"
"42.30000","2.11503","23173.50391","3.69760"
"42.60000","2.13007","23343.46680","3.72390"
"42.90000","2.14507","23511.60742","3.75011"
"43.20000","2.16003","23678.06055","3.77628"
"43.50000","2.17503","23842.87695","3.80249"
"43.80000","2.19007","24005.59180","3.82879"
"44.10000","2.20509","24166.97852","3.85505"
"44.40000","2.22003","24327.76953","3.88117"
"44.70000","2.23510","24484.80469","3.90752"
"45.00000","2.25012","24637.41992","3.93377"
"45.30000","2.26511","24786.29492","3.95998"
"45.60000","2.28010","24929.10547","3.98619"
"45.90000","2.29515","25071.43945","4.01249"
"46.20000","2.31014","25207.42773","4.03871"
"46.50000","2.32513","25338.27930","4.06492"
"46.80000","2.34005","25464.35352","4.09100"
"47.10000","2.35514","25585.65430","4.11738"
"47.40000","2.37014","25695.30859","4.14360"
"47.70000","2.38503","25802.39453","4.16963"
"48.00000","2.40000","25904.57422","4.19580"
"48.30000","2.41507","25999.05469","4.22214"
"48.60000","2.43008","26087.67383","4.24840"
"48.90000","2.44503","26171.51172","4.27452"
"49.20000","2.46007","26251.20312","4.30082"
"49.50000","2.47506","26325.01758","4.32703"
"49.80000","2.49008","26393.59180","4.35329"
"50.10000","2.50500","26456.08789","4.37937"
"50.40000","2.52012","26519.59961","4.40580"
"50.70000","2.53519","26573.89258","4.43214"
"51.00000","2.55018","26622.42578","4.45836"
"51.30000","2.56512","26670.02734","4.48448"
"51.60000","2.58014","26714.71875","4.51074"
"51.90000","2.59513","26754.39062","4.53695"
"52.20000","2.61005","26790.62500","4.56303"
"52.50000","2.62507","26825.61914","4.58928"
"52.80000","2.64011","26858.38086","4.61558"
"53.10000","2.65508","26886.88281","4.64175"
"53.40000","2.67002","26912.77539","4.66787"
"53.70000","2.68502","26941.79492","4.69408"
"54.00000","2.70003","26964.64648","4.72034"
"54.30000","2.71503","26986.15430","4.74655"
"54.60000","2.73005","27007.07617","4.77281"
"54.90000","2.74511","27028.46484","4.79915"
"55.20000","2.76018","27047.39258","4.82550"
"55.50000","2.77510","27065.16406","4.85157"
"55.80000","2.79012","27082.60742","4.87783"
"56.10000","2.80514","27098.25391","4.90409"
"56.40000","2.82016","27111.97070","4.93034"
"56.70000","2.83510","27125.94922","4.95647"
"57.00000","2.85012","27139.98047","4.98272"
"57.30000","2.86508","27153.33398","5.00889"
"57.60000","2.88008","27166.25391","5.03510"
"57.90000","2.89505","27176.11133","5.06127"
"58.20000","2.91001","27189.95117","5.08744"
"58.50000","2.92508","27201.82227","5.11378"
"58.80000","2.94007","27209.63672","5.13999"
"59.10000","2.95504","27220.73242","5.16616"
"59.40000","2.97001","27231.46680","5.19233"
"59.70000","2.98513","27241.58203","5.21876"
"60.00000","3.00010","27251.56836","5.24493"
"60.30000","3.01507","27260.55078","5.27109"
"60.60000","3.03011","27269.83984","5.29739"
"60.90000","3.04515","27280.80664","5.32369"
"61.20000","3.06015","27289.78711","5.34990"
"61.50000","3.07511","27299.08008","5.37607"
"61.80000","3.09016","27311.59570","5.40237"
"62.10000","3.10515","27318.45898","5.42858"
"62.40000","3.12012","27325.71680","5.45475"
"62.70000","3.13503","27334.06445","5.48083"
"63.00000","3.15010","27342.60547","5.50717"
"63.30000","3.16510","27348.73047","5.53339"
"63.60000","3.18001","27358.09961","5.55946"
"63.90000","3.19501","27367.02539","5.58568"
"64.20000","3.21008","27373.11328","5.61202"
"64.50000","3.22509","27382.36523","5.63828"
"64.80000","3.24006","27392.18555","5.66444"
"65.10000","3.25511","27400.38086","5.69074"
"65.40000","3.27012","27409.33594","5.71700"
"65.70000","3.28509","27415.48047","5.74317"
"66.00000","3.30003","27424.09180","5.76929"
"66.30000","3.31515","27435.56836","5.79572"
"66.60000","3.33020","27441.55469","5.82202"
"66.90000","3.34516","27447.90234","5.84819"
"67.20000","3.36011","27457.50586","5.87431"
"67.50000","3.37513","27465.62695","5.90057"
"67.80000","3.39009","27472.03711","5.92674"
"68.10000","3.40504","27480.16797","5.95286"
"68.40000","3.42008","27488.25781","5.97916"
"68.70000","3.43510","27494.33008","6.00541"
"69.00000","3.45004","27501.85938","6.03154"
"69.30000","3.46503","27509.98438","6.05775"
"69.60000","3.48003","27517.74219","6.08396"
"69.90000","3.49504","27526.88477","6.11022"
"70.20000","3.51001","27533.35156","6.13639"
"70.50000","3.52503","27542.45117","6.16264"
"70.80000","3.54015","27553.69531","6.18907"
"71.10000","3.55519","27559.55469","6.21537"
"71.40000","3.57014","27565.98047","6.24150"
"71.70000","3.58515","27575.82422","6.26775"
"72.00000","3.60020","27584.65430","6.29405"
"72.30000","3.61514","27591.41016","6.32017"
"72.60000","3.63011","27598.03906","6.34634"
"72.90000","3.64510","27603.33789","6.37255"
"73.20000","3.66007","27613.51758","6.39872"
"73.50000","3.67506","27621.94922","6.42493"
"73.80000","3.69000","27627.91602","6.45106"
"74.10000","3.70497","27635.95508","6.47722"
"74.40000","3.72007","27644.54688","6.50361"
"74.70000","3.73508","27649.06250","6.52987"
"75.00000","3.75010","27656.30469","6.55612"
"75.30000","3.76505","27665.55859","6.58225"
"75.60000","3.78016","27672.41211","6.60868"
"75.90000","3.79513","27679.03516","6.63485"
"76.20000","3.81008","27687.28125","6.66097"
"76.50000","3.82512","27694.87500","6.68727"
"76.80000","3.84014","27705.62109","6.71353"
"77.10000","3.85513","27713.38477","6.73974"
"77.40000","3.87010","27720.18359","6.76590"
"77.70000","3.88512","27729.19141","6.79216"
"78.00000","3.90011","27735.91211","6.81837"
"78.30000","3.91510","27740.45703","6.84458"
"78.60000","3.92999","27747.58594","6.87062"
"78.90000","3.94509","27755.49023","6.89701"
"79.20000","3.96011","27761.53125","6.92326"
"79.50000","3.97500","27769.32031","6.94930"
"79.80000","3.99002","27778.82227","6.97555"
"80.10000","4.00511","27785.88477","7.00194"
"80.40000","4.02010","27793.24414","7.02815"
"80.70000","4.03505","27798.72461","7.05428"
"81.00000","4.05012","27807.31836","7.08062"
"81.30000","4.06513","27817.11133","7.10688"
"81.60000","4.08010","27823.70117","7.13304"
"81.90000","4.09507","27830.41602","7.15921"
"82.20000","4.11016","27841.04297","7.18560"
"82.50000","4.12523","27847.25195","7.21194"
"82.80000","4.14015","27852.12305","7.23802"
"83.10000","4.15512","27860.81055","7.26419"
"83.40000","4.17011","27867.31445","7.29040"
"83.70000","4.18505","27873.16992","7.31653"
"84.00000","4.20000","27880.54688","7.34265"
"84.30000","4.21506","27887.92188","7.36899"
"84.60000","4.23006","27894.85156","7.39520"
"84.90000","4.24505","27901.22656","7.42142"
"85.20000","4.26004","27907.78320","7.44763"
"85.50000","4.27506","27914.54102","7.47388"
"85.80000","4.29008","27923.78906","7.50014"
"86.10000","4.30505","27930.64062","7.52631"
"86.40000","4.32009","27938.40820","7.55261"
"86.70000","4.33518","27947.56250","7.57899"
"87.00000","4.35018","27951.39648","7.60520"
"87.30000","4.36510","27957.92773","7.63128"
"87.60000","4.38014","27965.44727","7.65758"
"87.90000","4.39516","27971.57422","7.68384"
"88.20000","4.41012","27978.72070","7.71001"
"88.50000","4.42507","27984.89258","7.73613"
"88.80000","4.44006","27993.05664","7.76234"
"89.10000","4.45503","28001.75195","7.78851"
"89.40000","4.47002","28007.07812","7.81472"
"89.70000","4.48501","28011.57812","7.84093"
"90.00000","4.50001","28020.02734","7.86715"
"90.30000","4.51510","28026.83789","7.89353"
"90.60000","4.53009","28030.56836","7.91975"
"90.90000","4.54509","28038.66211","7.94596"
"91.20000","4.56008","28044.12500","7.97217"
"91.50000","4.57515","28051.13477","7.99851"
"91.80000","4.59012","28061.32812","8.02468"
"92.10000","4.60508","28067.33008","8.05085"
"92.40000","4.62015","28075.93945","8.07719"
"92.70000","4.63515","28082.29883","8.10340"
"93.00000","4.65011","28087.67578","8.12957"
"93.30000","4.66508","28093.76172","8.15574"
"93.60000","4.68013","28102.68750","8.18204"
"93.90000","4.69512","28106.82617","8.20825"
"94.20000","4.71006","28112.23047","8.23437"
"94.50000","4.72498","28117.48633","8.26045"
"94.80000","4.74010","28126.47266","8.28688"
"95.10000","4.75507","28130.62109","8.31305"
"95.40000","4.77001","28137.00391","8.33918"
"95.70000","4.78503","28144.14844","8.36543"
"96.00000","4.80012","28151.01953","8.39182"
"96.30000","4.81514","28156.23047","8.41807"
"96.60000","4.83011","28162.25586","8.44424"
"96.90000","4.84512","28169.11719","8.47050"
"97.20000","4.86014","28177.99805","8.49675"
"97.50000","4.87509","28181.58203","8.52288"
"97.80000","4.89005","28189.80469","8.54905"
"98.10000","4.90517","28199.62109","8.57548"
"98.40000","4.92017","28202.48633","8.60169"
"98.70000","4.93511","28206.44922","8.62781"
"99.00000","4.95008","28213.69141","8.65398"
"99.30000","4.96509","28217.94727","8.68023"
"99.60000","4.98004","28222.06641","8.70636"
"99.90000","4.99503","28227.52539","8.73257"
"100.20000","5.01007","28234.79102","8.75887"
"100.50000","5.02509","28241.83203","8.78513"
"100.80000","5.04008","28247.50781","8.81134"
"101.10000","5.05503","28254.24609","8.83746"
"101.40000","5.07007","28262.28516","8.86376"
"101.70000","5.08509","28267.71680","8.89002"
"102.00000","5.10006","28272.13086","8.91618"
"102.30000","5.11510","28277.19727","8.94248"
"102.60000","5.13019","28285.76562","8.96887"
"102.90000","5.14519","28288.66602","8.99508"
"103.20000","5.16013","28292.84961","9.02121"
"103.50000","5.17512","28300.70312","9.04742"
"103.80000","5.19014","28305.27734","9.07367"
"104.10000","5.20511","28310.12695","9.09984"
"104.40000","5.22003","28315.94336","9.12592"
"104.70000","5.23505","28322.77344","9.15218"
"105.00000","5.25001","28329.50977","9.17834"
"105.30000","5.26503","28333.53906","9.20460"
"105.60000","5.28000","28336.35156","9.23077"
"105.90000","5.29502","28344.34766","9.25702"
"106.20000","5.31014","28349.50391","9.28345"
"106.50000","5.32513","28352.99414","9.30967"
"106.80000","5.34012","28359.05273","9.33588"
"107.10000","5.35509","28365.83789","9.36205"
"107.40000","5.37021","28372.85742","9.38848"
"107.70000","5.38513","28377.16992","9.41456"
"108.00000","5.40009","28381.65430","9.44072"
"108.30000","5.41514","28389.33203","9.46703"
"108.60000","5.43016","28394.60938","9.49328"
"108.90000","5.44510","28397.73242","9.51940"
"109.20000","5.46007","28400.78711","9.54557"
"109.50000","5.47506","28407.03711","9.57178"
"109.80000","5.49005","28411.91797","9.59800"
"110.10000","5.50502","28416.18945","9.62416"
"110.40000","5.51999","28422.23047","9.65033"
"110.70000","5.53511","28427.86523","9.67676"
"111.00000","5.55010","28428.84570","9.70297"
"111.30000","5.56504","28435.29492","9.72910"
"111.60000","5.58006","28442.07227","9.75535"
"111.90000","5.59513","28447.26758","9.78170"
"112.20000","5.61012","28451.75586","9.80791"
"112.50000","5.62509","28455.82031","9.83408"
"112.80000","5.64016","28462.39258","9.86042"
"113.10000","5.65513","28469.10938","9.88659"
"113.40000","5.67007","28471.41016","9.91271"
"113.70000","5.68506","28477.37109","9.93892"
"114.00000","5.70016","28483.10156","9.96531"
"114.30000","5.71518","28483.93945","9.99157"
"114.60000","5.73009","28486.74609","10.01764"
"114.90000","5.74506","28491.61328","10.04381"
"115.20000","5.76005","28495.90820","10.07002"
"115.50000","5.77502","28500.82422","10.09619"
"115.80000","5.79001","28506.46289","10.12240"
"116.10000","5.80508","28511.92383","10.14875"
"116.40000","5.82010","28515.82812","10.17500"
"116.70000","5.83509","28519.32617","10.20121"
"117.00000","5.85006","28523.16797","10.22738"
"117.30000","5.86511","28529.98047","10.25368"
"117.60000","5.88010","28533.16016","10.27989"
"117.90000","5.89509","28537.13672","10.30610"
"118.20000","5.91014","28541.94727","10.33240"
"118.50000","5.92520","28547.10742","10.35875"
"118.80000","5.94015","28548.39844","10.38487"
"119.10000","5.95509","28553.65820","10.41100"
"119.40000","5.97008","28559.50586","10.43721"
"119.70000","5.98510","28562.54492","10.46346"
"120.00000","6.00007","28565.88086","10.48963"
"120.30000","6.01501","28567.27539","10.51575"
"120.60000","6.03005","28572.55664","10.54205"
"120.90000","6.04505","28575.93945","10.56827"
"121.20000","6.06004","28580.10547","10.59448"
"121.50000","6.07503","28582.59961","10.62069"
"121.80000","6.09005","28587.96680","10.64694"
"122.10000","6.10515","28593.46484","10.67333"
"122.40000","6.12014","28594.40820","10.69954"
"122.70000","6.13511","28600.63086","10.72571"
"123.00000","6.15010","28605.15430","10.75192"
"123.30000","6.16519","28609.64258","10.77831"
"123.60000","6.18011","28612.50977","10.80439"
"123.90000","6.19508","28616.13281","10.83056"
"124.20000","6.21015","28619.95898","10.85690"
"124.50000","6.22514","28624.34180","10.88311"
"124.80000","6.24008","28626.65039","10.90924"
"125.10000","6.25505","28630.75977","10.93540"
"125.40000","6.27007","28635.07031","10.96166"
"125.70000","6.28506","28637.34375","10.98787"
"126.00000","6.30003","28637.20703","11.01404"
"126.30000","6.31500","28642.02930","11.04021"
"126.60000","6.33014","28648.86133","11.06668"
"126.90000","6.34509","28649.13086","11.09281"
"127.20000","6.36005","28651.62500","11.11897"
"127.50000","6.37510","28656.08984","11.14527"
"127.80000","6.39017","28661.33789","11.17162"
"128.10000","6.40516","28666.48047","11.19783"
"128.40000","6.42013","28667.89648","11.22400"
"128.70000","6.43512","28671.26562","11.25021"
"129.00000","6.45016","28675.73242","11.27651"
"129.30000","6.46505","28675.42188","11.30254"
"129.60000","6.48005","28680.80469","11.32876"
"129.90000","6.49514","28685.00977","11.35514"
"130.20000","6.51011","28683.45703","11.38131"
"130.50000","6.52503","28685.13672","11.40739"
"130.80000","6.54005","28688.28125","11.43365"
"131.10000","6.55506","28691.02344","11.45990"
"131.40000","6.57003","28695.50586","11.48607"
"131.70000","6.58505","28700.14062","11.51232"
"132.00000","6.60009","28701.80859","11.53862"
"132.30000","6.61511","28705.04492","11.56488"
"132.60000","6.63011","28707.33203","11.59109"
"132.90000","6.64510","28710.04102","11.61730"
"133.20000","6.66014","28713.81641","11.64360"
"133.50000","6.67508","28716.67969","11.66973"
"133.80000","6.69008","28718.08789","11.69594"
"134.10000","6.70510","28722.82227","11.72219"
"134.40000","6.72016","28726.61133","11.74854"
"134.70000","6.73513","28725.15234","11.77471"
"135.00000","6.75007","28726.27344","11.80083"
"135.30000","6.76507","28730.33008","11.82704"
"135.60000","6.78009","28731.87109","11.85330"
"135.90000","6.79508","28734.79688","11.87951"
"136.20000","6.81002","28735.44922","11.90563"
"136.50000","6.82506","28738.83789","11.93193"
"136.80000","6.84003","28742.11133","11.95810"
"137.10000","6.85505","28746.64648","11.98436"
"137.40000","6.87004","28747.23633","12.01057"
"137.70000","6.88506","28751.42188","12.03682"
"138.00000","6.90016","28753.89062","12.06321"
"138.30000","6.91517","28753.80273","12.08947"
"138.60000","6.93014","28755.88867","12.11563"
"138.90000","6.94513","28759.07422","12.14184"
"139.20000","6.96020","28762.75195","12.16819"
"139.50000","6.97512","28763.38086","12.19427"
"139.80000","6.99006","28763.62891","12.22039"
"140.10000","7.00511","28767.16602","12.24669"
"140.40000","7.02007","28769.83594","12.27286"
"140.70000","7.03504","28772.10938","12.29903"
"141.00000","7.05001","28773.22070","12.32519"
"141.30000","7.06505","28775.98047","12.35149"
"141.60000","7.08007","28775.24219","12.37775"
"141.90000","7.09504","28774.85156","12.40392"
"142.20000","7.11003","28778.17773","12.43013"
"142.50000","7.12518","28780.23047","12.45660"
"142.80000","7.14009","28780.48633","12.48268"
"143.10000","7.15506","28785.11523","12.50885"
"143.40000","7.17013","28790.52148","12.53519"
"143.70000","7.18518","28793.37891","12.56150"
"144.00000","7.20014","28793.05859","12.58766"
"144.30000","7.21511","28793.73633","12.61383"
"144.60000","7.23013","28794.80469","12.64009"
"144.90000","7.24512","28796.04688","12.66630"
"145.20000","7.26001","28794.31250","12.69233"
"145.50000","7.27501","28797.83789","12.71854"
"145.80000","7.29013","28800.02930","12.74498"
"146.10000","7.30509","28798.64844","12.77114"
"146.40000","7.32004","28800.63867","12.79727"
"146.70000","7.33503","28804.71875","12.82348"
"147.00000","7.35007","28805.76172","12.84978"
"147.30000","7.36504","28805.76172","12.87595"
"147.60000","7.38006","28807.52930","12.90220"
"147.90000","7.39515","28807.94141","12.92859"
"148.20000","7.41015","28809.03516","12.95480"
"148.50000","7.42509","28810.01758","12.98092"
"148.80000","7.44011","28812.19727","13.00718"
"149.10000","7.45515","28816.64844","13.03348"
"149.40000","7.47009","28816.07617","13.05960"
"149.70000","7.48509","28817.45312","13.08582"
"150.00000","7.50010","28820.21289","13.11207"
"150.30000","7.51515","28820.51172","13.13837"
"150.60000","7.53012","28819.53516","13.16454"
"150.90000","7.54506","28819.76953","13.19066"
"151.20000","7.56005","28818.81641","13.21687"
"151.50000","7.57507","28820.13086","13.24313"
"151.80000","7.59004","28821.32031","13.26930"
"152.10000","7.60503","28822.83008","13.29551"
"152.40000","7.62007","28824.46094","13.32181"
"152.70000","7.63507","28826.12109","13.34802"
"153.00000","7.65009","28825.80469","13.37428"
"153.30000","7.66508","28825.35156","13.40049"
"153.60000","7.68010","28830.03320","13.42674"
"153.90000","7.69517","28831.29102","13.45309"
"154.20000","7.71016","28829.15234","13.47930"
"154.50000","7.72513","28829.76172","13.50547"
"154.80000","7.74012","28831.42578","13.53168"
"155.10000","7.75516","28832.27539","13.55798"
"155.40000","7.77006","28832.04297","13.58401"
"155.70000","7.78505","28833.95312","13.61023"
"156.00000","7.80007","28834.66406","13.63648"
"156.30000","7.81508","28834.97461","13.66273"
"156.60000","7.83005","28833.33594","13.68890"
"156.90000","7.84505","28832.14062","13.71511"
"157.20000","7.86009","28833.88672","13.74141"
"157.50000","7.87511","28832.07812","13.76767"
"157.80000","7.89002","28832.20312","13.79375"
"158.10000","7.90507","28834.89453","13.82005"
"158.40000","7.92016","28837.10352","13.84644"
"158.70000","7.93510","28836.22070","13.87256"
"159.00000","7.95007","28836.65625","13.89873"
"159.30000","7.96514","28838.91211","13.92507"
"159.60000","7.98018","28839.26953","13.95137"
"159.90000","7.99515","28838.14062","13.97754"
"160.20000","8.01012","28834.54297","14.00371"
"160.50000","8.02511","28834.97266","14.02992"
"160.80000","8.04011","28835.31836","14.05613"
"161.10000","8.05497","28831.35156","14.08212"
"161.40000","8.06997","28835.16797","14.10833"
"161.70000","8.08511","28836.30469","14.13481"
"162.00000","8.10008","28832.86719","14.16098"
"162.30000","8.11507","28832.55273","14.18719"
"162.60000","8.13006","28834.94141","14.21340"
"162.90000","8.14511","28831.99219","14.23970"
"163.20000","8.16005","28831.68750","14.26582"
"163.50000","8.17509","28833.56836","14.29212"
"163.80000","8.19016","28832.29883","14.31847"
"164.10000","8.20518","28831.75391","14.34472"
"164.40000","8.22012","28832.01172","14.37085"
"164.70000","8.23509","28831.98242","14.39701"
"165.00000","8.25014","28833.94336","14.42331"
"165.30000","8.26505","28830.43555","14.44939"
"165.60000","8.28007","28828.38477","14.47565"
"165.90000","8.29506","28827.78125","14.50186"
"166.20000","8.31013","28826.87695","14.52820"
"166.50000","8.32508","28822.83984","14.55433"
"166.80000","8.34004","28822.16211","14.58049"
"167.10000","8.35506","28821.48242","14.60675"
"167.40000","8.37008","28821.50977","14.63301"
"167.70000","8.38507","28821.41211","14.65922"
"168.00000","8.40004","28820.13672","14.68538"
"168.30000","8.41511","28819.90625","14.71173"
"168.60000","8.43008","28817.92188","14.73790"
"168.90000","8.44510","28815.05469","14.76415"
"169.20000","8.46006","28812.08594","14.79032"
"169.50000","8.47511","28813.46680","14.81662"
"169.80000","8.49018","28813.32617","14.84296"
"170.10000","8.50517","28809.16797","14.86917"
"170.40000","8.52011","28808.71289","14.89530"
"170.70000","8.53513","28807.96484","14.92155"
"171.00000","8.55012","28803.65039","14.94777"
"171.30000","8.56504","28801.04492","14.97384"
"171.60000","8.58003","28797.51953","15.00006"
"171.90000","8.59505","28795.22461","15.02631"
"172.20000","8.61007","28791.84570","15.05257"
"172.50000","8.62504","28787.32031","15.07874"
"172.80000","8.64006","28786.04297","15.10499"
"173.10000","8.65510","28785.36328","15.13129"
"173.40000","8.67009","28782.32812","15.15750"
"173.70000","8.68506","28779.63281","15.18367"
"174.00000","8.70013","28780.13477","15.21001"
"174.30000","8.71520","28775.88867","15.23636"
"174.60000","8.73009","28768.44922","15.26239"
"174.90000","8.74511","28766.43555","15.28865"
"175.20000","8.76013","28763.17773","15.31490"
"175.50000","8.77517","28760.23047","15.34120"
"175.80000","8.79009","28753.99805","15.36728"
"176.10000","8.80508","28749.96875","15.39350"
"176.40000","8.82007","28746.38477","15.41971"
"176.70000","8.83507","28741.24023","15.44592"
"177.00000","8.84993","28734.43164","15.47191"
"177.30000","8.86500","28734.37109","15.49826"
"177.60000","8.88012","28731.44141","15.52469"
"177.90000","8.89511","28721.43945","15.55090"
"178.20000","8.91008","28716.07617","15.57706"
"178.50000","8.92510","28710.65820","15.60332"
"178.80000","8.94012","28704.62305","15.62958"
"179.10000","8.95509","28700.36914","15.65574"
"179.40000","8.97008","28695.80664","15.68196"
"179.70000","8.98517","28689.34961","15.70835"
"180.00000","9.00014","28684.90234","15.73451"
"180.30000","9.01511","28678.64453","15.76068"
"180.60000","9.03013","28672.42969","15.78693"
"180.90000","9.04512","28666.37695","15.81315"
"181.20000","9.06004","28655.65039","15.83923"
"181.50000","9.07506","28647.07422","15.86548"
"181.80000","9.09007","28640.15039","15.89174"
"182.10000","9.10509","28632.20898","15.91799"
"182.40000","9.12009","28623.49414","15.94421"
"182.70000","9.13503","28615.64453","15.97033"
"183.00000","9.15007","28608.49414","15.99663"
"183.30000","9.16511","28599.04688","16.02293"
"183.60000","9.18008","28590.35352","16.04910"
"183.90000","9.19508","28581.67578","16.07531"
"184.20000","9.21009","28573.37305","16.10156"
"184.50000","9.22511","28564.61914","16.12782"
"184.80000","9.24013","28554.82031","16.15407"
"185.10000","9.25510","28544.42969","16.18024"
"185.40000","9.27012","28537.00000","16.20650"
"185.70000","9.28519","28525.60352","16.23284"
"186.00000","9.30013","28512.52539","16.25897"
"186.30000","9.31507","28503.25977","16.28509"
"186.60000","9.33009","28492.76953","16.31134"
"186.90000","9.34508","28478.61328","16.33755"
"187.20000","9.36002","28466.58008","16.36368"
"187.50000","9.37502","28454.87305","16.38989"
"187.80000","9.39006","28441.93555","16.41619"
"188.10000","9.40508","28429.73438","16.44244"
"188.40000","9.42007","28416.69922","16.46866"
"188.70000","9.43509","28405.90820","16.49491"
"189.00000","9.45013","28394.28125","16.52121"
"189.30000","9.46513","28378.03320","16.54743"
"189.60000","9.48004","28364.69141","16.57350"
"189.90000","9.49516","28353.20312","16.59994"
"190.20000","9.51018","28336.13672","16.62619"
"190.50000","9.52510","28320.08984","16.65227"
"190.80000","9.54009","28307.95312","16.67848"
"191.10000","9.55511","28293.89844","16.70474"
"191.40000","9.57015","28277.67773","16.73104"
"191.70000","9.58507","28260.90820","16.75712"
"192.00000","9.60006","28243.71094","16.78333"
"192.30000","9.61506","28227.98242","16.80954"
"192.60000","9.63005","28210.38086","16.83575"
"192.90000","9.64494","28192.03711","16.86179"
"193.20000","9.66004","28178.20703","16.88817"
"193.50000","9.67513","28160.64062","16.91456"
"193.80000","9.69010","28141.28320","16.94073"
"194.10000","9.70512","28125.67578","16.96699"
"194.40000","9.72008","28107.88086","16.99315"
"194.70000","9.73515","28092.06250","17.01950"
"195.00000","9.75010","28073.50195","17.04562"
"195.30000","9.76514","28055.59375","17.07192"
"195.60000","9.78021","28034.35547","17.09826"
"195.90000","9.79518","28015.08594","17.12443"
"196.20000","9.81007","27993.42773","17.15047"
"196.50000","9.82509","27974.24805","17.17672"
"196.80000","9.84008","27956.49219","17.20294"
"197.10000","9.85500","27935.64844","17.22901"
"197.40000","9.87002","27914.87500","17.25527"
"197.70000","9.88503","27894.03125","17.28153"
"198.00000","9.90008","27870.18164","17.30783"
"198.30000","9.91507","27849.79102","17.33404"
"198.60000","9.93006","27828.76758","17.36025"
"198.90000","9.94511","27808.15625","17.38655"
"199.20000","9.96012","27783.71289","17.41280"
"199.50000","9.97512","27761.50195","17.43902"
"199.80000","9.99011","27738.91406","17.46523"
"200.10000","10.00510","27716.95312","17.49144"
"200.40000","10.02010","27694.09766","17.51765"
"200.70000","10.03512","27671.20312","17.54391"
"201.00000","10.05008","27647.78125","17.57007"
"201.30000","10.06513","27622.56836","17.59637"
"201.60000","10.08014","27596.65234","17.62263"
"201.90000","10.09509","27570.04883","17.64875"
"202.20000","10.11005","27545.69727","17.67492"
"202.50000","10.12507","27519.45898","17.70118"
"202.80000","10.14007","27491.12500","17.72739"
"203.10000","10.15503","27466.56250","17.75356"
"203.40000","10.17005","27440.52734","17.77981"
"203.70000","10.18507","27414.22266","17.80607"
"204.00000","10.20009","27388.41992","17.83232"
"204.30000","10.21506","27360.21289","17.85849"
"204.60000","10.23010","27334.86914","17.88479"
"204.90000","10.24514","27307.57031","17.91109"
"205.20000","10.26016","27277.67188","17.93735"
"205.50000","10.27508","27248.84375","17.96343"
"205.80000","10.29017","27222.44336","17.98981"
"206.10000","10.30519","27191.91016","18.01607"
"206.40000","10.32008","27162.72266","18.04211"
"206.70000","10.33505","27134.83203","18.06827"
"207.00000","10.35009","27103.31641","18.09457"
"207.30000","10.36511","27071.60156","18.12083"
"207.60000","10.38003","27041.21680","18.14691"
"207.90000","10.39505","27010.00781","18.17316"
"208.20000","10.41007","26979.44336","18.19942"
"208.50000","10.42503","26944.74219","18.22558"
"208.80000","10.43995","26913.10938","18.25166"
"209.10000","10.45505","26884.69336","18.27805"
"209.40000","10.47014","26849.68750","18.30444"
"209.70000","10.48516","26814.89258","18.33070"
"210.00000","10.50013","26783.98828","18.35686"
"210.30000","10.51512","26751.22266","18.38308"
"210.60000","10.53016","26716.27734","18.40938"
"210.90000","10.54508","26681.98633","18.43545"
"211.20000","10.56010","26646.92383","18.46171"
"211.50000","10.57517","26612.15039","18.48806"
"211.80000","10.59011","26575.41406","18.51418"
"212.10000","10.60508","26538.55469","18.54035"
"212.40000","10.62007","26501.38477","18.56656"
"212.70000","10.63506","26465.29297","18.59277"
"213.00000","10.64998","26426.64648","18.61885"
"213.30000","10.66502","26389.53320","18.64515"
"213.60000","10.68009","26350.92383","18.67149"
"213.90000","10.69511","26309.50000","18.69775"
"214.20000","10.71008","26269.33203","18.72392"
"214.50000","10.72507","26233.32422","18.75013"
"214.80000","10.74014","26193.29297","18.77647"
"215.10000","10.75516","26154.43164","18.80273"
"215.40000","10.77010","26114.36523","18.82885"
"215.70000","10.78512","26074.02539","18.85511"
"216.00000","10.80014","26031.64844","18.88136"
"216.30000","10.81511","25990.10742","18.90753"
"216.60000","10.83010","25942.92773","18.93374"
"216.90000","10.84509","25900.96094","18.95995"
"217.20000","10.86011","25857.04297","18.98621"
"217.50000","10.87513","25809.62500","19.01246"
"217.80000","10.89007","25764.41992","19.03859"
"218.10000","10.90501","25717.83008","19.06471"
"218.40000","10.92006","25671.18359","19.09101"
"218.70000","10.93505","25623.35742","19.11722"
"219.00000","10.95004","25576.74023","19.14343"
"219.30000","10.96504","25528.04688","19.16965"
"219.60000","10.98011","25479.92969","19.19599"
"219.90000","10.99512","25428.56250","19.22225"
"220.20000","11.01009","25377.30859","19.24841"
"220.50000","11.02511","25329.05664","19.27467"
"220.80000","11.04018","25276.18945","19.30101"
"221.10000","11.05515","25221.84180","19.32718"
"221.40000","11.07006","25171.34180","19.35326"
"221.70000","11.08516","25118.10352","19.37965"
"222.00000","11.10015","25057.39258","19.40586"
"222.30000","11.11507","25001.33008","19.43194"
"222.60000","11.13004","24944.40039","19.45810"
"222.90000","11.14508","24884.37109","19.48441"
"223.20000","11.16012","24823.05078","19.51070"
"223.50000","11.17504","24761.24414","19.53679"
"223.80000","11.19006","24701.39648","19.56304"
"224.10000","11.20508","24637.57812","19.58930"
"224.40000","11.22007","24569.10547","19.61551"
"224.70000","11.23499","24502.20898","19.64159"
"224.80000","11.24005","24480.32422","19.65044"