File: Lab 2 - Monotonic Tensile and Fracture Toughness/test4.csv
Time,Extension,Load,Tensile strain (Extension),Strain 1
(s),(mm),(N),(%),(%)
"0.00000","0.00000","1.79788","0.00000","0.00029"
"0.10000","0.00544","2.07437","0.00952","0.00022"
"0.20000","0.01663","68.16452","0.02908","0.00121"
"0.30000","0.02802","129.28801","0.04899","0.00210"
"0.40000","0.03898","218.30113","0.06815","0.00352"
"0.50000","0.04946","330.68289","0.08648","0.00530"
"0.60000","0.05967","459.69180","0.10432","0.00746"
"0.70000","0.06990","610.97589","0.12220","0.00999"
"0.80000","0.08008","760.75763","0.14000","0.01259"
"0.90000","0.09008","907.37268","0.15749","0.01543"
"1.00000","0.10011","1052.56384","0.17502","0.01728"
"1.10000","0.11017","1194.04297","0.19260","0.02005"
"1.20000","0.12012","1330.83044","0.21000","0.02231"
"1.30000","0.13012","1460.87561","0.22749","0.02443"
"1.40000","0.14020","1591.63269","0.24511","0.02681"
"1.50000","0.15023","1713.86157","0.26264","0.02872"
"1.60000","0.16021","1836.03503","0.28009","0.03114"
"1.70000","0.17019","1956.55322","0.29754","0.03273"
"1.80000","0.18024","2069.90942","0.31511","0.03449"
"1.90000","0.19020","2178.64893","0.33251","0.03642"
"2.00000","0.20015","2282.70776","0.34991","0.03837"
"2.10000","0.21023","2385.06470","0.36754","0.03950"
"2.20000","0.22018","2479.70239","0.38494","0.04107"
"2.30000","0.23014","2571.36133","0.40234","0.04256"
"2.40000","0.24014","2660.22021","0.41983","0.04397"
"2.50000","0.25025","2747.40991","0.43749","0.04535"
"2.60000","0.26022","2830.57422","0.45494","0.04654"
"2.70000","0.27020","2909.55542","0.47238","0.04775"
"2.80000","0.28021","2985.37231","0.48987","0.04905"
"2.90000","0.29013","3056.62793","0.50723","0.04997"
"3.00000","0.30011","3126.73071","0.52467","0.05046"
"3.10000","0.31019","3197.69116","0.54229","0.05167"
"3.20000","0.32025","3263.47119","0.55987","0.05273"
"3.30000","0.33017","3325.49487","0.57723","0.05365"
"3.40000","0.34018","3388.04126","0.59472","0.05466"
"3.50000","0.35021","3448.36743","0.61225","0.05583"
"3.60000","0.36019","3504.14819","0.62970","0.05595"
"3.70000","0.37019","3562.55762","0.64718","0.05730"
"3.80000","0.38027","3619.15942","0.66481","0.05759"
"3.90000","0.39022","3673.06592","0.68221","0.05877"
"4.00000","0.40018","3722.96973","0.69961","0.05915"
"4.10000","0.41020","3776.23022","0.71714","0.06037"
"4.20000","0.42023","3826.79297","0.73467","0.06115"
"4.30000","0.43021","3874.86255","0.75212","0.06200"
"4.40000","0.44019","3924.83740","0.76956","0.06304"
"4.50000","0.45019","3975.48828","0.78705","0.06344"
"4.60000","0.46012","4023.15210","0.80441","0.06415"
"4.70000","0.47010","4074.32690","0.82186","0.06534"
"4.80000","0.48018","4126.71924","0.83948","0.06600"
"4.90000","0.49024","4178.40918","0.85705","0.06620"
"5.00000","0.50019","4228.32764","0.87446","0.06749"
"5.10000","0.51022","4281.61084","0.89199","0.06855"
"5.20000","0.52022","4334.39209","0.90948","0.06964"
"5.30000","0.53022","4386.35596","0.92697","0.07007"
"5.40000","0.54018","4439.82617","0.94437","0.07151"
"5.50000","0.55023","4494.54834","0.96194","0.07219"
"5.60000","0.56019","4549.60840","0.97935","0.07324"
"5.70000","0.57009","4603.91113","0.99666","0.07407"
"5.80000","0.58014","4660.02051","1.01424","0.07467"
"5.90000","0.59020","4715.39746","1.03181","0.07627"
"6.00000","0.60018","4771.04297","1.04926","0.07712"
"6.10000","0.61018","4828.52295","1.06675","0.07844"
"6.20000","0.62021","4886.44629","1.08428","0.07881"
"6.30000","0.63016","4941.22314","1.10168","0.08002"
"6.40000","0.64014","4998.67969","1.11913","0.08097"
"6.50000","0.65019","5057.94922","1.13670","0.08175"
"6.60000","0.66020","5116.38037","1.15419","0.08332"
"6.70000","0.67015","5173.41162","1.17159","0.08419"
"6.80000","0.68016","5232.95361","1.18908","0.08559"
"6.90000","0.69021","5293.53271","1.20666","0.08605"
"7.00000","0.70019","5351.89502","1.22411","0.08741"
"7.10000","0.71017","5412.88281","1.24155","0.08865"
"7.20000","0.72025","5473.35889","1.25917","0.08931"
"7.30000","0.73020","5534.26709","1.27657","0.09071"
"7.40000","0.74015","5597.16309","1.29397","0.09137"
"7.50000","0.75018","5659.93213","1.31151","0.09274"
"7.60000","0.76024","5723.75684","1.32908","0.09390"
"7.70000","0.77021","5785.14941","1.34653","0.09496"
"7.80000","0.78019","5850.76465","1.36397","0.09578"
"7.90000","0.79022","5914.39990","1.38151","0.09682"
"8.00000","0.80015","5976.75879","1.39886","0.09780"
"8.10000","0.81013","6040.68066","1.41631","0.09867"
"8.20000","0.82018","6107.33008","1.43389","0.09987"
"8.30000","0.83019","6171.34180","1.45138","0.10103"
"8.40000","0.84014","6236.34814","1.46878","0.10222"
"8.50000","0.85017","6302.51318","1.48631","0.10334"
"8.60000","0.86017","6367.81982","1.50380","0.10433"
"8.70000","0.87015","6434.94727","1.52124","0.10522"
"8.80000","0.88016","6502.62402","1.53873","0.10665"
"8.90000","0.89023","6570.15234","1.55635","0.10745"
"9.00000","0.90021","6635.84912","1.57380","0.10862"
"9.10000","0.91014","6703.02344","1.59116","0.10967"
"9.20000","0.92017","6772.71338","1.60869","0.11077"
"9.30000","0.93020","6839.57275","1.62622","0.11174"
"9.40000","0.94020","6907.47363","1.64371","0.11256"
"9.50000","0.95023","6975.81982","1.66124","0.11375"
"9.60000","0.96026","7045.12744","1.67878","0.11505"
"9.70000","0.97019","7112.59619","1.69613","0.11563"
"9.80000","0.98014","7181.86963","1.71354","0.11737"
"9.90000","0.99020","7252.24414","1.73111","0.11824"
"10.00000","1.00020","7320.38623","1.74860","0.11969"
"10.10000","1.01015","7390.77344","1.76600","0.12046"
"10.20000","1.02018","7461.90186","1.78354","0.12138"
"10.30000","1.03019","7532.27002","1.80103","0.12324"
"10.40000","1.04017","7603.03662","1.81847","0.12377"
"10.50000","1.05017","7676.28857","1.83596","0.12514"
"10.60000","1.06027","7750.43652","1.85362","0.12648"
"10.70000","1.07023","7820.20703","1.87103","0.12780"
"10.80000","1.08013","7891.99609","1.88834","0.12857"
"10.90000","1.09016","7965.89844","1.90587","0.12951"
"11.00000","1.10016","8038.90430","1.92336","0.13061"
"11.10000","1.11017","8111.07031","1.94085","0.13222"
"11.20000","1.12020","8184.65137","1.95838","0.13330"
"11.30000","1.13020","8257.97656","1.97587","0.13438"
"11.40000","1.14015","8331.08398","1.99327","0.13565"
"11.50000","1.15013","8408.01758","2.01072","0.13722"
"11.60000","1.16021","8482.85449","2.02834","0.13825"
"11.70000","1.17024","8556.95508","2.04587","0.13948"
"11.80000","1.18017","8634.12695","2.06323","0.14081"
"11.90000","1.19017","8712.47168","2.08072","0.14167"
"12.00000","1.20023","8789.18066","2.09830","0.14321"
"12.10000","1.21020","8864.72656","2.11574","0.14446"
"12.20000","1.22018","8943.36816","2.13319","0.14564"
"12.30000","1.23024","9022.92285","2.15076","0.14699"
"12.40000","1.24019","9099.07422","2.16816","0.14830"
"12.50000","1.25009","9176.67773","2.18548","0.14953"
"12.60000","1.26012","9256.97949","2.20301","0.15055"
"12.70000","1.27020","9337.81055","2.22063","0.15174"
"12.80000","1.28018","9417.71875","2.23808","0.15269"
"12.90000","1.29018","9497.34180","2.25557","0.15468"
"13.00000","1.30024","9577.15820","2.27314","0.15573"
"13.10000","1.31022","9658.80371","2.29059","0.15738"
"13.20000","1.32017","9741.40039","2.30799","0.15854"
"13.30000","1.33022","9824.27734","2.32557","0.16005"
"13.40000","1.34025","9904.82910","2.34310","0.16117"
"13.50000","1.35013","9987.07031","2.36037","0.16233"
"13.60000","1.36011","10072.89844","2.37781","0.16416"
"13.70000","1.37014","10156.29492","2.39535","0.16524"
"13.80000","1.38017","10240.76758","2.41288","0.16639"
"13.90000","1.39017","10325.62695","2.43037","0.16795"
"14.00000","1.40023","10411.76367","2.44795","0.16929"
"14.10000","1.41018","10495.52148","2.46535","0.17092"
"14.20000","1.42011","10579.92383","2.48270","0.17236"
"14.30000","1.43016","10665.80566","2.50028","0.17379"
"14.40000","1.44019","10751.16797","2.51781","0.17484"
"14.50000","1.45014","10837.95996","2.53522","0.17704"
"14.60000","1.46015","10927.19238","2.55270","0.17793"
"14.70000","1.47018","11014.38086","2.57024","0.17952"
"14.80000","1.48018","11102.26855","2.58773","0.18089"
"14.90000","1.49016","11191.61328","2.60517","0.18234"
"15.00000","1.50024","11281.58789","2.62279","0.18369"
"15.10000","1.51027","11368.95898","2.64033","0.18529"
"15.20000","1.52017","11457.06543","2.65764","0.18702"
"15.30000","1.53017","11548.43457","2.67513","0.18807"
"15.40000","1.54023","11637.76270","2.69271","0.18985"
"15.50000","1.55021","11727.27148","2.71015","0.19148"
"15.60000","1.56018","11816.81543","2.72760","0.19274"
"15.70000","1.57026","11906.92480","2.74522","0.19459"
"15.80000","1.58019","11997.60254","2.76257","0.19520"
"15.90000","1.59012","12086.17773","2.77993","0.19738"
"16.00000","1.60017","12178.90820","2.79751","0.19860"
"16.10000","1.61020","12270.20996","2.81504","0.20058"
"16.20000","1.62016","12362.37109","2.83244","0.20165"
"16.30000","1.63014","12455.43164","2.84989","0.20338"
"16.40000","1.64019","12547.68262","2.86746","0.20485"
"16.50000","1.65012","12638.47363","2.88482","0.20642"
"16.60000","1.66007","12732.83105","2.90222","0.20782"
"16.70000","1.67018","12827.94922","2.91989","0.20944"
"16.80000","1.68023","12921.60254","2.93746","0.21118"
"16.90000","1.69018","13014.18652","2.95487","0.21270"
"17.00000","1.70019","13107.55566","2.97235","0.21436"
"17.10000","1.71019","13201.91504","2.98984","0.21599"
"17.20000","1.72014","13295.99902","3.00725","0.21748"
"17.30000","1.73017","13391.94922","3.02478","0.21915"
"17.40000","1.74025","13486.19629","3.04240","0.22054"
"17.50000","1.75023","13581.40234","3.05984","0.22225"
"17.60000","1.76016","13678.89062","3.07720","0.22391"
"17.70000","1.77016","13775.21289","3.09469","0.22572"
"17.80000","1.78019","13870.11230","3.11222","0.22690"
"17.90000","1.79015","13966.94824","3.12962","0.22864"
"18.00000","1.80017","14066.24023","3.14716","0.23035"
"18.10000","1.81020","14162.45410","3.16469","0.23194"
"18.20000","1.82016","14256.89453","3.18209","0.23316"
"18.30000","1.83014","14355.52344","3.19954","0.23534"
"18.40000","1.84019","14455.26172","3.21711","0.23655"
"18.50000","1.85022","14553.22656","3.23465","0.23878"
"18.60000","1.86020","14650.84082","3.25209","0.24004"
"18.70000","1.87020","14748.59375","3.26958","0.24162"
"18.80000","1.88015","14846.22852","3.28698","0.24339"
"18.90000","1.89011","14945.82910","3.30438","0.24500"
"19.00000","1.90016","15047.58594","3.32196","0.24704"
"19.10000","1.91024","15146.34082","3.33958","0.24829"
"19.20000","1.92022","15245.60645","3.35703","0.24990"
"19.30000","1.93015","15345.68945","3.37438","0.25173"
"19.40000","1.94018","15446.38281","3.39192","0.25361"
"19.50000","1.95021","15547.85547","3.40945","0.25500"
"19.60000","1.96021","15647.41113","3.42694","0.25681"
"19.70000","1.97021","15748.98047","3.44443","0.25877"
"19.80000","1.98024","15851.76465","3.46196","0.25987"
"19.90000","1.99017","15951.61719","3.47932","0.26163"
"20.00000","2.00017","16052.82324","3.49681","0.26351"
"20.10000","2.01025","16155.15918","3.51443","0.26541"
"20.20000","2.02023","16258.34375","3.53187","0.26694"
"20.30000","2.03019","16359.60938","3.54928","0.26935"
"20.40000","2.04016","16463.00586","3.56672","0.27079"
"20.50000","2.05012","16562.94531","3.58412","0.27257"
"20.60000","2.06012","16668.52344","3.60161","0.27403"
"20.70000","2.07015","16773.42578","3.61914","0.27603"
"20.80000","2.08025","16876.75000","3.63681","0.27796"
"20.90000","2.09023","16978.36133","3.65425","0.27953"
"21.00000","2.10016","17083.04492","3.67161","0.28100"
"21.10000","2.11019","17189.14453","3.68914","0.28291"
"21.20000","2.12022","17292.05078","3.70668","0.28486"
"21.30000","2.13020","17394.25195","3.72412","0.28650"
"21.40000","2.14020","17500.10352","3.74161","0.28823"
"21.50000","2.15018","17604.58203","3.75906","0.29017"
"21.60000","2.16013","17709.20703","3.77646","0.29175"
"21.70000","2.17011","17815.65625","3.79390","0.29369"
"21.80000","2.18024","17922.73438","3.81161","0.29551"
"21.90000","2.19025","18027.16797","3.82910","0.29713"
"22.00000","2.20017","18132.66797","3.84646","0.29930"
"22.10000","2.21015","18240.23242","3.86390","0.30134"
"22.20000","2.22016","18346.17773","3.88139","0.30286"
"22.30000","2.23013","18453.19922","3.89884","0.30456"
"22.40000","2.24014","18563.72070","3.91633","0.30627"
"22.50000","2.25017","18669.29492","3.93386","0.30804"
"22.60000","2.26017","18775.64648","3.95135","0.30957"
"22.70000","2.27012","18882.83203","3.96875","0.31168"
"22.80000","2.28018","18991.87109","3.98633","0.31370"
"22.90000","2.29023","19100.56055","4.00390","0.31572"
"23.00000","2.30021","19207.98242","4.02135","0.31733"
"23.10000","2.31019","19314.90430","4.03879","0.31919"
"23.20000","2.32019","19421.86914","4.05628","0.32143"
"23.30000","2.33012","19528.73828","4.07364","0.32269"
"23.40000","2.34013","19638.24805","4.09113","0.32446"
"23.50000","2.35023","19746.47656","4.10879","0.32695"
"23.60000","2.36023","19853.82227","4.12628","0.32876"
"23.70000","2.37019","19964.29492","4.14368","0.33045"
"23.80000","2.38019","20074.78125","4.16117","0.33278"
"23.90000","2.39017","20183.59375","4.17862","0.33439"
"24.00000","2.40015","20291.24414","4.19606","0.33606"
"24.10000","2.41013","20405.02930","4.21351","0.33812"
"24.20000","2.42018","20514.64258","4.23109","0.34018"
"24.30000","2.43016","20623.33789","4.24853","0.34243"
"24.40000","2.44011","20733.58203","4.26593","0.34411"
"24.50000","2.45017","20845.10156","4.28351","0.34638"
"24.60000","2.46017","20954.43555","4.30100","0.34841"
"24.70000","2.47015","21064.69141","4.31844","0.35028"
"24.80000","2.48020","21175.15625","4.33602","0.35245"
"24.90000","2.49023","21283.36523","4.35355","0.35409"
"25.00000","2.50019","21393.04102","4.37096","0.35627"
"25.10000","2.51011","21504.91406","4.38831","0.35793"
"25.20000","2.52019","21617.86914","4.40593","0.36041"
"25.30000","2.53025","21726.79883","4.42351","0.36224"
"25.40000","2.54018","21837.95703","4.44087","0.36411"
"25.50000","2.55020","21947.85547","4.45840","0.36675"
"25.60000","2.56018","22057.32617","4.47585","0.36866"
"25.70000","2.57019","22166.58008","4.49333","0.37054"
"25.80000","2.58017","22276.12500","4.51078","0.37276"
"25.90000","2.59022","22385.08984","4.52836","0.37483"
"26.00000","2.60017","22495.08594","4.54576","0.37685"
"26.10000","2.61013","22603.68555","4.56316","0.37893"
"26.20000","2.62018","22713.68750","4.58074","0.38107"
"26.30000","2.63018","22823.57422","4.59822","0.38327"
"26.40000","2.64016","22933.38086","4.61567","0.38579"
"26.50000","2.65022","23042.79688","4.63325","0.38798"
"26.60000","2.66025","23149.60547","4.65078","0.39016"
"26.70000","2.67015","23256.07617","4.66809","0.39232"
"26.80000","2.68008","23364.97656","4.68545","0.39445"
"26.90000","2.69021","23473.33789","4.70316","0.39655"
"27.00000","2.70024","23575.60352","4.72069","0.39883"
"27.10000","2.71019","23677.88281","4.73809","0.40171"
"27.20000","2.72017","23781.98047","4.75554","0.40415"
"27.30000","2.73017","23883.25586","4.77303","0.40658"
"27.40000","2.74013","23983.16406","4.79043","0.40921"
"27.50000","2.75018","24084.25000","4.80801","0.41187"
"27.60000","2.76026","24180.26953","4.82563","0.41483"
"27.70000","2.77019","24274.38867","4.84298","0.41761"
"27.80000","2.78012","24369.16602","4.86034","0.42022"
"27.90000","2.79019","24462.75000","4.87796","0.42399"
"28.00000","2.80022","24553.25781","4.89550","0.42716"
"28.10000","2.81018","24642.23242","4.91290","0.43035"
"28.20000","2.82023","24730.82617","4.93047","0.43418"
"28.30000","2.83023","24813.05273","4.94796","0.43787"
"28.40000","2.84011","24894.21289","4.96523","0.44232"
"28.50000","2.85009","24978.04492","4.98268","0.44706"
"28.60000","2.86020","25057.92773","5.00034","0.45136"
"28.70000","2.87020","25131.71484","5.01783","0.45641"
"28.80000","2.88018","25203.61523","5.03528","0.46172"
"28.90000","2.89021","25276.25000","5.05281","0.46709"
"29.00000","2.90021","25345.68555","5.07030","0.47292"
"29.10000","2.91019","25413.50781","5.08774","0.47900"
"29.20000","2.92022","25478.40234","5.10528","0.48555"
"29.30000","2.93025","25541.51758","5.12281","0.49174"
"29.40000","2.94015","25600.34766","5.14012","0.49929"
"29.50000","2.95008","25658.78711","5.15748","0.50666"
"29.60000","2.96016","25715.98633","5.17510","0.51402"
"29.70000","2.97021","25770.55664","5.19268","0.52214"
"29.80000","2.98022","25821.42383","5.21017","0.53065"
"29.90000","2.99022","25872.20312","5.22766","0.53864"
"30.00000","3.00022","25920.17383","5.24515","0.54773"
"30.10000","3.01013","25965.23828","5.26246","0.55692"
"30.20000","3.02013","26010.57031","5.27995","0.56612"
"30.30000","3.03021","26053.89453","5.29757","0.57580"
"30.40000","3.04019","26092.34766","5.31501","0.58534"
"30.50000","3.05014","26129.67188","5.33242","0.59565"
"30.60000","3.06020","26166.58789","5.34999","0.60605"
"30.70000","3.07020","26202.87305","5.36748","0.61635"
"30.80000","3.08018","26237.74023","5.38493","0.62739"
"30.90000","3.09023","26270.20117","5.40250","0.63819"
"31.00000","3.10029","26300.30273","5.42008","0.64972"
"31.10000","3.11024","26328.96680","5.43748","0.66142"
"31.20000","3.12019","26357.67188","5.45488","0.67266"
"31.30000","3.13022","26385.08398","5.47242","0.68436"
"31.40000","3.14023","26409.06836","5.48990","0.69671"
"31.50000","3.15018","26432.29688","5.50731","0.70845"
"31.60000","3.16021","26457.52734","5.52484","0.72070"
"31.70000","3.17021","26479.91992","5.54233","0.73337"
"31.80000","3.18014","26499.82227","5.55969","0.74604"
"31.90000","3.19014","26520.40430","5.57717","0.75866"
"32.00000","3.20020","26541.50391","5.59475","0.77125"
"32.10000","3.21018","26559.04688","5.61220","0.78445"
"32.20000","3.22013","26575.50000","5.62960","0.79737"
"32.30000","3.23016","26593.35742","5.64713","0.80997"
"32.40000","3.24011","26609.27148","5.66453","0.82352"
"32.50000","3.25012","26626.76953","5.68202","0.83664"
"32.60000","3.26020","26643.00195","5.69964","0.85026"
"32.70000","3.27027","26656.89258","5.71726","0.86385"
"32.80000","3.28020","26667.08594","5.73462","0.87674"
"32.90000","3.29016","26682.00781","5.75202","0.89068"
"33.00000","3.30018","26697.22656","5.76955","0.90442"
"33.10000","3.31019","26708.57227","5.78704","0.91829"
"33.20000","3.32019","26720.87891","5.80453","0.93198"
"33.30000","3.33025","26733.89062","5.82211","0.94540"
"33.40000","3.34025","26744.55273","5.83960","0.95914"
"33.50000","3.35018","26753.70508","5.85696","0.97280"
"33.60000","3.36016","26764.78320","5.87440","0.98722"
"33.70000","3.37021","26775.56250","5.89198","1.00062"
"33.80000","3.38019","26786.22070","5.90942","1.01453"
"33.90000","3.39017","26797.00195","5.92687","1.02853"
"34.00000","3.40017","26806.72070","5.94436","1.04280"
"34.10000","3.41018","26815.97461","5.96185","1.05682"
"34.20000","3.42013","26824.58984","5.97925","1.07090"
"34.30000","3.43016","26836.55859","5.99678","1.08559"
"34.40000","3.44024","26844.92773","6.01440","1.09983"
"34.50000","3.45024","26849.57031","6.03189","1.11403"
"34.60000","3.46017","26857.19727","6.04925","1.12841"
"34.70000","3.47012","26866.62891","6.06665","1.14259"
"34.80000","3.48018","26876.67383","6.08423","1.15732"
"34.90000","3.49021","26883.93555","6.10176","1.17207"
"35.00000","3.50024","26890.69727","6.11929","1.18643"
"35.10000","3.51021","26898.76758","6.13674","1.20150"
"35.20000","3.52014","26904.43164","6.15410","1.21581"
"35.30000","3.53015","26914.15234","6.17158","1.23063"
"35.40000","3.54023","26921.80859","6.18920","1.24504"
"35.50000","3.55023","26927.87695","6.20669","1.26022"
"35.60000","3.56018","26937.37500","6.22410","1.27506"
"35.70000","3.57021","26946.60352","6.24163","1.29050"
"35.80000","3.58021","26952.57422","6.25912","1.30535"
"35.90000","3.59022","26959.05859","6.27661","1.32127"
"36.00000","3.60022","26967.35352","6.29410","1.33656"
"36.10000","3.61025","26973.90625","6.31163","1.35247"
"36.20000","3.62020","26978.19727","6.32903","1.36762"
"36.30000","3.63011","26983.77734","6.34634","1.38379"
"36.40000","3.64014","26992.86719","6.36388","1.39929"
"36.50000","3.65017","27001.91797","6.38141","1.41532"
"36.60000","3.66017","27008.00000","6.39890","1.43132"
"36.70000","3.67022","27013.17383","6.41648","1.44764"
"36.80000","3.68028","27018.27539","6.43405","1.46333"
"36.90000","3.69021","27023.47656","6.45141","1.47964"
"37.00000","3.70018","27031.25781","6.46885","1.49513"
"37.10000","3.71024","27039.54297","6.48643","1.51141"
"37.20000","3.72024","27044.29297","6.50392","1.52798"
"37.30000","3.73015","27051.24414","6.52123","1.54436"
"37.40000","3.74015","27058.35742","6.53872","1.56045"
"37.50000","3.75013","27063.60156","6.55617","1.57736"
"37.60000","3.76013","27068.62305","6.57366","1.59389"
"37.70000","3.77021","27076.97461","6.59128","1.61098"
"37.80000","3.78024","27083.90430","6.60881","1.62766"
"37.90000","3.79019","27087.41211","6.62621","1.64474"
"38.00000","3.80012","27092.30469","6.64357","1.66149"
"38.10000","3.81020","27098.88867","6.66119","1.67817"
"38.20000","3.82018","27104.81250","6.67864","1.69509"
"38.30000","3.83016","27110.68945","6.69608","1.71197"
"38.40000","3.84019","27117.61523","6.71361","1.72938"
"38.50000","3.85022","27120.30078","6.73115","1.74641"
"38.60000","3.86014","27125.42383","6.74850","1.76314"
"38.70000","3.87015","27133.62500","6.76599","1.78078"
"38.80000","3.88023","27140.31055","6.78361","1.79854"
"38.90000","3.89023","27143.90234","6.80110","1.81561"
"39.00000","3.90018","27148.73242","6.81850","1.83306"
"39.10000","3.91021","27155.88281","6.83604","1.85029"
"39.20000","3.92022","27160.81055","6.85353","1.86787"
"39.30000","3.93017","27165.54492","6.87093","1.88558"
"39.40000","3.94020","27172.77344","6.88846","1.90299"
"39.50000","3.95028","27178.27930","6.90608","1.92064"
"39.60000","3.96021","27182.72852","6.92344","1.93818"
"39.70000","3.97016","27187.83984","6.94084","1.95522"
"39.80000","3.98021","27193.39453","6.95842","1.97295"
"39.90000","3.99019","27199.46484","6.97586","1.99015"
"40.00000","4.00015","27206.96094","6.99326","2.00767"
"40.10000","4.01015","27214.84375","7.01075","2.02548"
"40.20000","4.02018","27220.75000","7.02829","2.04327"
"40.30000","4.03011","27224.32617","7.04564","2.06116"
"40.40000","4.04011","27232.65625","7.06313","2.07848"
"40.50000","4.05019","27238.13281","7.08075","2.09681"
"40.60000","4.06022","27243.20312","7.09829","2.11461"
"40.70000","4.07022","27246.47852","7.11577","2.13244"
"40.80000","4.08023","27252.07812","7.13326","2.15007"
"40.90000","4.09021","27256.64648","7.15071","2.16784"
"41.00000","4.10013","27261.81836","7.16807","2.18518"
"41.10000","4.11021","27269.51172","7.18569","2.20362"
"41.20000","4.12032","27274.54688","7.20335","2.22115"
"41.30000","4.13022","27276.97266","7.22066","2.23888"
"41.40000","4.14017","27283.31055","7.23807","2.25662"
"41.50000","4.15020","27289.02930","7.25560","2.27407"
"41.60000","4.16018","27293.74219","7.27304","2.29143"
"41.70000","4.17016","27300.19141","7.29049","2.30910"
"41.80000","4.18019","27308.81836","7.30802","2.32670"
"41.90000","4.19019","27313.70117","7.32551","2.34472"
"42.00000","4.20015","27316.89258","7.34291","2.36221"
"42.10000","4.21015","27323.19141","7.36040","2.37951"
"42.20000","4.22020","27330.32422","7.37798","2.39708"
"42.30000","4.23021","27334.76367","7.39547","2.41498"
"42.40000","4.24021","27339.98633","7.41296","2.43248"
"42.50000","4.25024","27343.60938","7.43049","2.44965"
"42.60000","4.26019","27347.68750","7.44789","2.46711"
"42.70000","4.27010","27353.11328","7.46520","2.48416"
"42.80000","4.28018","27361.09570","7.48283","2.50194"
"42.90000","4.29026","27366.36719","7.50045","2.51929"
"43.00000","4.30018","27370.15234","7.51780","2.53621"
"43.10000","4.31014","27376.66992","7.53521","2.55375"
"43.20000","4.32019","27384.08398","7.55278","2.57108"
"43.30000","4.33020","27387.94727","7.57027","2.58771"
"43.40000","4.34020","27392.90234","7.58776","2.60535"
"43.50000","4.35023","27399.80273","7.60529","2.62301"
"43.60000","4.36021","27405.00000","7.62274","2.64013"
"43.70000","4.37016","27408.89844","7.64014","2.65691"
"43.80000","4.38019","27415.42383","7.65767","2.67438"
"43.90000","4.39024","27422.60156","7.67525","2.69134"
"44.00000","4.40025","27426.43945","7.69274","2.70838"
"44.10000","4.41020","27431.58398","7.71014","2.72551"
"44.20000","4.42020","27434.36133","7.72763","2.74265"
"44.30000","4.43016","27437.96094","7.74503","2.75900"
"44.40000","4.44011","27444.17578","7.76243","2.77582"
"44.50000","4.45019","27453.23828","7.78005","2.79276"
"44.60000","4.46024","27457.57617","7.79763","2.81007"
"44.70000","4.47020","27462.32422","7.81503","2.82699"
"44.80000","4.48018","27468.58594","7.83248","2.84367"
"44.90000","4.49023","27474.54297","7.85005","2.86079"
"45.00000","4.50021","27478.54688","7.86750","2.87706"
"45.10000","4.51019","27483.13281","7.88494","2.89424"
"45.20000","4.52022","27488.40430","7.90248","2.91120"
"45.30000","4.53017","27493.20508","7.91988","2.92756"
"45.40000","4.54012","27498.00000","7.93728","2.94381"
"45.50000","4.55015","27505.84570","7.95481","2.96073"
"45.60000","4.56023","27510.84180","7.97243","2.97710"
"45.70000","4.57021","27516.09375","7.98988","2.99379"
"45.80000","4.58019","27521.14453","8.00732","3.00991"
"45.90000","4.59019","27526.04102","8.02481","3.02690"
"46.00000","4.60015","27528.48047","8.04221","3.04283"
"46.10000","4.61012","27535.33984","8.05966","3.05972"
"46.20000","4.62018","27544.69141","8.07724","3.07633"
"46.30000","4.63018","27550.89062","8.09472","3.09306"
"46.40000","4.64016","27553.77344","8.11217","3.10926"
"46.50000","4.65017","27560.13477","8.12966","3.12611"
"46.60000","4.66019","27565.42188","8.14719","3.14293"
"46.70000","4.67022","27569.88672","8.16472","3.15935"
"46.80000","4.68020","27573.75195","8.18217","3.17573"
"46.90000","4.69023","27577.85938","8.19970","3.19227"
"47.00000","4.70021","27583.35156","8.21715","3.20849"
"47.10000","4.71019","27588.08789","8.23459","3.22474"
"47.20000","4.72017","27595.13477","8.25204","3.24127"
"47.30000","4.73025","27600.18359","8.26966","3.25794"
"47.40000","4.74025","27604.45117","8.28715","3.27361"
"47.50000","4.75020","27610.53711","8.30455","3.29038"
"47.60000","4.76023","27614.85938","8.32208","3.30631"
"47.70000","4.77018","27620.15234","8.33948","3.32259"
"47.80000","4.78014","27624.76562","8.35688","3.33885"
"47.90000","4.79014","27633.17188","8.37437","3.35514"
"48.00000","4.80017","27637.39453","8.39191","3.37166"
"48.10000","4.81012","27640.30664","8.40931","3.38787"
"48.20000","4.82010","27646.13867","8.42675","3.40391"
"48.30000","4.83018","27653.02148","8.44437","3.42064"
"48.40000","4.84016","27658.37891","8.46182","3.43718"
"48.50000","4.85016","27663.52539","8.47931","3.45336"
"48.60000","4.86027","27668.47266","8.49697","3.46984"
"48.70000","4.87027","27670.53906","8.51446","3.48624"
"48.80000","4.88020","27674.25977","8.53182","3.50248"
"48.90000","4.89018","27679.64844","8.54926","3.51851"
"49.00000","4.90021","27684.02344","8.56680","3.53487"
"49.10000","4.91024","27687.61523","8.58433","3.55054"
"49.20000","4.92019","27694.25781","8.60173","3.56676"
"49.30000","4.93022","27701.80664","8.61927","3.58265"
"49.40000","4.94017","27706.51562","8.63667","3.59901"
"49.50000","4.95015","27709.85742","8.65411","3.61511"
"49.60000","4.96018","27717.45703","8.67164","3.63138"
"49.70000","4.97021","27721.67969","8.68918","3.64746"
"49.80000","4.98021","27725.80664","8.70667","3.66413"
"49.90000","4.99019","27731.73438","8.72411","3.68028"
"50.00000","5.00022","27735.98047","8.74165","3.69624"
"50.10000","5.01017","27739.88867","8.75905","3.71222"
"50.20000","5.02015","27746.64258","8.77649","3.72873"
"50.30000","5.03023","27751.63867","8.79411","3.74478"
"50.40000","5.04026","27754.93359","8.81165","3.76055"
"50.50000","5.05016","27758.70312","8.82896","3.77695"
"50.60000","5.06012","27764.14844","8.84636","3.79238"
"50.70000","5.07022","27770.57812","8.86402","3.80883"
"50.80000","5.08025","27776.24805","8.88156","3.82467"
"50.90000","5.09020","27779.88867","8.89896","3.84061"
"51.00000","5.10018","27786.00977","8.91640","3.85714"
"51.10000","5.11016","27789.82812","8.93385","3.87283"
"51.20000","5.12009","27795.21289","8.95121","3.88905"
"51.30000","5.13019","27802.57422","8.96887","3.90533"
"51.40000","5.14027","27807.07227","8.98649","3.92132"
"51.50000","5.15025","27810.64258","9.00394","3.93756"
"51.60000","5.16018","27813.07422","9.02129","3.95385"
"51.70000","5.17024","27816.99219","9.03887","3.96976"
"51.80000","5.18021","27820.93945","9.05632","3.98524"
"51.90000","5.19017","27827.90625","9.07372","4.00122"
"52.00000","5.20022","27835.44727","9.09129","4.01765"
"52.10000","5.21020","27838.12305","9.10874","4.03323"
"52.20000","5.22010","27840.32617","9.12605","4.04928"
"52.30000","5.23008","27848.91992","9.14350","4.06544"
"52.40000","5.24021","27856.02734","9.16121","4.08193"
"52.50000","5.25021","27859.75391","9.17870","4.09771"
"52.60000","5.26019","27862.01758","9.19614","4.11381"
"52.70000","5.27025","27866.74805","9.21372","4.12967"
"52.80000","5.28020","27870.32422","9.23112","4.14557"
"52.90000","5.29018","27875.69727","9.24857","4.16150"
"53.00000","5.30021","27881.39062","9.26610","4.17745"
"53.10000","5.31026","27884.36914","9.28368","4.19364"
"53.20000","5.32017","27889.31445","9.30099","4.20905"
"53.30000","5.33009","27893.74219","9.31835","4.22572"
"53.40000","5.34017","27897.74609","9.33597","4.24168"
"53.50000","5.35020","27901.04492","9.35350","4.25755"
"53.60000","5.36021","27906.56055","9.37099","4.27318"
"53.70000","5.37023","27912.04688","9.38852","4.28928"
"53.80000","5.38021","27917.51562","9.40597","4.30513"
"53.90000","5.39012","27920.33008","9.42328","4.32120"
"54.00000","5.40015","27926.43359","9.44081","4.33726"
"54.10000","5.41020","27932.19727","9.45839","4.35336"
"54.20000","5.42013","27934.43555","9.47575","4.36903"
"54.30000","5.43011","27939.30859","9.49319","4.38479"
"54.40000","5.44019","27943.75195","9.51081","4.40082"
"54.50000","5.45016","27948.35547","9.52826","4.41670"
"54.60000","5.46014","27952.06250","9.54570","4.43244"
"54.70000","5.47025","27957.80078","9.56337","4.44811"
"54.80000","5.48030","27959.87695","9.58095","4.46419"
"54.90000","5.49023","27962.96094","9.59830","4.48017"
"55.00000","5.50018","27968.33008","9.61570","4.49590"
"55.10000","5.51021","27974.06836","9.63324","4.51176"
"55.20000","5.52022","27977.62500","9.65073","4.52730"
"55.30000","5.53017","27982.01758","9.66813","4.54283"
"55.40000","5.54022","27987.50977","9.68570","4.55892"
"55.50000","5.55023","27992.63086","9.70319","4.57429"
"55.60000","5.56013","27995.41602","9.72051","4.59027"
"55.70000","5.57018","28003.12695","9.73808","4.60681"
"55.80000","5.58021","28007.30469","9.75562","4.62213"
"55.90000","5.59017","28011.40039","9.77302","4.63809"
"56.00000","5.60012","28015.15820","9.79042","4.65411"
"56.10000","5.61020","28019.41992","9.80804","4.67019"
"56.20000","5.62015","28021.61328","9.82544","4.68566"
"56.30000","5.63008","28026.66211","9.84280","4.70159"
"56.40000","5.64021","28032.18359","9.86051","4.71756"
"56.50000","5.65024","28034.84180","9.87804","4.73330"
"56.60000","5.66022","28036.44531","9.89549","4.74921"
"56.70000","5.67017","28040.54297","9.91289","4.76479"
"56.80000","5.68020","28046.13086","9.93042","4.78026"
"56.90000","5.69015","28049.73438","9.94782","4.79615"
"57.00000","5.70018","28056.34375","9.96535","4.81193"
"57.10000","5.71026","28061.56836","9.98297","4.82747"
"57.20000","5.72024","28065.60742","10.00042","4.84337"
"57.30000","5.73017","28068.08594","10.01778","4.85926"
"57.40000","5.74017","28072.67969","10.03527","4.87484"
"57.50000","5.75023","28075.62695","10.05284","4.89046"
"57.60000","5.76020","28080.18359","10.07029","4.90647"
"57.70000","5.77021","28085.81250","10.08778","4.92291"
"57.80000","5.78026","28090.87695","10.10535","4.93837"
"57.90000","5.79022","28091.54688","10.12276","4.95432"
"58.00000","5.80014","28095.42773","10.14011","4.96959"
"58.10000","5.81017","28102.18359","10.15765","4.98514"
"58.20000","5.82025","28105.73047","10.17527","5.00080"
"58.30000","5.83021","28108.93750","10.19267","5.01688"
"58.40000","5.84019","28113.75586","10.21011","5.03234"
"58.50000","5.85016","28119.17578","10.22756","5.04829"
"58.60000","5.86014","28121.67383","10.24500","5.06376"
"58.70000","5.87017","28125.35156","10.26254","5.07990"
"58.80000","5.88025","28128.98438","10.28016","5.09539"
"58.90000","5.89020","28131.13086","10.29756","5.11132"
"59.00000","5.90011","28133.75586","10.31487","5.12647"
"59.10000","5.91011","28139.84375","10.33236","5.14238"
"59.20000","5.92022","28143.88281","10.35003","5.15766"
"59.30000","5.93022","28148.71094","10.36751","5.17366"
"59.40000","5.94025","28153.30078","10.38505","5.18932"
"59.50000","5.95025","28156.40625","10.40254","5.20497"
"59.60000","5.96021","28157.41992","10.41994","5.22026"
"59.70000","5.97018","28162.14062","10.43738","5.23606"
"59.80000","5.98021","28168.51758","10.45492","5.25135"
"59.90000","5.99024","28173.21484","10.47245","5.26679"
"60.00000","6.00014","28175.19531","10.48976","5.28271"
"60.10000","6.01012","28180.31055","10.50721","5.29842"
"60.20000","6.02010","28183.72461","10.52465","5.31415"
"60.30000","6.03013","28188.40234","10.54219","5.32968"
"60.40000","6.04018","28193.67383","10.55976","5.34575"
"60.50000","6.05029","28196.16406","10.57743","5.36216"
"60.60000","6.06027","28196.61133","10.59487","5.37681"
"60.70000","6.07017","28200.00391","10.61219","5.39245"
"60.80000","6.08017","28204.36328","10.62968","5.40801"
"60.90000","6.09023","28207.02734","10.64725","5.42363"
"61.00000","6.10023","28210.22656","10.66474","5.43861"
"61.10000","6.11019","28215.65820","10.68214","5.45451"
"61.20000","6.12016","28219.50391","10.69959","5.46998"
"61.30000","6.13014","28222.89844","10.71703","5.48526"
"61.40000","6.14015","28228.40234","10.73452","5.50147"
"61.50000","6.15025","28233.45312","10.75219","5.51701"
"61.60000","6.16025","28236.74414","10.76968","5.53257"
"61.70000","6.17021","28238.66016","10.78708","5.54857"
"61.80000","6.18014","28243.69336","10.80443","5.56359"
"61.90000","6.19017","28245.71484","10.82197","5.57922"
"62.00000","6.20017","28250.55664","10.83946","5.59517"
"62.10000","6.21012","28254.96484","10.85686","5.61051"
"62.20000","6.22013","28257.60547","10.87435","5.62650"
"62.30000","6.23016","28257.66797","10.89188","5.64157"
"62.40000","6.24013","28260.69336","10.90933","5.65734"
"62.50000","6.25019","28266.00977","10.92690","5.67254"
"62.60000","6.26027","28269.73828","10.94452","5.68808"
"62.70000","6.27027","28272.75000","10.96201","5.70425"
"62.80000","6.28022","28275.35547","10.97941","5.71927"
"62.90000","6.29023","28279.41211","10.99690","5.73482"
"63.00000","6.30021","28282.54492","11.01435","5.75016"
"63.10000","6.31016","28286.92773","11.03175","5.76546"
"63.20000","6.32021","28291.51758","11.04933","5.78070"
"63.30000","6.33024","28294.16602","11.06686","5.79642"
"63.40000","6.34017","28296.26758","11.08422","5.81220"
"63.50000","6.35015","28300.35352","11.10166","5.82774"
"63.60000","6.36020","28303.07227","11.11924","5.84303"
"63.70000","6.37021","28307.16602","11.13673","5.85853"
"63.80000","6.38019","28312.00586","11.15417","5.87397"
"63.90000","6.39019","28315.05859","11.17166","5.88945"
"64.00000","6.40017","28316.28711","11.18911","5.90498"
"64.10000","6.41012","28318.78320","11.20651","5.92064"
"64.20000","6.42013","28324.28906","11.22400","5.93645"
"64.30000","6.43018","28325.92188","11.24157","5.95179"
"64.40000","6.44018","28330.24219","11.25906","5.96747"
"64.50000","6.45019","28334.28125","11.27655","5.98300"
"64.60000","6.46022","28336.70703","11.29408","5.99855"
"64.70000","6.47017","28339.82617","11.31149","6.01318"
"64.80000","6.48012","28343.71875","11.32889","6.02896"
"64.90000","6.49020","28346.39844","11.34651","6.04438"
"65.00000","6.50028","28348.21094","11.36413","6.05999"
"65.10000","6.51021","28351.55664","11.38149","6.07519"
"65.20000","6.52019","28355.41016","11.39893","6.09053"
"65.30000","6.53019","28357.24414","11.41642","6.10673"
"65.40000","6.54017","28359.09180","11.43387","6.12156"
"65.50000","6.55015","28362.70898","11.45131","6.13686"
"65.60000","6.56025","28367.95508","11.46898","6.15270"
"65.70000","6.57028","28369.74219","11.48651","6.16798"
"65.80000","6.58019","28372.17773","11.50382","6.18339"
"65.90000","6.59019","28375.75000","11.52131","6.19858"
"66.00000","6.60019","28381.35352","11.53880","6.21404"
"66.10000","6.61017","28385.30273","11.55625","6.22914"
"66.20000","6.62018","28388.42773","11.57374","6.24491"
"66.30000","6.63023","28388.33594","11.59131","6.26006"
"66.40000","6.64013","28390.03125","11.60863","6.27583"
"66.50000","6.65009","28393.85938","11.62603","6.29043"
"66.60000","6.66022","28399.02930","11.64374","6.30607"
"66.70000","6.67027","28400.50781","11.66131","6.32144"
"66.80000","6.68017","28401.60742","11.67863","6.33638"
"66.90000","6.69015","28405.17969","11.69607","6.35237"
"67.00000","6.70016","28408.31055","11.71356","6.36716"
"67.10000","6.71013","28409.26953","11.73100","6.38240"
"67.20000","6.72016","28413.45117","11.74854","6.39743"
"67.30000","6.73027","28419.05078","11.76620","6.41305"
"67.40000","6.74027","28422.21875","11.78369","6.42830"
"67.50000","6.75017","28423.67383","11.80101","6.44365"
"67.60000","6.76020","28427.96680","11.81854","6.45917"
"67.70000","6.77023","28430.71289","11.83607","6.47428"
"67.80000","6.78019","28432.86133","11.85347","6.48986"
"67.90000","6.79019","28436.71094","11.87096","6.50514"
"68.00000","6.80022","28438.74414","11.88850","6.52051"
"68.10000","6.81005","28436.95508","11.90568","6.53591"
"68.20000","6.82008","28442.48438","11.92321","6.55139"
"68.30000","6.83023","28448.77930","11.94096","6.56659"
"68.40000","6.84028","28450.16797","11.95854","6.58206"
"68.50000","6.85024","28449.31250","11.97594","6.59714"
"68.60000","6.86022","28451.40039","11.99338","6.61255"
"68.70000","6.87022","28453.66992","12.01087","6.62772"
"68.80000","6.88022","28456.81641","12.02836","6.64239"
"68.90000","6.89018","28460.30664","12.04576","6.65816"
"69.00000","6.90023","28464.89453","12.06334","6.67305"
"69.10000","6.91018","28467.29688","12.08074","6.68823"
"69.20000","6.92009","28469.19531","12.09806","6.70355"
"69.30000","6.93017","28473.54102","12.11568","6.71890"
"69.40000","6.94025","28475.67188","12.13330","6.73430"
"69.50000","6.95020","28477.33789","12.15070","6.75013"
"69.60000","6.96018","28479.42969","12.16814","6.76523"
"69.70000","6.97021","28481.40039","12.18568","6.78037"
"69.80000","6.98016","28481.43945","12.20308","6.79520"
"69.90000","6.99014","28484.97070","12.22052","6.81019"
"70.00000","7.00019","28488.99609","12.23810","6.82521"
"70.10000","7.01017","28490.16211","12.25555","6.84049"
"70.20000","7.02007","28490.39648","12.27286","6.85570"
"70.30000","7.03013","28494.88867","12.29044","6.87060"
"70.40000","7.04021","28500.37500","12.30806","6.88594"
"70.50000","7.05021","28502.86914","12.32555","6.90093"
"70.60000","7.06022","28505.19141","12.34303","6.91634"
"70.70000","7.07030","28504.51758","12.36066","6.93135"
"70.80000","7.08022","28505.94141","12.37801","6.94614"
"70.90000","7.09018","28507.67383","12.39542","6.96125"
"71.00000","7.10021","28513.60156","12.41295","6.97634"
"71.10000","7.11026","28515.16992","12.43052","6.99156"
"71.20000","7.12024","28515.81641","12.44797","7.00611"
"71.30000","7.13022","28519.55078","12.46542","7.02157"
"71.40000","7.14022","28521.46680","12.48290","7.03656"
"71.50000","7.15017","28522.38086","12.50030","7.05133"
"71.60000","7.16015","28523.66211","12.51775","7.06686"
"71.70000","7.17021","28528.18359","12.53533","7.08143"
"71.80000","7.18019","28531.08008","12.55277","7.09591"
"71.90000","7.19011","28532.89258","12.57013","7.11084"
"72.00000","7.20014","28536.03320","12.58766","7.12588"
"72.10000","7.21015","28538.52734","12.60515","7.14114"
"72.20000","7.22013","28541.29297","12.62260","7.15620"
"72.30000","7.23015","28544.22656","12.64013","7.17138"
"72.40000","7.24023","28544.85547","12.65775","7.18613"
"72.50000","7.25024","28544.44336","12.67524","7.20114"
"72.60000","7.26014","28547.13281","12.69255","7.21565"
"72.70000","7.27014","28550.42188","12.71004","7.23075"
"72.80000","7.28022","28552.54102","12.72766","7.24538"
"72.90000","7.29023","28554.02148","12.74515","7.26038"
"73.00000","7.30023","28555.54297","12.76264","7.27493"
"73.10000","7.31026","28556.66016","12.78017","7.28996"
"73.20000","7.32019","28557.45312","12.79753","7.30484"
"73.30000","7.33014","28559.22070","12.81493","7.31930"
"73.40000","7.34020","28563.93750","12.83251","7.33487"
"73.50000","7.35022","28567.70117","12.85004","7.34966"
"73.60000","7.36020","28569.66016","12.86749","7.36474"
"73.70000","7.37021","28571.96094","12.88498","7.37924"
"73.80000","7.38021","28572.79688","12.90247","7.39404"
"73.90000","7.39016","28574.02539","12.91987","7.40850"
"74.00000","7.40017","28578.70117","12.93736","7.42360"
"74.10000","7.41027","28582.32812","12.95502","7.43818"
"74.20000","7.42025","28579.31055","12.97247","7.45277"
"74.30000","7.43018","28579.02344","12.98982","7.46738"
"74.40000","7.44013","28581.57812","13.00723","7.48229"
"74.50000","7.45019","28583.46680","13.02480","7.49681"
"74.60000","7.46022","28585.45703","13.04234","7.51129"
"74.70000","7.47019","28588.02930","13.05978","7.52559"
"74.80000","7.48020","28589.77930","13.07727","7.54052"
"74.90000","7.49013","28591.26367","13.09463","7.55454"
"75.00000","7.50008","28594.14258","13.11203","7.56885"
"75.10000","7.51018","28597.42969","13.12969","7.58377"
"75.20000","7.52024","28598.88672","13.14727","7.59801"
"75.30000","7.53019","28600.36719","13.16467","7.61268"
"75.40000","7.54022","28603.61328","13.18220","7.62761"
"75.50000","7.55025","28603.91406","13.19974","7.64185"
"75.60000","7.56023","28605.17773","13.21718","7.65619"
"75.70000","7.57018","28607.78516","13.23458","7.67073"
"75.80000","7.58024","28610.07227","13.25216","7.68528"
"75.90000","7.59021","28609.69531","13.26960","7.69949"
"76.00000","7.60004","28609.03516","13.28679","7.71351"
"76.10000","7.61007","28611.07812","13.30432","7.72758"
"76.20000","7.62023","28617.05664","13.32207","7.74212"
"76.30000","7.63023","28618.08203","13.33956","7.75676"
"76.40000","7.64026","28619.45703","13.35710","7.77101"
"76.50000","7.65026","28619.98047","13.37458","7.78523"
"76.60000","7.66022","28622.45117","13.39198","7.79976"
"76.70000","7.67017","28625.45312","13.40939","7.81352"
"76.80000","7.68025","28626.88672","13.42701","7.82830"
"76.90000","7.69025","28625.86719","13.44450","7.84173"
"77.00000","7.70016","28626.65039","13.46181","7.85620"
"77.10000","7.71011","28629.56250","13.47921","7.86998"
"77.20000","7.72019","28630.90039","13.49683","7.88429"
"77.30000","7.73019","28631.95508","13.51432","7.89857"
"77.40000","7.74022","28634.78125","13.53185","7.91247"
"77.50000","7.75028","28636.93555","13.54943","7.92640"
"77.60000","7.76023","28635.07031","13.56683","7.94050"
"77.70000","7.77011","28635.41602","13.58410","7.95451"
"77.80000","7.78016","28637.84961","13.60168","7.96883"
"77.90000","7.79019","28641.58203","13.61921","7.98240"
"78.00000","7.80012","28643.69531","13.63657","7.99661"
"78.10000","7.81007","28645.93945","13.65397","8.01060"
"78.20000","7.82015","28646.34766","13.67159","8.02405"
"78.30000","7.83015","28647.35938","13.68908","8.03801"
"78.40000","7.84018","28649.04688","13.70661","8.05227"
"78.50000","7.85029","28650.29492","13.72428","8.06591"
"78.60000","7.86029","28649.19336","13.74177","8.07910"
"78.70000","7.87022","28647.76172","13.75912","8.09304"
"78.80000","7.88020","28651.13281","13.77657","8.10664"
"78.90000","7.89023","28652.79102","13.79410","8.12045"
"79.00000","7.90020","28653.62500","13.81155","8.13404"
"79.10000","7.91018","28655.59375","13.82899","8.14743"
"79.20000","7.92026","28658.69336","13.84661","8.16090"
"79.30000","7.93022","28659.34375","13.86402","8.17455"
"79.40000","7.94014","28660.00586","13.88137","8.18793"
"79.50000","7.95020","28660.71094","13.89895","8.20166"
"79.60000","7.96020","28663.14258","13.91644","8.21491"
"79.70000","7.97016","28664.41602","13.93384","8.22844"
"79.80000","7.98013","28666.35352","13.95128","8.24166"
"79.90000","7.99016","28668.29688","13.96882","8.25496"
"80.00000","8.00012","28666.30273","13.98622","8.26884"