File: Lab 2 - Monotonic Tensile and Fracture Toughness/test6.csv
Time,Extension,Load,Tensile strain (Extension),Strain 1
(s),(mm),(N),(%),(%)
"0.00000","0.00000","1.99811","0.00000","0.00167"
"0.20000","0.01648","25.41140","0.02881","0.00181"
"0.40000","0.03855","231.26619","0.06740","0.00278"
"0.60000","0.05967","500.75482","0.10432","0.00449"
"0.80000","0.07995","861.03540","0.13978","0.00682"
"1.00000","0.10006","1272.31567","0.17494","0.00928"
"1.20000","0.12012","1695.36768","0.21000","0.01172"
"1.40000","0.14015","2108.56396","0.24502","0.01431"
"1.60000","0.16019","2526.52319","0.28005","0.01677"
"1.80000","0.18019","2951.80835","0.31502","0.01941"
"2.00000","0.20023","3364.92920","0.35005","0.02158"
"2.20000","0.22013","3774.61499","0.38485","0.02378"
"2.40000","0.24022","4170.67871","0.41996","0.02649"
"2.60000","0.26017","4550.37891","0.45485","0.02813"
"2.80000","0.28011","4863.49609","0.48969","0.02978"
"3.00000","0.30016","5118.15820","0.52476","0.03053"
"3.20000","0.32007","5374.93848","0.55956","0.03149"
"3.40000","0.34018","5618.34326","0.59472","0.03271"
"3.60000","0.36021","5842.25635","0.62974","0.03359"
"3.80000","0.38019","6037.80127","0.66467","0.03459"
"4.00000","0.40018","6195.89648","0.69961","0.03466"
"4.20000","0.42018","6356.20215","0.73459","0.03581"
"4.40000","0.44019","6526.51465","0.76956","0.03625"
"4.60000","0.46015","6713.83789","0.80445","0.03691"
"4.80000","0.48018","6908.23779","0.83948","0.03751"
"5.00000","0.50016","7111.55078","0.87441","0.03855"
"5.20000","0.52015","7310.37939","0.90935","0.03920"
"5.40000","0.54023","7524.68506","0.94446","0.04086"
"5.60000","0.56008","7747.36768","0.97917","0.04162"
"5.80000","0.58022","7965.29785","1.01437","0.04247"
"6.00000","0.60018","8183.49658","1.04926","0.04389"
"6.20000","0.62013","8406.75293","1.08415","0.04493"
"6.40000","0.64024","8640.76270","1.11930","0.04654"
"6.60000","0.66015","8877.26367","1.15410","0.04773"
"6.80000","0.68021","9116.16406","1.18917","0.04918"
"7.00000","0.70019","9361.20312","1.22411","0.05036"
"7.20000","0.72007","9597.60254","1.25886","0.05172"
"7.40000","0.74018","9844.61523","1.29402","0.05347"
"7.60000","0.76019","10083.34570","1.32900","0.05476"
"7.80000","0.78022","10329.48535","1.36402","0.05623"
"8.00000","0.80018","10578.80859","1.39891","0.05787"
"8.20000","0.82013","10830.83887","1.43380","0.05936"
"8.40000","0.84011","11091.11719","1.46873","0.06091"
"8.60000","0.86017","11348.39355","1.50380","0.06244"
"8.80000","0.88021","11608.09082","1.53882","0.06384"
"9.00000","0.90011","11865.86621","1.57362","0.06552"
"9.20000","0.92015","12131.60352","1.60865","0.06737"
"9.40000","0.94015","12398.07715","1.64362","0.06863"
"9.60000","0.96011","12670.69141","1.67851","0.07020"
"9.80000","0.98022","12947.09277","1.71367","0.07192"
"10.00000","1.00012","13216.72168","1.74847","0.07412"
"10.20000","1.02018","13493.94629","1.78354","0.07520"
"10.40000","1.04019","13772.64746","1.81851","0.07721"
"10.60000","1.06012","14048.57617","1.85336","0.07852"
"10.80000","1.08018","14329.71387","1.88843","0.07994"
"11.00000","1.10009","14613.87305","1.92323","0.08202"
"11.20000","1.12014","14899.14551","1.95830","0.08351"
"11.40000","1.14015","15188.24805","1.99327","0.08551"
"11.60000","1.16021","15472.31836","2.02834","0.08738"
"11.80000","1.18017","15763.51270","2.06323","0.08904"
"12.00000","1.20018","16052.56348","2.09821","0.09063"
"12.20000","1.22021","16342.90527","2.13323","0.09237"
"12.40000","1.24011","16633.72070","2.16803","0.09413"
"12.60000","1.26017","16929.49414","2.20310","0.09601"
"12.80000","1.28013","17227.31836","2.23799","0.09778"
"13.00000","1.30009","17523.22656","2.27288","0.09938"
"13.20000","1.32025","17828.40430","2.30812","0.10088"
"13.40000","1.34013","18123.41211","2.34288","0.10299"
"13.60000","1.36011","18423.40625","2.37781","0.10500"
"13.80000","1.38019","18728.38672","2.41292","0.10655"
"14.00000","1.40012","19029.53711","2.44777","0.10821"
"14.20000","1.42018","19338.51758","2.48284","0.11000"
"14.40000","1.44021","19646.19336","2.51786","0.11178"
"14.60000","1.46017","19953.16016","2.55275","0.11398"
"14.80000","1.48015","20263.77539","2.58768","0.11532"
"15.00000","1.50016","20570.59766","2.62266","0.11725"
"15.20000","1.52009","20878.98242","2.65751","0.11917"
"15.40000","1.54015","21198.01758","2.69257","0.12104"
"15.60000","1.56021","21510.32422","2.72764","0.12282"
"15.80000","1.58012","21829.59180","2.76244","0.12508"
"16.00000","1.60017","22144.51953","2.79751","0.12672"
"16.20000","1.62013","22462.04102","2.83240","0.12873"
"16.40000","1.64011","22776.05469","2.86733","0.13040"
"16.60000","1.66025","23096.49219","2.90253","0.13266"
"16.80000","1.68010","23416.26953","2.93724","0.13434"
"17.00000","1.70014","23741.30273","2.97227","0.13644"
"17.20000","1.72014","24068.89648","3.00725","0.13804"
"17.40000","1.74013","24395.08398","3.04218","0.13988"
"17.60000","1.76023","24728.63477","3.07733","0.14252"
"17.80000","1.78017","25051.44531","3.11218","0.14417"
"18.00000","1.80017","25380.34375","3.14716","0.14596"
"18.20000","1.82018","25707.30469","3.18214","0.14796"
"18.40000","1.84016","26037.19141","3.21707","0.14978"
"18.60000","1.86015","26371.68555","3.25200","0.15208"
"18.80000","1.88010","26710.05664","3.28689","0.15384"
"19.00000","1.90011","27043.27930","3.32187","0.15589"
"19.20000","1.92007","27378.56250","3.35676","0.15769"
"19.40000","1.94020","27715.35742","3.39196","0.15987"
"19.60000","1.96023","28049.51953","3.42698","0.16144"
"19.80000","1.98009","28382.35156","3.46170","0.16409"
"20.00000","2.00027","28720.73438","3.49698","0.16581"
"20.20000","2.02016","29059.63086","3.53174","0.16816"
"20.40000","2.04016","29397.38672","3.56672","0.17001"
"20.60000","2.06017","29739.45703","3.60170","0.17241"
"20.80000","2.08010","30075.54688","3.63654","0.17409"
"21.00000","2.10019","30419.96875","3.67165","0.17663"
"21.20000","2.12017","30759.34961","3.70659","0.17845"
"21.40000","2.14013","31098.43750","3.74148","0.18083"
"21.60000","2.16013","31446.18359","3.77646","0.18321"
"21.80000","2.18014","31785.86914","3.81144","0.18537"
"22.00000","2.20017","32132.81250","3.84646","0.18802"
"22.20000","2.22016","32473.00781","3.88139","0.19025"
"22.40000","2.24019","32813.61719","3.91641","0.19301"
"22.60000","2.26015","33145.75000","3.95130","0.19616"
"22.80000","2.28018","33461.51562","3.98633","0.19877"
"23.00000","2.30014","33757.31250","4.02122","0.20330"
"23.20000","2.32007","33999.71875","4.05606","0.20821"
"23.40000","2.34023","33985.89062","4.09131","0.21478"
"23.56400","2.35663","33528.04688","4.11998","0.20556"
"23.76400","2.37656","33531.77734","4.15483","0.20242"
"23.96400","2.39665","33696.41797","4.18994","0.20111"
"24.16400","2.41648","33824.98828","4.22461","0.20079"
"24.36400","2.43659","33921.72656","4.25976","0.19981"
"24.56400","2.45662","33992.92188","4.29479","0.20055"
"24.76400","2.47650","33982.97656","4.32954","0.20264"
"24.96400","2.49658","33929.57812","4.36466","0.20401"
"25.16400","2.51649","33966.26172","4.39946","0.20734"
"25.36400","2.53657","34033.55078","4.43457","0.23425"
"25.56400","2.55668","34126.12891","4.46972","0.31202"
"25.76400","2.57661","34200.10156","4.50457","0.41376"
"25.96400","2.59660","34294.41797","4.53950","0.52991"
"26.16400","2.61655","34337.86719","4.57439","0.65585"
"26.36400","2.63659","34318.41016","4.60941","0.79304"
"26.56400","2.65654","34193.41016","4.64430","0.95668"
"26.76400","2.67655","34135.80078","4.67928","1.13034"
"26.96400","2.69653","34179.94531","4.71422","1.21935"
"27.16400","2.71649","34255.36328","4.74911","1.25945"
"27.36400","2.73662","34286.69141","4.78431","1.28122"
"27.56400","2.75661","34180.91406","4.81924","1.30063"
"27.76400","2.77659","34112.87891","4.85417","1.31422"
"27.96400","2.79665","34189.41406","4.88924","1.32403"
"28.16400","2.81653","34213.81250","4.92400","1.33450"
"28.36400","2.83661","34133.25391","4.95911","1.34469"
"28.56400","2.85657","34221.88672","4.99400","1.35387"
"28.76400","2.87655","34194.20312","5.02893","1.36140"
"28.96400","2.89656","34200.76562","5.06391","1.36588"
"29.16400","2.91662","34245.30469","5.09898","1.37061"
"29.36400","2.93652","34213.37500","5.13378","1.37548"
"29.56400","2.95658","34211.97656","5.16885","1.37845"
"29.76400","2.97661","34209.26953","5.20387","1.38135"
"29.96400","2.99654","34217.21875","5.23871","1.38500"
"30.16400","3.01663","34169.32812","5.27382","1.38714"
"30.36400","3.03663","34178.55859","5.30880","1.39054"
"30.56400","3.05657","34316.22266","5.34365","1.39536"
"30.76400","3.07660","34534.37500","5.37867","1.40458"
"30.96400","3.09648","34722.26953","5.41343","1.41871"
"31.16400","3.11651","34872.33984","5.44845","1.43624"
"31.36400","3.13662","35032.64062","5.48361","1.45412"
"31.56400","3.15658","35211.84766","5.51850","1.47169"
"31.76400","3.17664","35379.21094","5.55356","1.48905"
"31.96400","3.19654","35530.49609","5.58836","1.50593"
"32.16400","3.21653","35666.50781","5.62330","1.52275"
"32.36400","3.23661","35801.82031","5.65841","1.54008"
"32.56400","3.25657","35927.60156","5.69330","1.55709"
"32.76400","3.27655","36045.35938","5.72823","1.57465"
"32.96400","3.29653","36168.70312","5.76317","1.59239"
"33.16400","3.31656","36288.80859","5.79819","1.61052"
"33.36400","3.33655","36410.14062","5.83312","1.62868"
"33.56400","3.35663","36526.48828","5.86823","1.64708"
"33.76400","3.37661","36646.64844","5.90317","1.66562"
"33.96400","3.39654","36763.53125","5.93801","1.68487"
"34.16400","3.41663","36881.65625","5.97312","1.70402"
"34.36400","3.43653","36993.93750","6.00793","1.72259"
"34.56400","3.45657","37107.54297","6.04295","1.74170"
"34.76400","3.47657","37225.43750","6.07793","1.76117"
"34.96400","3.49646","37337.37891","6.11268","1.78053"
"35.16400","3.51659","37457.98047","6.14788","1.80020"
"35.36400","3.53657","37572.54688","6.18282","1.81953"
"35.56400","3.55658","37683.67969","6.21780","1.83983"
"35.76400","3.57659","37795.75000","6.25277","1.85939"
"35.96400","3.59659","37903.98047","6.28775","1.87916"
"36.16400","3.61658","38016.54688","6.32269","1.89860"
"36.36400","3.63653","38129.08984","6.35758","1.91815"
"36.56400","3.65657","38241.42578","6.39260","1.93784"
"36.76400","3.67655","38354.32422","6.42753","1.95801"
"36.96400","3.69656","38468.87500","6.46251","1.97796"
"37.16400","3.71664","38578.88672","6.49762","1.99852"
"37.36400","3.73645","38686.92578","6.53225","2.01874"
"37.56400","3.75665","38798.16406","6.56758","2.03936"
"37.76400","3.77654","38902.83594","6.60233","2.05942"
"37.96400","3.79657","39010.43750","6.63736","2.07967"
"38.16400","3.81663","39118.71484","6.67242","2.10001"
"38.36400","3.83651","39222.69531","6.70718","2.12046"
"38.56400","3.85662","39331.52734","6.74234","2.14165"
"38.76400","3.87657","39434.95312","6.77723","2.16267"
"38.96400","3.89651","39535.24609","6.81207","2.18262"
"39.16400","3.91659","39645.98047","6.84718","2.20331"
"39.36400","3.93660","39744.80859","6.88216","2.22392"
"39.56400","3.95663","39850.49609","6.91718","2.24357"
"39.76400","3.97659","39952.65625","6.95207","2.26403"
"39.96400","3.99654","40054.99609","6.98696","2.28509"
"40.16400","4.01653","40161.36328","7.02190","2.30543"
"40.36400","4.03658","40265.17188","7.05696","2.32566"
"40.56400","4.05659","40364.18750","7.09194","2.34721"
"40.76400","4.07650","40460.89844","7.12674","2.36781"
"40.96400","4.09656","40564.42188","7.16181","2.38854"
"41.16400","4.11654","40662.74609","7.19674","2.40965"
"41.36400","4.13657","40763.66797","7.23177","2.43079"
"41.56400","4.15663","40861.71094","7.26683","2.45143"
"41.76400","4.17651","40957.58984","7.30159","2.47240"
"41.96400","4.19664","41058.53906","7.33679","2.49320"
"42.16400","4.21660","41155.56250","7.37168","2.51445"
"42.36400","4.23658","41248.74609","7.40661","2.53515"
"42.56400","4.25657","41350.20703","7.44155","2.55604"
"42.76400","4.27650","41446.56250","7.47639","2.57708"
"42.96400","4.29653","41545.04688","7.51142","2.59888"
"43.16400","4.31654","41643.96484","7.54640","2.62063"
"43.36400","4.33662","41737.57812","7.58151","2.64294"
"43.56400","4.35658","41832.92578","7.61639","2.66389"
"43.76400","4.37664","41924.59766","7.65146","2.68526"
"43.96400","4.39664","42020.01562","7.68644","2.70717"
"44.16400","4.41655","42108.54297","7.72124","2.72860"
"44.36400","4.43658","42202.46094","7.75626","2.75013"
"44.56400","4.45651","42296.55469","7.79111","2.77173"
"44.76400","4.47652","42389.29297","7.82609","2.79352"
"44.96400","4.49666","42483.16406","7.86129","2.81537"
"45.16400","4.51656","42566.53516","7.89609","2.83737"
"45.36400","4.53660","42657.86719","7.93111","2.85852"
"45.56400","4.55658","42746.96875","7.96604","2.87993"
"45.76400","4.57653","42834.04297","8.00093","2.90222"
"45.96400","4.59659","42925.35156","8.03600","2.92414"
"46.16400","4.61658","43011.91406","8.07094","2.94594"
"46.36400","4.63661","43102.48047","8.10596","2.96786"
"46.56400","4.65656","43191.21094","8.14085","2.98981"
"46.76400","4.67660","43273.91016","8.17587","3.01199"
"46.96400","4.69648","43360.08203","8.21063","3.03448"
"47.16400","4.71656","43447.77344","8.24574","3.05657"
"47.36400","4.73667","43535.14062","8.28089","3.07854"
"47.56400","4.75655","43619.87109","8.31565","3.10103"
"47.76400","4.77661","43701.81641","8.35072","3.12328"
"47.96400","4.79649","43787.53906","8.38548","3.14550"
"48.16400","4.81660","43868.30469","8.42063","3.16775"
"48.36400","4.83663","43956.24219","8.45565","3.19013"
"48.56400","4.85649","44034.89062","8.49037","3.21274"
"48.76400","4.87657","44121.14844","8.52548","3.23554"
"48.96400","4.89650","44201.30078","8.56032","3.25815"
"49.16400","4.91654","44281.56641","8.59534","3.28053"
"49.36400","4.93665","44365.66406","8.63050","3.30304"
"49.56400","4.95658","44440.45312","8.66534","3.32621"
"49.76400","4.97658","44519.60938","8.70032","3.34825"
"49.96400","4.99662","44600.19141","8.73535","3.37102"
"50.16400","5.01663","44677.35156","8.77032","3.39365"
"50.36400","5.03656","44756.55469","8.80517","3.41577"
"50.56400","5.05649","44836.21875","8.84002","3.43863"
"50.76400","5.07655","44914.71484","8.87508","3.46230"
"50.96400","5.09650","44993.64062","8.90997","3.48518"
"51.16400","5.11664","45068.01953","8.94517","3.50840"
"51.36400","5.13659","45139.42969","8.98006","3.53141"
"51.56400","5.15655","45212.57422","9.01495","3.55428"
"51.76400","5.17663","45293.26562","9.05006","3.57658"
"51.96400","5.19654","45367.17578","9.08486","3.60005"
"52.16400","5.21660","45440.52344","9.11993","3.62298"
"52.36400","5.23658","45515.95703","9.15486","3.64591"
"52.56400","5.25656","45584.29297","9.18980","3.66924"
"52.76400","5.27660","45660.82812","9.22482","3.69286"
"52.96400","5.29660","45730.44922","9.25980","3.71546"
"53.16400","5.31656","45801.93750","9.29469","3.73869"
"53.36400","5.33654","45874.36719","9.32962","3.76174"
"53.56400","5.35660","45945.19141","9.36469","3.78539"
"53.76400","5.37653","46016.90625","9.39953","3.80883"
"53.96400","5.39659","46088.56250","9.43460","3.83223"
"54.16400","5.41660","46158.89844","9.46958","3.85648"
"54.36400","5.43656","46225.51953","9.50447","3.87975"
"54.56400","5.45659","46296.05078","9.53949","3.90346"
"54.76400","5.47655","46365.10938","9.57438","3.92757"
"54.96400","5.49650","46434.01953","9.60927","3.95094"
"55.16400","5.51661","46504.96094","9.64443","3.97468"
"55.36400","5.53657","46570.40625","9.67932","3.99888"
"55.56400","5.55663","46633.05469","9.71438","4.02256"
"55.76400","5.57658","46698.91406","9.74927","4.04672"
"55.96400","5.59649","46761.95312","9.78407","4.07008"
"56.16400","5.61662","46832.05078","9.81927","4.09419"
"56.36400","5.63656","46894.45703","9.85412","4.11801"
"56.56400","5.65654","46959.04297","9.88905","4.14255"
"56.76400","5.67652","47028.38281","9.92399","4.16684"
"56.96400","5.69655","47089.06250","9.95901","4.19068"
"57.16400","5.71656","47155.26953","9.99399","4.21532"
"57.36400","5.73664","47216.08984","10.02910","4.23939"
"57.56400","5.75663","47277.29688","10.06403","4.26374"
"57.76400","5.77651","47337.25781","10.09879","4.28776"
"57.96400","5.79659","47400.03125","10.13390","4.31278"
"58.16400","5.81660","47464.19922","10.16888","4.33688"
"58.36400","5.83658","47524.23047","10.20381","4.36139"
"58.56400","5.85656","47588.55859","10.23875","4.38621"
"58.76400","5.87644","47644.27344","10.27351","4.41112"
"58.96400","5.89658","47705.88672","10.30870","4.43570"
"59.16400","5.91664","47764.56641","10.34377","4.46052"
"59.36400","5.93659","47820.28516","10.37866","4.48507"
"59.56400","5.95658","47882.48047","10.41359","4.51007"
"59.76400","5.97656","47939.23438","10.44853","4.53459"
"59.96400","5.99657","47995.53125","10.48351","4.55969"
"60.16400","6.01657","48054.03125","10.51848","4.58449"
"60.36400","6.03661","48108.33203","10.55351","4.60960"
"60.56400","6.05656","48165.29297","10.58840","4.63378"
"60.76400","6.07655","48221.30469","10.62333","4.65881"
"60.96400","6.09665","48279.61719","10.65849","4.68467"
"61.16400","6.11646","48335.46094","10.69311","4.71036"
"61.36400","6.13664","48391.05859","10.72840","4.73522"
"61.56400","6.15658","48444.93750","10.76325","4.76088"
"61.76400","6.17653","48497.78906","10.79813","4.78593"
"61.96400","6.19664","48552.78125","10.83329","4.81150"
"62.16400","6.21652","48601.89062","10.86805","4.83650"
"62.36400","6.23661","48656.12109","10.90316","4.86188"
"62.56400","6.25659","48710.35547","10.93809","4.88723"
"62.76400","6.27649","48759.69141","10.97289","4.91302"
"62.96400","6.29660","48818.89453","11.00805","4.93871"
"63.16400","6.31659","48866.53125","11.04298","4.96477"
"63.36400","6.33664","48915.86719","11.07805","4.99044"
"63.56400","6.35660","48966.99609","11.11294","5.01602"
"63.76400","6.37658","49016.96875","11.14787","5.04181"
"63.96400","6.39657","49068.06641","11.18281","5.06791"
"64.16400","6.41655","49119.03125","11.21774","5.09335"
"64.36400","6.43658","49166.50781","11.25276","5.11985"
"64.56400","6.45651","49213.17578","11.28761","5.14547"
"64.76400","6.47657","49259.47656","11.32268","5.17115"
"64.96400","6.49658","49304.83203","11.35765","5.19643"
"65.16400","6.51656","49350.62109","11.39259","5.22252"
"65.36400","6.53667","49399.81250","11.42774","5.24813"
"65.56400","6.55655","49445.88672","11.46250","5.27379"
"65.76400","6.57663","49491.89453","11.49761","5.29941"
"65.96400","6.59659","49541.39062","11.53250","5.32613"
"66.16400","6.61655","49583.93750","11.56739","5.35214"
"66.36400","6.63658","49633.93359","11.60241","5.37896"
"66.56400","6.65651","49675.42188","11.63726","5.40492"
"66.76400","6.67652","49720.94141","11.67224","5.43082"
"66.96400","6.69655","49770.46094","11.70726","5.45789"
"67.16400","6.71661","49811.15625","11.74233","5.48413"
"67.36400","6.73657","49857.87891","11.77722","5.51110"
"67.56400","6.75658","49899.15625","11.81219","5.53799"
"67.76400","6.77658","49945.04688","11.84717","5.56438"
"67.96400","6.79654","49986.74609","11.88206","5.59113"
"68.16400","6.81660","50029.38672","11.91713","5.61817"
"68.36400","6.83658","50072.34375","11.95206","5.64523"
"68.56400","6.85651","50113.32812","11.98691","5.67159"
"68.76400","6.87660","50159.90625","12.02202","5.69901"
"68.96400","6.89658","50200.07031","12.05695","5.72652"
"69.16400","6.91653","50239.30859","12.09184","5.75378"
"69.36400","6.93662","50282.09766","12.12695","5.78141"
"69.56400","6.95658","50318.63281","12.16184","5.80837"
"69.76400","6.97661","50359.46484","12.19687","5.83580"
"69.96400","6.99656","50399.97656","12.23176","5.86330"
"70.16400","7.01657","50433.62891","12.26673","5.89036"
"70.36400","7.03655","50472.20703","12.30167","5.91729"
"70.56400","7.05659","50510.24609","12.33669","5.94467"
"70.76400","7.07652","50552.26172","12.37154","5.97190"
"70.96400","7.09658","50590.89844","12.40660","5.99928"
"71.16400","7.11661","50624.92578","12.44163","6.02685"
"71.36400","7.13659","50664.19922","12.47656","6.05443"
"71.56400","7.15665","50701.19531","12.51163","6.08153"
"71.76400","7.17653","50739.00391","12.54638","6.10969"
"71.96400","7.19657","50775.63672","12.58141","6.13718"
"72.16400","7.21662","50810.90234","12.61647","6.16506"
"72.36400","7.23650","50844.94922","12.65123","6.19281"
"72.56400","7.25656","50882.55859","12.68630","6.21993"
"72.76400","7.27657","50920.62891","12.72127","6.24831"
"72.96400","7.29653","50954.39062","12.75617","6.27636"
"73.16400","7.31664","50990.53906","12.79132","6.30458"
"73.36400","7.33657","51021.66406","12.82617","6.33285"
"73.56400","7.35657","51057.13672","12.86114","6.36072"
"73.76400","7.37658","51093.22656","12.89612","6.38914"
"73.96400","7.39661","51123.28125","12.93114","6.41701"
"74.16400","7.41660","51155.71484","12.96608","6.44524"
"74.36400","7.43653","51189.89453","13.00092","6.47313"
"74.56400","7.45659","51223.27344","13.03599","6.50199"
"74.76400","7.47647","51257.45703","13.07075","6.53056"
"74.96400","7.49658","51289.44531","13.10590","6.55917"
"75.16400","7.51661","51319.91406","13.14093","6.58794"
"75.36400","7.53654","51347.53516","13.17577","6.61611"
"75.56400","7.55668","51380.44922","13.21097","6.64459"
"75.76400","7.57656","51412.12891","13.24573","6.67273"
"75.96400","7.59659","51441.59766","13.28075","6.70150"
"76.16400","7.61660","51476.39062","13.31573","6.73010"
"76.36400","7.63655","51505.08984","13.35062","6.75904"
"76.56400","7.65656","51538.72266","13.38560","6.78782"
"76.76400","7.67659","51568.02344","13.42062","6.81697"
"76.96400","7.69655","51592.48828","13.45551","6.84593"
"77.16400","7.71658","51624.57812","13.49053","6.87468"
"77.36400","7.73659","51651.39844","13.52551","6.90397"
"77.56400","7.75652","51682.73047","13.56036","6.93239"
"77.76400","7.77653","51711.73047","13.59533","6.96196"
"77.96400","7.79664","51741.25391","13.63049","6.99139"
"78.16400","7.81660","51767.53516","13.66538","7.02047"
"78.36400","7.83658","51792.83203","13.70031","7.04974"
"78.56400","7.85659","51820.48828","13.73529","7.07877"
"78.76400","7.87649","51848.37500","13.77009","7.10785"
"78.96400","7.89665","51879.53125","13.80534","7.13811"
"79.16400","7.91658","51903.00391","13.84018","7.16759"
"79.36400","7.93659","51928.80078","13.87516","7.19699"
"79.56400","7.95660","51956.48828","13.91014","7.22682"
"79.76400","7.97653","51980.67578","13.94498","7.25568"
"79.96400","7.99666","52007.94531","13.98018","7.28548"
"80.16400","8.01657","52031.16016","14.01498","7.31503"
"80.36400","8.03650","52053.97656","14.04983","7.34436"
"80.56400","8.05654","52083.77734","14.08485","7.37467"
"80.76400","8.07654","52106.99609","14.11983","7.40423"
"80.96400","8.09658","52135.49609","14.15485","7.43424"
"81.16400","8.11661","52156.47656","14.18988","7.46427"
"81.36400","8.13664","52179.33203","14.22490","7.49391"
"81.56400","8.15657","52202.78516","14.25974","7.52374"
"81.76400","8.17661","52225.70312","14.29477","7.55366"
"81.96400","8.19659","52251.01172","14.32970","7.58388"
"82.16400","8.21655","52271.61719","14.36459","7.61322"
"82.36400","8.23655","52297.84766","14.39957","7.64350"
"82.56400","8.25648","52320.63672","14.43441","7.67363"
"82.76400","8.27652","52345.41406","14.46944","7.70393"
"82.96400","8.29663","52368.53906","14.50459","7.73477"
"83.16400","8.31656","52384.10938","14.53944","7.76530"
"83.36400","8.33659","52407.49609","14.57446","7.79510"
"83.56400","8.35655","52429.17578","14.60935","7.82506"
"83.76400","8.37658","52445.64453","14.64437","7.85511"
"83.96400","8.39659","52469.32422","14.67935","7.88518"
"84.16400","8.41660","52489.86328","14.71433","7.91523"
"84.36400","8.43655","52513.46094","14.74922","7.94557"
"84.56400","8.45654","52535.69922","14.78415","7.97628"
"84.76400","8.47667","52554.97656","14.81935","8.00701"
"84.96400","8.49647","52575.89062","14.85398","8.03778"
"85.16400","8.51663","52598.14453","14.88922","8.06888"
"85.36400","8.53659","52618.50781","14.92411","8.09995"
"85.56400","8.55650","52635.17969","14.95891","8.13054"
"85.76400","8.57663","52658.51172","14.99411","8.16187"
"85.96400","8.59654","52673.88672","15.02891","8.19258"
"86.16400","8.61660","52692.40234","15.06398","8.22345"
"86.36400","8.63660","52714.80078","15.09896","8.25423"
"86.56400","8.65648","52730.76172","15.13371","8.28519"
"86.76400","8.67659","52754.82031","15.16887","8.31618"
"86.96400","8.69658","52770.26172","15.20380","8.34797"
"87.16400","8.71666","52789.38281","15.23891","8.38015"
"87.36400","8.73662","52806.62891","15.27380","8.41147"
"87.56400","8.75655","52818.85156","15.30865","8.44224"
"87.76400","8.77656","52838.71875","15.34363","8.47309"
"87.96400","8.79656","52860.58594","15.37860","8.50452"
"88.16400","8.81660","52878.26172","15.41363","8.53626"
"88.36400","8.83650","52897.62500","15.44843","8.56785"
"88.56400","8.85653","52914.15625","15.48345","8.60056"
"88.76400","8.87659","52929.17969","15.51852","8.63205"
"88.96400","8.89653","52943.96094","15.55337","8.66397"
"89.16400","8.91666","52961.78516","15.58856","8.69545"
"89.36400","8.93654","52979.83984","15.62332","8.72724"
"89.56400","8.95660","52995.82031","15.65839","8.75886"
"89.76400","8.97666","53015.01172","15.69345","8.79127"
"89.96400","8.99656","53026.17969","15.72825","8.82361"
"90.16400","9.01662","53045.28516","15.76332","8.85516"
"90.36400","9.03653","53058.73047","15.79812","8.88751"
"90.56400","9.05653","53070.20703","15.83310","8.91968"
"90.76400","9.07657","53090.01953","15.86812","8.95190"
"90.96400","9.09660","53103.45312","15.90315","8.98414"
"91.16400","9.11661","53118.76953","15.93813","9.01641"
"91.36400","9.13657","53131.50391","15.97302","9.04827"
"91.56400","9.15660","53146.82812","16.00804","9.08075"
"91.76400","9.17655","53162.51953","16.04293","9.11306"
"91.96400","9.19659","53178.64844","16.07795","9.14558"
"92.16400","9.21660","53192.03906","16.11293","9.17805"
"92.36400","9.23650","53202.95703","16.14773","9.21097"
"92.56400","9.25664","53220.86719","16.18293","9.24351"
"92.76400","9.27659","53233.67188","16.21782","9.27633"
"92.96400","9.29652","53247.61328","16.25266","9.30917"
"93.16400","9.31663","53262.67578","16.28782","9.34191"
"93.36400","9.33651","53270.87500","16.32258","9.37469"
"93.56400","9.35660","53284.90625","16.35769","9.40760"
"93.76400","9.37658","53299.53906","16.39262","9.44070"
"93.96400","9.39656","53310.44141","16.42756","9.47365"
"94.16400","9.41657","53327.34766","16.46253","9.50676"
"94.36400","9.43655","53336.83594","16.49747","9.54019"
"94.56400","9.45653","53352.42578","16.53240","9.57349"
"94.76400","9.47657","53369.23438","16.56742","9.60699"
"94.96400","9.49662","53376.48828","16.60249","9.64078"
"95.16400","9.51663","53386.88672","16.63747","9.67381"
"95.36400","9.53664","53395.99219","16.67245","9.70754"
"95.56400","9.55655","53408.58203","16.70725","9.74063"
"95.76400","9.57653","53421.67188","16.74218","9.77406"
"95.96400","9.59661","53434.05078","16.77729","9.80780"
"96.16400","9.61652","53443.46094","16.81210","9.84172"
"96.36400","9.63655","53456.16797","16.84712","9.87556"
"96.56400","9.65658","53469.39453","16.88214","9.90901"
"96.76400","9.67654","53475.12891","16.91703","9.94283"
"96.96400","9.69662","53490.32812","16.95214","9.97669"
"97.16400","9.71663","53500.68750","16.98712","10.01069"
"97.36400","9.73659","53508.09766","17.02201","10.04496"
"97.56400","9.75657","53519.63672","17.05694","10.07857"
"97.76400","9.77658","53528.68359","17.09192","10.11297"
"97.96400","9.79659","53541.21875","17.12690","10.14708"
"98.16400","9.81654","53551.62109","17.16179","10.18130"
"98.36400","9.83658","53559.75000","17.19681","10.21566"
"98.56400","9.85648","53571.10547","17.23161","10.24997"
"98.76400","9.87659","53581.98828","17.26677","10.28447"
"98.96400","9.89660","53591.03516","17.30175","10.31907"
"99.16400","9.91651","53599.43359","17.33655","10.35353"
"99.36400","9.93664","53608.67188","17.37175","10.38819"
"99.56400","9.95655","53617.13672","17.40655","10.42262"
"99.76400","9.97658","53623.12891","17.44157","10.45737"
"99.96400","9.99661","53637.38672","17.47659","10.49207"
"100.00000","10.00016","53638.99609","17.48281","10.49813"