File: Lab 2 - Monotonic Tensile and Fracture Toughness/test5.csv
Time,Extension,Load,Tensile strain (Extension)
(s),(mm),(N),(%)
"0.00000","0.00000","1.27835","0.00000"
"0.20000","0.01645","21.93377","0.02877"
"0.40000","0.03868","250.13036","0.06762"
"0.60000","0.05972","498.97766","0.10441"
"0.80000","0.08008","839.02020","0.14000"
"1.00000","0.10009","1243.03503","0.17498"
"1.20000","0.12025","1641.00769","0.21022"
"1.40000","0.14013","2037.83777","0.24498"
"1.60000","0.16016","2451.95117","0.28000"
"1.80000","0.18022","2884.23242","0.31507"
"2.00000","0.20013","3303.11572","0.34987"
"2.20000","0.22021","3712.23120","0.38498"
"2.40000","0.24019","3909.06177","0.41991"
"2.60000","0.26022","4085.53516","0.45494"
"2.80000","0.28021","4235.93896","0.48987"
"3.00000","0.30024","4385.66504","0.52489"
"3.20000","0.32022","4544.63574","0.55983"
"3.40000","0.34018","4712.04395","0.59472"
"3.60000","0.36021","4870.58838","0.62974"
"3.80000","0.38017","5036.37549","0.66463"
"4.00000","0.40020","5212.79590","0.69965"
"4.20000","0.42028","5399.77490","0.73476"
"4.40000","0.44014","5589.48584","0.76948"
"4.60000","0.46025","5809.49316","0.80463"
"4.80000","0.48018","6029.39307","0.83948"
"5.00000","0.50016","6260.90332","0.87441"
"5.20000","0.52027","6503.28711","0.90957"
"5.40000","0.54015","6749.16602","0.94432"
"5.60000","0.56029","7006.73926","0.97952"
"5.80000","0.58022","7261.29102","1.01437"
"6.00000","0.60015","7490.97412","1.04921"
"6.20000","0.62021","7671.90918","1.08428"
"6.40000","0.64022","7891.18701","1.11926"
"6.60000","0.66022","8128.98340","1.15424"
"6.80000","0.68018","8377.70703","1.18913"
"7.00000","0.70016","8638.99902","1.22406"
"7.20000","0.72017","8905.47949","1.25904"
"7.40000","0.74020","9170.31738","1.29406"
"7.60000","0.76021","9444.63867","1.32904"
"7.80000","0.78014","9711.83594","1.36389"
"8.00000","0.80020","9986.31641","1.39895"
"8.20000","0.82018","10260.69043","1.43389"
"8.40000","0.84019","10537.37891","1.46886"
"8.60000","0.86027","10813.77441","1.50397"
"8.80000","0.88018","11088.85449","1.53878"
"9.00000","0.90024","11363.30957","1.57384"
"9.20000","0.92022","11637.57520","1.60878"
"9.40000","0.94018","11908.67676","1.64367"
"9.60000","0.96019","12185.95312","1.67865"
"9.80000","0.98012","12462.86035","1.71349"
"10.00000","1.00018","12745.12402","1.74856"
"10.20000","1.02016","13028.25684","1.78349"
"10.40000","1.04027","13307.15527","1.81865"
"10.60000","1.06017","13593.58301","1.85345"
"10.80000","1.08021","13872.10938","1.88847"
"11.00000","1.10024","14153.23633","1.92349"
"11.20000","1.12017","14432.64062","1.95834"
"11.40000","1.14025","14714.28418","1.99345"
"11.60000","1.16019","14999.59961","2.02830"
"11.80000","1.18014","15282.33887","2.06319"
"12.00000","1.20025","15573.25977","2.09834"
"12.20000","1.22016","15853.47949","2.13314"
"12.40000","1.24022","16143.25000","2.16821"
"12.60000","1.26022","16429.87305","2.20319"
"12.80000","1.28015","16717.08984","2.23803"
"13.00000","1.30021","17014.26172","2.27310"
"13.20000","1.32020","17305.78906","2.30803"
"13.40000","1.34018","17601.58984","2.34297"
"13.60000","1.36018","17903.09375","2.37795"
"13.80000","1.38022","18199.91016","2.41297"
"14.00000","1.40017","18498.12891","2.44786"
"14.20000","1.42023","18802.61719","2.48292"
"14.40000","1.44024","19103.86719","2.51790"
"14.60000","1.46017","19408.89844","2.55275"
"14.80000","1.48026","19712.50977","2.58786"
"15.00000","1.50011","20019.45117","2.62257"
"15.20000","1.52017","20323.68359","2.65764"
"15.40000","1.54025","20632.26953","2.69275"
"15.60000","1.56013","20937.85938","2.72751"
"15.80000","1.58022","21252.36133","2.76262"
"16.00000","1.60017","21564.78125","2.79751"
"16.20000","1.62018","21874.91602","2.83249"
"16.40000","1.64024","22195.06641","2.86755"
"16.60000","1.66022","22508.41602","2.90249"
"16.80000","1.68023","22826.33594","2.93746"
"17.00000","1.70019","23141.00977","2.97235"
"17.20000","1.72022","23462.06055","3.00738"
"17.40000","1.74018","23781.92773","3.04227"
"17.60000","1.76013","24104.00586","3.07716"
"17.80000","1.78019","24428.79492","3.11222"
"18.00000","1.80010","24752.88867","3.14703"
"18.20000","1.82023","25081.02930","3.18222"
"18.40000","1.84021","25403.08203","3.21716"
"18.60000","1.86012","25727.88086","3.25196"
"18.80000","1.88025","26059.18359","3.28716"
"19.00000","1.90016","26384.83008","3.32196"
"19.20000","1.92022","26713.83398","3.35703"
"19.40000","1.94020","27047.63477","3.39196"
"19.60000","1.96018","27370.38672","3.42690"
"19.80000","1.98019","27707.38281","3.46187"
"20.00000","2.00022","28037.05664","3.49690"
"20.20000","2.02018","28365.58789","3.53179"
"20.40000","2.04019","28701.80664","3.56676"
"20.60000","2.06020","29037.77344","3.60174"
"20.80000","2.08018","29374.60156","3.63668"
"21.00000","2.10021","29702.47266","3.67170"
"21.20000","2.12022","30030.59961","3.70668"
"21.40000","2.14015","30356.87305","3.74152"
"21.60000","2.16023","30685.40430","3.77663"
"21.80000","2.18017","30996.72852","3.81148"
"22.00000","2.20015","31295.64844","3.84641"
"22.20000","2.22026","31591.54102","3.88157"
"22.40000","2.24019","31860.50977","3.91641"
"22.60000","2.26022","32081.26758","3.95144"
"22.80000","2.28018","32235.88672","3.98633"
"23.00000","2.30016","32332.61914","4.02126"
"23.20000","2.32027","32421.36328","4.05641"
"23.40000","2.34020","32660.09766","4.09126"
"23.60000","2.36016","32866.94531","4.12615"
"23.80000","2.38017","33042.71484","4.16113"
"24.00000","2.40020","33185.00391","4.19615"
"24.20000","2.42021","33328.88672","4.23113"
"24.40000","2.44026","33450.28516","4.26620"
"24.60000","2.46027","33560.19141","4.30117"
"24.80000","2.48018","33635.51562","4.33598"
"25.00000","2.50024","33624.71094","4.37104"
"25.20000","2.52019","33503.32812","4.40593"
"25.40000","2.54020","33227.65234","4.44091"
"25.60000","2.56021","33005.67969","4.47589"
"25.80000","2.58014","32876.62109","4.51074"
"26.00000","2.60017","32912.40234","4.54576"
"26.20000","2.62026","33001.88281","4.58087"
"26.40000","2.64024","33024.92969","4.61580"
"26.60000","2.66025","33044.75391","4.65078"
"26.80000","2.68020","33046.22656","4.68567"
"27.00000","2.70021","33037.61328","4.72065"
"27.20000","2.72022","33056.73438","4.75563"
"27.40000","2.74023","33090.19922","4.79061"
"27.60000","2.76021","33121.42188","4.82554"
"27.80000","2.78019","33110.21094","4.86047"
"28.00000","2.80027","33117.89453","4.89558"
"28.20000","2.82008","33094.12109","4.93021"
"28.40000","2.84031","33093.40625","4.96558"
"28.60000","2.86022","33118.37500","5.00039"
"28.80000","2.88018","33129.22266","5.03528"
"29.00000","2.90029","33172.64453","5.07043"
"29.20000","2.92017","33183.23047","5.10519"
"29.34000","2.93420","32711.92969","5.12973"
"29.54000","2.95426","32745.33789","5.16479"
"29.74000","2.97417","33228.48828","5.19959"
"29.94000","2.99415","33625.42969","5.23453"
"30.14000","3.01426","33918.97656","5.26968"
"30.34000","3.03422","34133.59375","5.30457"
"30.54000","3.05422","34310.94141","5.33955"
"30.74000","3.07418","34467.85547","5.37444"
"30.94000","3.09414","34614.67188","5.40933"
"31.14000","3.11427","34761.00000","5.44453"
"31.34000","3.13420","34894.60156","5.47938"
"31.54000","3.15419","35024.48828","5.51431"
"31.74000","3.17417","35153.32422","5.54924"
"31.94000","3.19420","35274.57812","5.58427"
"32.14000","3.21418","35399.32031","5.61920"
"32.34000","3.23424","35522.59375","5.65427"
"32.54000","3.25425","35647.03906","5.68925"
"32.74000","3.27416","35771.93359","5.72405"
"32.94000","3.29426","35895.64453","5.75920"
"33.14000","3.31422","36016.33594","5.79409"
"33.34000","3.33418","36130.77344","5.82898"
"33.54000","3.35419","36256.47656","5.86396"
"33.74000","3.37414","36376.17578","5.89885"
"33.94000","3.39423","36498.36328","5.93396"
"34.14000","3.41421","36618.89844","5.96890"
"34.34000","3.43422","36736.60547","6.00387"
"34.54000","3.45420","36854.87500","6.03881"
"34.74000","3.47421","36969.85938","6.07379"
"34.94000","3.49421","37085.16797","6.10876"
"35.14000","3.51422","37203.80469","6.14374"
"35.34000","3.53423","37321.00781","6.17872"
"35.54000","3.55419","37438.92188","6.21361"
"35.74000","3.57419","37557.12891","6.24859"
"35.94000","3.59425","37673.96094","6.28366"
"36.14000","3.61408","37784.91016","6.31832"
"36.34000","3.63429","37899.09375","6.35365"
"36.54000","3.65420","38009.30469","6.38846"
"36.74000","3.67418","38119.44531","6.42339"
"36.94000","3.69426","38236.92969","6.45850"
"37.14000","3.71414","38347.96875","6.49326"
"37.34000","3.73423","38463.70312","6.52837"
"37.54000","3.75424","38576.12109","6.56335"
"37.74000","3.77417","38681.90625","6.59819"
"37.94000","3.79423","38796.05078","6.63326"
"38.14000","3.81421","38901.32422","6.66819"
"38.34000","3.83427","39015.47266","6.70326"
"38.54000","3.85425","39124.14844","6.73820"
"38.74000","3.87418","39231.42578","6.77304"
"38.94000","3.89416","39342.72656","6.80798"
"39.14000","3.91419","39449.85156","6.84300"
"39.34000","3.93423","39553.77734","6.87802"
"39.54000","3.95416","39658.01562","6.91287"
"39.74000","3.97419","39763.93750","6.94789"
"39.94000","3.99420","39871.25391","6.98287"
"40.14000","4.01421","39976.50000","7.01784"
"40.34000","4.03432","40081.95312","7.05300"
"40.54000","4.05420","40186.13281","7.08776"
"40.74000","4.07423","40288.73828","7.12278"
"40.94000","4.09424","40394.95312","7.15776"
"41.14000","4.11419","40492.66406","7.19265"
"41.34000","4.13423","40599.49219","7.22767"
"41.54000","4.15413","40700.11328","7.26247"
"41.74000","4.17412","40801.87500","7.29741"
"41.94000","4.19422","40908.97656","7.33256"
"42.14000","4.21428","41004.78125","7.36763"
"42.34000","4.23424","41104.48047","7.40252"
"42.54000","4.25422","41200.12500","7.43745"
"42.74000","4.27425","41301.35156","7.47247"
"42.94000","4.29419","41400.45703","7.50732"
"43.14000","4.31424","41499.90234","7.54239"
"43.34000","4.33423","41594.07812","7.57732"
"43.54000","4.35413","41688.53906","7.61212"
"43.74000","4.37424","41788.44922","7.64728"
"43.94000","4.39417","41878.96094","7.68212"
"44.14000","4.41421","41972.15625","7.71715"
"44.34000","4.43426","42069.88672","7.75221"
"44.54000","4.45412","42159.41016","7.78693"
"44.74000","4.47420","42259.84766","7.82204"
"44.94000","4.49424","42354.85938","7.85706"
"45.14000","4.51424","42444.71094","7.89204"
"45.34000","4.53423","42537.77344","7.92697"
"45.54000","4.55423","42627.14844","7.96195"
"45.74000","4.57414","42717.56641","7.99675"
"45.94000","4.59420","42807.26562","8.03182"
"46.14000","4.61428","42899.01562","8.06693"
"46.34000","4.63419","42989.91016","8.10173"
"46.54000","4.65425","43079.18750","8.13679"
"46.74000","4.67415","43167.58594","8.17160"
"46.94000","4.69421","43252.61328","8.20666"
"47.14000","4.71427","43342.24219","8.24173"
"47.34000","4.73413","43427.38281","8.27644"
"47.54000","4.75421","43518.36719","8.31155"
"47.74000","4.77417","43604.67578","8.34644"
"47.94000","4.79415","43688.41406","8.38138"
"48.14000","4.81428","43778.25781","8.41658"
"48.34000","4.83424","43860.69922","8.45147"
"48.54000","4.85425","43944.10938","8.48645"
"48.74000","4.87423","44026.98438","8.52138"
"48.94000","4.89419","44112.09375","8.55627"
"49.14000","4.91422","44199.31641","8.59129"
"49.34000","4.93413","44282.29688","8.62609"
"49.54000","4.95418","44364.84766","8.66116"
"49.74000","4.97409","44447.04297","8.69596"
"49.94000","4.99422","44527.07031","8.73116"
"50.14000","5.01426","44604.64844","8.76618"
"50.34000","5.03416","44681.72656","8.80098"
"50.54000","5.05432","44766.15625","8.83623"
"50.74000","5.07420","44846.87891","8.87099"
"50.94000","5.09424","44924.30469","8.90601"
"51.14000","5.11422","45006.24609","8.94094"
"51.34000","5.13418","45080.57422","8.97583"
"51.54000","5.15423","45163.25781","9.01090"
"51.74000","5.17422","45238.14453","9.04583"
"51.94000","5.19417","45315.74609","9.08072"
"52.14000","5.21423","45396.01562","9.11579"
"52.34000","5.23421","45466.72656","9.15072"
"52.54000","5.25417","45541.18359","9.18561"
"52.74000","5.27418","45618.17969","9.22059"
"52.94000","5.29431","45692.17969","9.25579"
"53.14000","5.31422","45762.51953","9.29059"
"53.34000","5.33423","45838.51562","9.32557"
"53.54000","5.35421","45909.87891","9.36050"
"53.74000","5.37409","45981.17578","9.39526"
"53.94000","5.39430","46060.12109","9.43059"
"54.14000","5.41421","46127.65625","9.46539"
"54.34000","5.43424","46199.98047","9.50042"
"54.54000","5.45422","46274.13281","9.53535"
"54.74000","5.47413","46340.21094","9.57015"
"54.94000","5.49429","46415.22656","9.60540"
"55.14000","5.51422","46485.16016","9.64024"
"55.34000","5.53415","46551.19922","9.67509"
"55.54000","5.55418","46625.75000","9.71011"
"55.74000","5.57419","46688.14062","9.74509"
"55.94000","5.59420","46758.49219","9.78007"
"56.14000","5.61426","46821.64062","9.81513"
"56.34000","5.63426","46887.44141","9.85011"
"56.54000","5.65420","46956.58594","9.88496"
"56.74000","5.67425","47022.57422","9.92002"
"56.94000","5.69421","47091.29688","9.95491"
"57.14000","5.71419","47153.63672","9.98985"
"57.34000","5.73418","47219.98828","10.02478"
"57.54000","5.75411","47283.57812","10.05963"
"57.74000","5.77417","47348.52734","10.09469"
"57.94000","5.79427","47413.83203","10.12985"
"58.14000","5.81421","47473.82812","10.16469"
"58.34000","5.83424","47538.23438","10.19972"
"58.54000","5.85422","47599.78516","10.23465"
"58.74000","5.87423","47659.62109","10.26963"
"58.94000","5.89424","47721.55859","10.30461"
"59.14000","5.91427","47779.49609","10.33963"
"59.34000","5.93420","47839.13281","10.37448"
"59.54000","5.95416","47902.07422","10.40937"
"59.74000","5.97427","47963.68359","10.44452"
"59.94000","5.99412","48024.67578","10.47923"
"60.14000","6.01426","48084.09375","10.51443"
"60.34000","6.03421","48141.54688","10.54932"
"60.54000","6.05412","48196.09375","10.58412"
"60.74000","6.07428","48256.52344","10.61937"
"60.94000","6.09423","48311.05469","10.65426"
"61.14000","6.11424","48361.88672","10.68923"
"61.34000","6.13425","48421.07031","10.72421"
"61.54000","6.15406","48473.01953","10.75884"
"61.74000","6.17421","48538.10938","10.79408"
"61.94000","6.19427","48591.83594","10.82915"
"62.14000","6.21425","48642.28125","10.86408"
"62.34000","6.23424","48695.18750","10.89902"
"62.54000","6.25417","48750.80469","10.93386"
"62.74000","6.27420","48807.19922","10.96888"
"62.94000","6.29421","48863.63281","11.00386"
"63.14000","6.31422","48916.08594","11.03884"
"63.34000","6.33415","48968.73047","11.07369"
"63.54000","6.35418","49020.44141","11.10871"
"63.74000","6.37421","49072.01953","11.14373"
"63.94000","6.39420","49124.82812","11.17867"
"64.14000","6.41433","49176.71875","11.21386"
"64.34000","6.43421","49228.18750","11.24862"
"64.54000","6.45425","49276.93359","11.28365"
"64.74000","6.47423","49331.14453","11.31858"
"64.94000","6.49416","49377.67188","11.35342"
"65.14000","6.51424","49429.34766","11.38853"
"65.34000","6.53415","49473.72266","11.42334"
"65.54000","6.55413","49521.78125","11.45827"
"65.74000","6.57419","49575.31250","11.49334"
"65.94000","6.59425","49619.86719","11.52840"
"66.14000","6.61423","49669.65234","11.56334"
"66.34000","6.63424","49715.77734","11.59832"
"66.54000","6.65427","49763.26172","11.63334"
"66.74000","6.67420","49808.05078","11.66819"
"66.94000","6.69421","49854.00000","11.70316"
"67.14000","6.71427","49904.30859","11.73823"
"67.34000","6.73415","49946.41016","11.77299"
"67.54000","6.75426","49993.75781","11.80814"
"67.74000","6.77419","50036.30469","11.84299"
"67.94000","6.79417","50079.47656","11.87792"
"68.14000","6.81428","50125.89062","11.91308"
"68.34000","6.83414","50161.27344","11.94779"
"68.54000","6.85419","50208.03125","11.98286"
"68.74000","6.87423","50253.10938","12.01788"
"68.94000","6.89426","50295.78125","12.05290"
"69.14000","6.91422","50340.14062","12.08779"
"69.34000","6.93420","50376.88672","12.12272"
"69.54000","6.95411","50417.24609","12.15753"
"69.74000","6.97421","50464.69531","12.19268"
"69.94000","6.99430","50501.88281","12.22779"
"70.14000","7.01420","50541.56641","12.26260"
"70.34000","7.03424","50580.69922","12.29762"
"70.54000","7.05419","50624.42578","12.33251"
"70.74000","7.07420","50661.76172","12.36749"
"70.94000","7.09428","50702.75781","12.40259"
"71.14000","7.11412","50736.73828","12.43726"
"71.34000","7.13417","50777.24609","12.47233"
"71.54000","7.15418","50818.94922","12.50731"
"71.74000","7.17414","50853.56250","12.54220"
"71.94000","7.19427","50894.75391","12.57740"
"72.14000","7.21425","50927.74609","12.61233"
"72.34000","7.23424","50962.90625","12.64727"
"72.54000","7.25424","51000.26562","12.68224"
"72.74000","7.27423","51032.79297","12.71718"
"72.94000","7.29423","51068.66797","12.75216"
"73.14000","7.31417","51106.16016","12.78700"
"73.34000","7.33417","51141.09375","12.82198"
"73.54000","7.35410","51180.11328","12.85683"
"73.74000","7.37421","51216.04297","12.89198"
"73.94000","7.39427","51250.02734","12.92705"
"74.14000","7.41418","51280.16016","12.96185"
"74.34000","7.43434","51314.97266","12.99709"
"74.54000","7.45419","51348.94922","13.03181"
"74.74000","7.47423","51382.57812","13.06683"
"74.94000","7.49423","51420.39062","13.10181"
"75.14000","7.51417","51450.21484","13.13665"
"75.34000","7.53422","51484.26953","13.17172"
"75.54000","7.55421","51515.30469","13.20665"
"75.74000","7.57416","51543.35938","13.24154"
"75.94000","7.59425","51579.50000","13.27665"
"76.14000","7.61420","51607.06641","13.31154"
"76.34000","7.63419","51640.33203","13.34648"
"76.54000","7.65417","51672.04297","13.38141"
"76.74000","7.67430","51703.00781","13.41661"
"76.94000","7.69423","51730.88281","13.45146"
"77.14000","7.71419","51760.35156","13.48635"
"77.34000","7.73422","51790.26562","13.52137"
"77.54000","7.75408","51819.83203","13.55608"
"77.74000","7.77431","51851.00391","13.59146"
"77.94000","7.79422","51879.39844","13.62626"
"78.14000","7.81423","51908.53906","13.66124"
"78.34000","7.83426","51937.23438","13.69626"
"78.54000","7.85414","51961.52344","13.73102"
"78.74000","7.87430","51990.82031","13.76626"
"78.94000","7.89423","52017.60938","13.80111"
"79.14000","7.91414","52041.51172","13.83591"
"79.34000","7.93420","52078.19531","13.87098"
"79.54000","7.95415","52100.03125","13.90586"
"79.74000","7.97419","52130.66797","13.94089"
"79.94000","7.99425","52158.58203","13.97595"
"80.14000","8.01428","52182.03125","14.01098"
"80.34000","8.03424","52207.75781","14.04587"
"80.54000","8.05424","52230.65625","14.08084"
"80.74000","8.07425","52258.94922","14.11582"
"80.94000","8.09416","52283.14844","14.15062"
"81.14000","8.11416","52310.17578","14.18560"
"81.34000","8.13412","52334.61328","14.22049"
"81.54000","8.15413","52359.96875","14.25547"
"81.74000","8.17429","52387.27344","14.29071"
"81.94000","8.19422","52405.97266","14.32556"
"82.14000","8.21423","52427.72656","14.36054"
"82.34000","8.23423","52455.49219","14.39552"
"82.54000","8.25422","52478.24219","14.43045"
"82.74000","8.27425","52504.68750","14.46547"
"82.94000","8.29423","52524.47266","14.50041"
"83.14000","8.31421","52544.56250","14.53534"
"83.34000","8.33417","52569.15234","14.57023"
"83.54000","8.35425","52591.14453","14.60534"
"83.74000","8.37414","52613.93750","14.64010"
"83.94000","8.39425","52635.91406","14.67525"
"84.14000","8.41420","52658.52734","14.71014"
"84.34000","8.43408","52682.01172","14.74490"
"84.54000","8.45427","52705.45312","14.78019"
"84.74000","8.47428","52725.05469","14.81517"
"84.94000","8.49428","52739.78516","14.85014"
"85.14000","8.51427","52766.60938","14.88508"
"85.34000","8.53405","52784.14453","14.91966"
"85.54000","8.55420","52813.08203","14.95490"
"85.74000","8.57429","52832.47656","14.99001"
"85.94000","8.59424","52848.61328","15.02490"
"86.14000","8.61425","52867.78125","15.05988"
"86.34000","8.63416","52882.21875","15.09468"
"86.54000","8.65419","52903.17578","15.12971"
"86.74000","8.67422","52925.43750","15.16473"
"86.94000","8.69423","52943.32031","15.19971"
"87.14000","8.71416","52962.08203","15.23455"
"87.34000","8.73415","52983.68359","15.26949"
"87.54000","8.75420","53001.96875","15.30455"
"87.74000","8.77416","53019.01172","15.33944"
"87.94000","8.79434","53037.28516","15.37473"
"88.14000","8.81423","53054.95312","15.40949"
"88.34000","8.83421","53069.91797","15.44442"
"88.54000","8.85427","53089.75000","15.47949"
"88.74000","8.87415","53104.16406","15.51425"
"88.94000","8.89423","53127.09375","15.54936"
"89.14000","8.91416","53143.89453","15.58420"
"89.34000","8.93415","53156.64844","15.61914"
"89.54000","8.95420","53176.70703","15.65420"
"89.74000","8.97424","53191.66016","15.68922"
"89.94000","8.99424","53208.33984","15.72420"
"90.14000","9.01423","53226.04297","15.75914"
"90.34000","9.03426","53241.94922","15.79416"
"90.54000","9.05422","53258.99219","15.82905"
"90.74000","9.07420","53273.43750","15.86398"
"90.94000","9.09428","53288.78125","15.89909"
"91.14000","9.11416","53303.44922","15.93385"
"91.34000","9.13425","53320.33594","15.96896"
"91.54000","9.15423","53335.07812","16.00390"
"91.74000","9.17414","53346.44141","16.03870"
"91.94000","9.19429","53365.05859","16.07394"
"92.14000","9.21413","53374.52734","16.10861"
"92.34000","9.23418","53389.51172","16.14368"
"92.54000","9.25424","53406.48438","16.17874"
"92.74000","9.27422","53418.58984","16.21368"
"92.94000","9.29426","53437.92578","16.24870"
"93.14000","9.31419","53450.17969","16.28355"
"93.34000","9.33407","53461.47266","16.31830"
"93.54000","9.35423","53483.68750","16.35355"
"93.74000","9.37429","53489.92188","16.38861"
"93.94000","9.39424","53504.90625","16.42350"
"94.14000","9.41425","53513.55859","16.45848"
"94.34000","9.43421","53528.19141","16.49337"
"94.54000","9.45419","53541.28516","16.52831"
"94.74000","9.47425","53555.33203","16.56337"
"94.94000","9.49413","53567.07422","16.59813"
"95.14000","9.51416","53580.82031","16.63315"
"95.34000","9.53422","53595.30469","16.66822"
"95.54000","9.55415","53604.59766","16.70306"
"95.74000","9.57429","53618.09766","16.73826"
"95.94000","9.59429","53627.89062","16.77324"
"96.14000","9.61423","53637.12500","16.80809"
"96.34000","9.63426","53651.77344","16.84311"
"96.54000","9.65419","53662.17969","16.87795"
"96.74000","9.67422","53671.31250","16.91298"
"96.94000","9.69418","53683.69141","16.94787"
"97.14000","9.71419","53692.00000","16.98285"
"97.34000","9.73412","53706.40234","17.01769"
"97.54000","9.75420","53717.79688","17.05280"
"97.74000","9.77426","53730.43359","17.08787"
"97.94000","9.79417","53738.93359","17.12267"
"98.14000","9.81430","53747.85156","17.15787"
"98.34000","9.83423","53757.56641","17.19272"
"98.54000","9.85422","53762.96484","17.22765"
"98.74000","9.87427","53779.56641","17.26272"
"98.94000","9.89418","53785.73438","17.29752"
"99.14000","9.91421","53799.96484","17.33254"
"99.34000","9.93420","53810.71484","17.36747"
"99.54000","9.95415","53817.34375","17.40237"
"99.74000","9.97424","53830.85547","17.43747"
"99.94000","9.99422","53833.41406","17.47241"
"100.14000","10.01418","53843.63672","17.50730"
"100.34000","10.03416","53855.71875","17.54223"
"100.54000","10.05429","53866.69531","17.57743"
"100.74000","10.07425","53874.94531","17.61232"
"100.94000","10.09420","53882.89844","17.64721"
"101.14000","10.11424","53891.63672","17.68223"
"101.34000","10.13407","53899.64453","17.71690"
"101.54000","10.15430","53909.40234","17.75228"
"101.74000","10.17426","53914.38672","17.78717"
"101.94000","10.19419","53919.76172","17.82202"
"102.14000","10.21428","53932.41797","17.85712"
"102.34000","10.23413","53939.68359","17.89184"
"102.54000","10.25427","53948.38281","17.92704"
"102.74000","10.27425","53957.16016","17.96197"
"102.94000","10.29413","53959.20703","17.99673"
"103.14000","10.31424","53971.46484","18.03188"
"103.34000","10.33414","53975.81641","18.06669"
"103.54000","10.35418","53986.92578","18.10171"
"103.74000","10.37424","53995.27734","18.13677"
"103.94000","10.39427","53995.81641","18.17180"
"104.14000","10.41422","54003.94922","18.20669"
"104.34000","10.43423","54011.38672","18.24166"
"104.54000","10.45424","54020.17188","18.27664"
"104.74000","10.47417","54025.22656","18.31149"
"104.94000","10.49418","54031.78516","18.34647"
"105.14000","10.51416","54040.03125","18.38140"
"105.34000","10.53414","54047.82422","18.41634"
"105.54000","10.55428","54054.95312","18.45154"
"105.74000","10.57418","54057.61719","18.48634"
"105.94000","10.59424","54062.37109","18.52140"
"106.14000","10.61427","54070.41406","18.55642"
"106.34000","10.63418","54072.55469","18.59123"
"106.54000","10.65427","54082.10156","18.62634"
"106.74000","10.67422","54087.53906","18.66123"
"106.94000","10.69421","54091.10938","18.69616"
"107.14000","10.71419","54099.56641","18.73110"
"107.34000","10.73425","54102.77734","18.76616"
"107.54000","10.75418","54105.48438","18.80101"
"107.74000","10.77423","54109.02344","18.83608"
"107.94000","10.79422","54114.44141","18.87101"
"108.14000","10.81410","54121.14844","18.90577"
"108.34000","10.83423","54129.85156","18.94097"
"108.54000","10.85426","54137.15234","18.97599"
"108.74000","10.87425","54137.50391","19.01092"
"108.94000","10.89428","54143.99609","19.04594"
"109.14000","10.91406","54142.19922","19.08053"
"109.34000","10.93419","54151.12891","19.11573"
"109.54000","10.95428","54158.50391","19.15084"
"109.74000","10.97423","54157.37500","19.18572"
"109.94000","10.99427","54164.65234","19.22075"
"110.14000","11.01415","54165.64844","19.25550"
"110.34000","11.03418","54171.20312","19.29053"
"110.54000","11.05427","54178.48828","19.32564"
"110.74000","11.07422","54176.51562","19.36053"
"110.94000","11.09415","54183.76172","19.39537"
"111.14000","11.11414","54188.23828","19.43031"
"111.34000","11.13422","54191.41016","19.46542"
"111.54000","11.15418","54196.38281","19.50031"
"111.74000","11.17434","54195.52344","19.53555"
"111.94000","11.19427","54197.80469","19.57040"
"112.14000","11.21420","54198.91406","19.60524"
"112.34000","11.23428","54206.17969","19.64035"
"112.54000","11.25416","54207.47266","19.67511"
"112.74000","11.27425","54211.59766","19.71022"
"112.94000","11.29415","54215.88281","19.74502"
"113.14000","11.31411","54216.33594","19.77991"
"113.34000","11.33419","54224.91406","19.81502"
"113.54000","11.35423","54223.20312","19.85005"
"113.74000","11.37426","54223.91406","19.88507"
"113.94000","11.39424","54226.18359","19.92000"
"114.14000","11.41425","54228.75781","19.95498"
"114.34000","11.43421","54233.81250","19.98987"
"114.54000","11.45419","54235.49219","20.02481"
"114.74000","11.47427","54237.50391","20.05991"
"114.94000","11.49418","54239.25391","20.09472"
"115.14000","11.51426","54242.66016","20.12983"
"115.34000","11.53424","54241.29297","20.16476"
"115.54000","11.55415","54244.00000","20.19956"
"115.74000","11.57428","54248.35156","20.23476"
"115.94000","11.59414","54245.88281","20.26948"
"116.14000","11.61415","54249.56641","20.30445"
"116.34000","11.63426","54256.35156","20.33961"
"116.54000","11.65421","54251.92578","20.37450"
"116.74000","11.67427","54255.54688","20.40957"
"116.94000","11.69420","54256.09375","20.44441"
"117.14000","11.71408","54255.06250","20.47917"
"117.34000","11.73424","54264.66406","20.51441"
"117.54000","11.75428","54257.32031","20.54943"
"117.74000","11.77426","54259.31641","20.58437"
"117.94000","11.79422","54258.26953","20.61926"
"118.14000","11.81420","54258.58984","20.65419"
"118.34000","11.83420","54259.66406","20.68917"
"118.54000","11.85424","54262.45312","20.72419"
"118.74000","11.87417","54263.09766","20.75904"
"118.94000","11.89415","54263.76953","20.79397"
"119.14000","11.91421","54265.96484","20.82904"
"119.34000","11.93417","54262.83594","20.86393"
"119.54000","11.95423","54263.14062","20.89899"
"119.74000","11.97431","54264.61719","20.93411"
"119.94000","11.99419","54263.01172","20.96886"
"120.14000","12.01427","54265.70703","21.00397"
"120.34000","12.03418","54264.48438","21.03878"
"120.54000","12.05421","54266.73438","21.07380"
"120.74000","12.07420","54268.90234","21.10873"
"120.94000","12.09415","54263.11328","21.14362"
"121.14000","12.11416","54263.00781","21.17860"
"121.34000","12.13419","54265.99219","21.21362"
"121.54000","12.15428","54264.49219","21.24874"
"121.74000","12.17418","54264.27734","21.28354"
"121.94000","12.19429","54263.84375","21.31869"
"122.14000","12.21422","54262.56641","21.35354"
"122.34000","12.23418","54258.97266","21.38842"
"122.54000","12.25426","54261.79688","21.42354"
"122.74000","12.27419","54258.47266","21.45838"
"122.94000","12.29420","54258.97266","21.49336"
"123.14000","12.31424","54258.75781","21.52838"
"123.34000","12.33414","54255.55078","21.56318"
"123.54000","12.35423","54260.26172","21.59830"
"123.74000","12.37421","54256.23047","21.63323"
"123.94000","12.39417","54252.59375","21.66812"
"124.14000","12.41417","54255.43750","21.70310"
"124.34000","12.43428","54254.45312","21.73825"
"124.54000","12.45426","54253.36328","21.77319"
"124.74000","12.47419","54249.95312","21.80803"
"124.94000","12.49423","54248.94141","21.84305"
"125.14000","12.51408","54250.67578","21.87777"
"125.34000","12.53427","54249.50781","21.91305"
"125.54000","12.55427","54244.39453","21.94803"
"125.74000","12.57421","54238.72656","21.98288"
"125.94000","12.59429","54241.23828","22.01799"
"126.14000","12.61412","54239.15234","22.05266"
"126.34000","12.63423","54239.97656","22.08781"
"126.54000","12.65426","54240.39453","22.12284"
"126.74000","12.67409","54230.01562","22.15751"
"126.94000","12.69423","54234.40234","22.19270"
"127.14000","12.71413","54226.23828","22.22751"
"127.34000","12.73419","54224.43750","22.26257"
"127.54000","12.75428","54225.22266","22.29768"
"127.74000","12.77426","54219.94141","22.33262"
"127.94000","12.79427","54219.42578","22.36760"
"128.14000","12.81420","54214.07031","22.40244"
"128.34000","12.83423","54212.29688","22.43747"
"128.54000","12.85419","54209.64453","22.47236"
"128.74000","12.87417","54208.50000","22.50729"
"128.94000","12.89418","54205.39844","22.54227"
"129.14000","12.91411","54201.57422","22.57711"
"129.34000","12.93427","54200.41016","22.61236"
"129.54000","12.95417","54194.88672","22.64716"
"129.74000","12.97421","54191.71484","22.68218"
"129.94000","12.99429","54190.44531","22.71729"
"130.14000","13.01420","54182.45312","22.75209"
"130.34000","13.03425","54182.05859","22.78716"
"130.54000","13.05424","54180.50391","22.82209"
"130.74000","13.07419","54174.04297","22.85698"
"130.94000","13.09420","54176.03906","22.89196"
"131.14000","13.11423","54168.28516","22.92698"
"131.34000","13.13417","54167.26953","22.96183"
"131.54000","13.15420","54162.06641","22.99685"
"131.74000","13.17421","54156.16016","23.03183"
"131.94000","13.19414","54155.56250","23.06668"
"132.14000","13.21422","54150.53516","23.10178"
"132.34000","13.23428","54149.61719","23.13685"
"132.54000","13.25421","54143.44141","23.17170"
"132.74000","13.27427","54141.68359","23.20676"
"132.94000","13.29408","54133.01562","23.24139"
"133.14000","13.31418","54129.74219","23.27655"
"133.34000","13.33432","54125.72656","23.31174"
"133.54000","13.35420","54116.97656","23.34650"
"133.74000","13.37426","54117.49609","23.38157"
"133.94000","13.39416","54110.82031","23.41637"
"134.14000","13.41420","54107.36719","23.45139"
"134.34000","13.43428","54104.69141","23.48650"
"134.54000","13.45421","54094.83984","23.52135"
"134.74000","13.47417","54089.70703","23.55624"
"134.94000","13.49415","54086.50000","23.59117"
"135.14000","13.51421","54081.34375","23.62624"
"135.34000","13.53417","54079.99609","23.66113"
"135.54000","13.55428","54073.63672","23.69629"
"135.74000","13.57426","54067.30078","23.73122"
"135.94000","13.59421","54058.57031","23.76611"
"136.14000","13.61430","54054.42188","23.80122"
"136.34000","13.63418","54047.44922","23.83598"
"136.54000","13.65424","54040.48047","23.87104"
"136.74000","13.67419","54035.66797","23.90593"
"136.94000","13.69410","54029.55469","23.94073"
"137.14000","13.71421","54030.04297","23.97589"
"137.34000","13.73422","54018.61719","24.01087"
"137.54000","13.75422","54009.37891","24.04585"
"137.74000","13.77426","54003.39844","24.08087"
"137.94000","13.79424","53993.60547","24.11580"
"138.14000","13.81422","53990.71484","24.15074"
"138.34000","13.83420","53986.73438","24.18567"
"138.54000","13.85426","53978.66797","24.22074"
"138.74000","13.87417","53973.20312","24.25554"
"138.94000","13.89420","53967.88672","24.29056"
"139.14000","13.91426","53960.67969","24.32563"
"139.34000","13.93412","53950.00000","24.36034"
"139.54000","13.95430","53945.54297","24.39563"
"139.74000","13.97416","53937.33203","24.43034"
"139.94000","13.99416","53931.73828","24.46532"
"140.14000","14.01427","53926.98047","24.50047"
"140.34000","14.03423","53914.79297","24.53536"
"140.54000","14.05429","53909.18750","24.57043"
"140.74000","14.07422","53898.78906","24.60528"
"140.94000","14.09405","53884.53516","24.63995"
"141.14000","14.11423","53885.48438","24.67523"
"141.34000","14.13427","53874.75000","24.71026"
"141.54000","14.15427","53866.31641","24.74523"
"141.74000","14.17421","53854.52344","24.78008"
"141.94000","14.19419","53845.88672","24.81502"
"142.14000","14.21420","53838.31250","24.84999"
"142.34000","14.23425","53826.33203","24.88506"
"142.54000","14.25419","53813.70312","24.91991"
"142.74000","14.27414","53808.61719","24.95480"
"142.94000","14.29420","53800.15234","24.98986"
"143.14000","14.31416","53788.46094","25.02475"
"143.34000","14.33422","53778.34375","25.05982"
"143.54000","14.35430","53765.90625","25.09493"
"143.74000","14.37421","53752.12500","25.12973"
"143.94000","14.39426","53745.01953","25.16479"
"144.14000","14.41422","53737.16406","25.19969"
"144.34000","14.43420","53723.22266","25.23462"
"144.54000","14.45421","53715.52734","25.26960"
"144.74000","14.47414","53701.32422","25.30444"
"144.94000","14.49417","53689.66406","25.33947"
"145.14000","14.51418","53678.30469","25.37445"
"145.34000","14.53427","53662.39453","25.40956"
"145.54000","14.55420","53652.75000","25.44440"
"145.74000","14.57426","53639.60156","25.47947"
"145.94000","14.59426","53631.48438","25.51444"
"146.14000","14.61417","53615.70312","25.54925"
"146.34000","14.63425","53604.42969","25.58436"
"146.54000","14.65418","53588.68359","25.61920"
"146.74000","14.67419","53573.26172","25.65418"
"146.94000","14.69425","53562.03906","25.68925"
"147.14000","14.71418","53545.63672","25.72410"
"147.34000","14.73424","53534.64062","25.75916"
"147.54000","14.75420","53518.37109","25.79405"
"147.74000","14.77415","53501.77734","25.82894"
"147.94000","14.79419","53488.66406","25.86396"
"148.14000","14.81427","53472.14453","25.89907"
"148.34000","14.83428","53452.85938","25.93405"
"148.54000","14.85421","53436.02344","25.96890"
"148.74000","14.87422","53418.76562","26.00388"
"148.94000","14.89410","53405.17578","26.03864"
"149.14000","14.91426","53391.63672","26.07388"
"149.34000","14.93429","53369.86719","26.10890"
"149.54000","14.95422","53350.33984","26.14375"
"149.74000","14.97431","53329.82422","26.17886"
"149.94000","14.99414","53309.54688","26.21353"
"150.14000","15.01422","53292.56250","26.24864"
"150.34000","15.03428","53277.15234","26.28371"
"150.54000","15.05411","53254.15625","26.31837"
"150.74000","15.07424","53239.07812","26.35357"
"150.94000","15.09412","53216.17188","26.38833"
"151.14000","15.11416","53192.03125","26.42335"
"151.34000","15.13429","53172.43750","26.45855"
"151.54000","15.15427","53147.37109","26.49348"
"151.74000","15.17425","53127.11719","26.52842"
"151.94000","15.19421","53103.70312","26.56331"
"152.14000","15.21425","53080.42188","26.59833"
"152.34000","15.23420","53058.44141","26.63322"
"152.54000","15.25416","53034.65234","26.66811"
"152.74000","15.27419","53008.63281","26.70313"
"152.94000","15.29412","52983.82031","26.73798"
"153.14000","15.31426","52959.10938","26.77318"
"153.34000","15.33421","52932.60938","26.80807"
"153.54000","15.35420","52904.16406","26.84300"
"153.74000","15.37433","52880.42969","26.87820"
"153.94000","15.39419","52849.89453","26.91291"
"154.14000","15.41424","52826.11719","26.94798"
"154.34000","15.43423","52798.71875","26.98292"
"154.54000","15.45421","52767.17969","27.01785"
"154.74000","15.47422","52743.47656","27.05283"
"154.94000","15.49422","52711.91016","27.08780"
"155.14000","15.51416","52681.23047","27.12265"
"155.34000","15.53419","52655.60938","27.15767"
"155.54000","15.55422","52619.94531","27.19270"
"155.74000","15.57415","52590.46094","27.22754"
"155.94000","15.59421","52557.86719","27.26261"
"156.14000","15.61432","52530.24609","27.29776"
"156.34000","15.63423","52493.12500","27.33256"
"156.54000","15.65426","52463.78906","27.36759"
"156.74000","15.67412","52431.49219","27.40230"
"156.94000","15.69415","52399.12891","27.43732"
"157.14000","15.71433","52362.48828","27.47261"
"157.34000","15.73421","52322.75000","27.50736"
"157.54000","15.75427","52287.23438","27.54243"
"157.74000","15.77420","52254.14453","27.57728"
"157.94000","15.79419","52217.48828","27.61221"
"158.14000","15.81427","52185.67188","27.64732"
"158.34000","15.83420","52146.30859","27.68217"
"158.54000","15.85416","52109.09375","27.71706"
"158.74000","15.87417","52073.71875","27.75204"
"158.94000","15.89417","52029.87109","27.78701"
"159.14000","15.91421","51995.88672","27.82204"
"159.34000","15.93426","51956.30078","27.85710"
"159.54000","15.95427","51916.30859","27.89208"
"159.74000","15.97420","51876.37109","27.92693"
"159.94000","15.99426","51833.93359","27.96199"
"160.14000","16.01419","51795.14453","27.99684"
"160.34000","16.03423","51752.94141","28.03186"
"160.54000","16.05421","51711.81641","28.06680"
"160.74000","16.07412","51665.34766","28.10160"
"160.94000","16.09420","51628.21484","28.13671"
"161.14000","16.11423","51586.19141","28.17173"
"161.34000","16.13424","51540.35156","28.20671"
"161.54000","16.15425","51495.52734","28.24169"
"161.74000","16.17423","51448.82812","28.27662"
"161.94000","16.19423","51403.95312","28.31160"
"162.14000","16.21422","51361.07812","28.34654"
"162.34000","16.23425","51313.64453","28.38156"
"162.54000","16.25421","51266.93750","28.41645"
"162.74000","16.27419","51221.68750","28.45138"
"162.94000","16.29425","51172.60156","28.48645"
"163.14000","16.31410","51124.10938","28.52116"
"163.34000","16.33426","51075.64453","28.55640"
"163.54000","16.35417","51025.10547","28.59121"
"163.74000","16.37415","50972.71875","28.62614"
"163.94000","16.39426","50925.60547","28.66129"
"164.14000","16.41422","50874.41016","28.69618"
"164.34000","16.43425","50824.92188","28.73121"
"164.54000","16.45423","50776.52344","28.76614"
"164.74000","16.47406","50715.26172","28.80081"
"164.94000","16.49425","50670.73828","28.83610"
"165.14000","16.51428","50609.70703","28.87112"
"165.34000","16.53426","50557.02734","28.90606"
"165.54000","16.55422","50503.35547","28.94094"
"165.74000","16.57418","50446.85547","28.97584"
"165.94000","16.59421","50397.58203","29.01086"
"166.14000","16.61424","50341.28516","29.04588"
"166.34000","16.63420","50280.51172","29.08077"
"166.54000","16.65416","50221.82031","29.11566"
"166.74000","16.67419","50167.09375","29.15068"
"166.94000","16.69420","50107.53125","29.18566"
"167.14000","16.71420","50049.46094","29.22064"
"167.34000","16.73434","49989.03516","29.25584"
"167.54000","16.75422","49924.14844","29.29059"
"167.74000","16.77428","49864.67188","29.32566"
"167.94000","16.79424","49804.71875","29.36055"
"168.14000","16.81419","49739.29688","29.39544"
"168.34000","16.83425","49678.95312","29.43051"
"168.54000","16.85410","49612.32422","29.46522"
"168.74000","16.87416","49553.16016","29.50029"
"168.94000","16.89420","49489.83984","29.53531"
"169.14000","16.91426","49417.04688","29.57038"
"169.34000","16.93424","49350.44141","29.60531"
"169.54000","16.95424","49284.92188","29.64029"
"169.74000","16.97425","49219.81641","29.67526"
"169.94000","16.99421","49151.84766","29.71016"
"170.14000","17.01424","49084.02734","29.74518"
"170.34000","17.03423","49013.75000","29.78011"
"170.54000","17.05416","48942.36719","29.81496"
"170.74000","17.07426","48873.85547","29.85011"
"170.94000","17.09420","48795.58203","29.88496"
"171.14000","17.11423","48723.19531","29.91998"
"171.34000","17.13426","48651.30078","29.95500"
"171.54000","17.15414","48573.90625","29.98976"
"171.74000","17.17418","48503.11719","30.02478"
"171.94000","17.19426","48427.85547","30.05989"
"172.14000","17.21427","48348.33594","30.09487"
"172.34000","17.23422","48271.49219","30.12976"
"172.54000","17.25421","48187.63672","30.16470"
"172.74000","17.27411","48107.87891","30.19950"
"172.94000","17.29422","48028.94141","30.23465"
"173.14000","17.31431","47946.98438","30.26977"
"173.34000","17.33421","47864.26562","30.30457"
"173.54000","17.35427","47779.70312","30.33963"
"173.74000","17.37418","47696.44922","30.37443"
"173.94000","17.39421","47609.53906","30.40946"
"174.14000","17.41429","47525.05859","30.44457"
"174.34000","17.43412","47433.07031","30.47924"
"174.54000","17.45421","47348.90625","30.51435"
"174.74000","17.47416","47259.20312","30.54924"
"174.94000","17.49417","47168.39062","30.58422"
"175.14000","17.51428","47077.32031","30.61937"
"175.34000","17.53426","46977.26172","30.65430"
"175.54000","17.55427","46882.57812","30.68928"
"175.74000","17.57423","46786.76562","30.72417"
"175.94000","17.59423","46688.34766","30.75915"
"176.14000","17.61424","46590.09766","30.79413"
"176.34000","17.63417","46488.35547","30.82898"
"176.54000","17.65421","46383.65625","30.86400"
"176.74000","17.67411","46275.57812","30.89880"
"176.94000","17.69425","46156.62500","30.93400"
"177.14000","17.71425","46026.98047","30.96898"